Workbook

Sheet BITACORA
A1: RECEPCION Y CONTROL: MADERA EN TUCO
A3: FECHA DE PARTIDA | B3: FECHA DE RECEPCION EN PLANTA | C3: PLACA | D3: RESPONSABLE | E3: PUNTO DE PARTIDA | F3: DETALLE | G3: ID | H3: ESTIMADO (TICKET) | I3: DATO REAL (DATO ASERRADO) | J3: PRECIO $ (VALOR A PAGAR) | K3: COSTO $ | L3: SALDO | M3: ESTADO $ | N3: OBSERVACION
A4: 44321 | B4: 44321 | C4: HBA0270 | D4: ANAGUANO GALARRAGA FAUSTO | E4: VARIOS | F4: PROVEEDOR | G4: 1 | I4: 110 | J4: 100 | K4: 0.90909091 | L4: 0 | M4: CANCELADO | N4: 27 TUCOS EN CAMIONETA
A5: 44321 | B5: 44321 | C5: XBE343 | D5: BRAVO BRAVO MILTON GABRIEL | E5: VARIOS | F5: PROVEEDOR | G5: 2 | I5: 320 | J5: 200 | K5: 0.625 | L5: 0 | M5: CANCELADO | N5: CAMIONETADA COMPRADA EN $200 PAGO EN EFECTIVO
A6: 44321 | B6: 44321 | C6: HBC6496 | D6: VELIZ ZAMBRANO JAIME GREGORIO | E6: RIO FRIO | F6: BOSQUE | G6: 3 | I6: 83 | J6: 0 | K6: 0 | L6: 0 | N6: 13 TUCOS GRUESOS EN BUEN ESTADO Y UNO FINO. Completado con madera aserrada.
A7: 44323 | B7: 44323 | C7: NBF0031 | D7: VELIZ ZAMBRANO JAIME GREGORIO | E7: RIO FRIO | F7: BOSQUE | G7: 4 | I7: 3090 | J7: 0 | K7: 0 | L7: 0 | N7: 5 FILAS. LAS ULTIMAS FILAS NO VINIERON COMPLETAS. PERO BUEN GROSOR, POCA MADERA FINA
A8: 44322 | B8: 44322 | C8: NBF0031 | D8: VELIZ ZAMBRANO JAIME GREGORIO | E8: RIO FRIO | F8: BOSQUE | G8: 5 | I8: 3385 | J8: 0 | K8: 0 | L8: 0 | N8: 5 FILAS COMPLETAS HASTA ARRIBA. MADERA DE BUEN GROSOR. ULTIMA FILA CON MADERA UN POCO MAS FINA.
A9: 44323 | B9: 44323 | C9: HBC6496 | D9: VELIZ ZAMBRANO JAIME GREGORIO | E9: RIO FRIO | F9: BOSQUE | G9: 6 | I9: 1125 | J9: 0 | K9: 0 | L9: 0 | N9: 2 CAMIONETADAS
A10: 44323 | B10: 44323 | C10: PPA1778 | D10: VELIZ ZAMBRANO JAIME GREGORIO | E10: RIO FRIO | F10: BOSQUE | G10: 7 | I10: 407 | J10: 0 | K10: 0 | L10: 0 | N10: CAMIONETADA V6
A11: 44323 | B11: 44323 | C11: PPA1778 | D11: VELIZ ZAMBRANO JAIME GREGORIO | E11: RIO FRIO | F11: BOSQUE | G11: 8 | I11: 408 | J11: 0 | K11: 0 | L11: 0 | N11: CAMIONETADA V6
A12: 44323 | B12: 44323 | C12: NBF0031 | D12: VELIZ ZAMBRANO JAIME GREGORIO | E12: RIO FRIO | F12: BOSQUE | G12: 9 | I12: 1505 | J12: 0 | K12: 0 | L12: 0 | N12: POCA MADERA
A13: 44323 | B13: 44323 | C13: HBA0270 | D13: VELIZ ZAMBRANO JAIME GREGORIO | E13: RIO FRIO | F13: BOSQUE | G13: 10 | I13: 481 | J13: 0 | K13: 0 | L13: 0 | N13: CAMIONETADA V6
A14: 44326 | B14: 44326 | C14: PPA1778 | D14: VELIZ ZAMBRANO JAIME GREGORIO | E14: RIO FRIO | F14: BOSQUE | G14: 11 | I14: 478 | J14: 0 | K14: 0 | L14: 0 | N14: CAMIONETADA V6
A15: 44327 | B15: 44327 | C15: HBC6496 | D15: VELIZ ZAMBRANO JAIME GREGORIO | E15: RIO FRIO | F15: BOSQUE | G15: 13 | I15: 484 | J15: 0 | K15: 0 | L15: 0 | N15: CAMIONETADA V6
A16: 44327 | B16: 44327 | C16: RBA9146 | D16: VELIZ ZAMBRANO JAIME GREGORIO | E16: RIO FRIO | F16: BOSQUE | G16: 14 | I16: 410 | J16: 0 | K16: 0 | L16: 0 | N16: VAMIONETADA V6
A17: 44327 | B17: 44327 | C17: PPA1778 | D17: VELIZ ZAMBRANO JAIME GREGORIO | E17: RIO FRIO | F17: BOSQUE | G17: 15 | I17: 369 | J17: 0 | K17: 0 | L17: 0 | N17: CAMIONETADA MADERA LARGA
... A19: 44327 | B19: 44327 | C19: HBC6496 | D19: VELIZ ZAMBRANO JAIME GREGORIO | E19: RIO FRIO | F19: BOSQUE | G19: 17 | I19: 408 | J19: 0 | K19: 0 | L19: 0 | N19: VAMIONETADA V6
A20: 44327 | B20: 44327 | C20: PVL0706 | D20: AGUILAR ALVARES PATRICIO ESTUARDO | E20: VARIOS | F20: PROVEEDOR | G20: 18 | H20: 3600 | I20: 3522 | J20: 3000 | K20: 0.85178876 | L20: 0 | M20: CANCELADO | N20: GH 5 FILAS. MADERA GRUESA, PERO CON GRAN PORCENTAJE DE MADERA PESADA.
A21: 44327 | B21: 44327 | C21: PFB0399 | D21: VELIZ ZAMBRANO JAIME GREGORIO | E21: RIO FRIO | F21: BOSQUE | G21: 19 | I21: 401 | J21: 0 | K21: 0 | L21: 0 | N21: VAMIONETADA V6
A22: 44328 | B22: 44328 | D22: MADERA DE PLANTA | E22: FINCA EN PLANTA | F22: FINCA | G22: 20 | I22: 33 | J22: 0 | K22: 0 | L22: 0 | N22: 1 PATA TRAS PARQUEADERO
A23: 44328 | B23: 44328 | C23: NBF0031 | D23: VELIZ ZAMBRANO JAIME GREGORIO | E23: RIO FRIO | F23: BOSQUE | G23: 21 | I23: 2290 | J23: 0 | K23: 0 | L23: 0
A24: 44328 | B24: 44328 | C24: HGC420 | D24: MENDOZA GUARDERAS JORGE MANUEL | E24: VARIOS | F24: PROVEEDOR | G24: 22 | I24: 300 | J24: 225 | K24: 0.75 | L24: 0 | M24: CANCELADO | N24: CAMIONETADA
A25: 44330 | B25: 44330 | C25: PVL602 | D25: OLGUIN QUINATOA JAVIER ANTONIO | E25: VARIOS | F25: PROVEEDOR | G25: 23 | I25: 1205 | J25: 870 | K25: 0.7219917 | L25: 0 | M25: CANCELADO | N25: 4 FILAS MADERA 60% FINA 40% PROMEDIO PAGADO CON CHEQUE
A26: 44330 | B26: 44330 | C26: PBS1430 | D26: DOMINGUEZ CHIRIBOGA JORGE VICENTE | E26: VARIOS | F26: PROVEEDOR | G26: 24 | I26: 2061 | J26: 1400 | K26: 0.6792819 | L26: 0 | M26: CANCELADO | N26: VOLQUETA 4 FILAS. 20% MADERA FINA 80% MADERA PROMEDIO GRUESA PERO EN BUENE STADO
A27: 44330 | B27: 44330 | C27: PVH243 | D27: NAPA CAICEDO HENRRY JULIAN | E27: VARIOS | F27: PROVEEDOR | G27: 25 | I27: 65 | J27: 45 | K27: 0.69230769 | L27: 0 | M27: CANCELADO | N27: TROOPER CON 35 TUCOS MEDIANOS. PAGADOS EN EFECTIVO
A28: 44330 | B28: 44330 | C28: PVL602 | D28: OLGUIN QUINATOA JAVIER ANTONIO | E28: VARIOS | F28: PROVEEDOR | G28: 26 | I28: 1677 | J28: 870 | K28: 0.51878354 | L28: 0 | M28: CANCELADO | N28: 4 FILAS MADERA 70% FINA 30% PROMEDIO
A29: 44332 | B29: 44332 | C29: PBI0064 | D29: APOLO DIAS SEGUNDO PETER | E29: VARIOS | F29: PROVEEDOR | G29: 27 | I29: 2464 | J29: 2100 | K29: 0.85227273 | L29: 0 | M29: CANCELADO | N29: FC 4 FILAS MADERA GRUESA, 80 % LIVIANA
A30: 44332 | B30: 44332 | C30: PQF0935 | D30: APOLO DIAS SEGUNDO PETER | E30: VARIOS | F30: PROVEEDOR | G30: 28 | I30: 2314 | J30: 2100 | K30: 0.90751945 | L30: 0 | M30: CANCELADO | N30: FC 4 FILAS MADERA GRUESA, 80 % LIVIANA
A31: 44333 | B31: 44333 | C31: PLV602 | D31: OLGUIN QUINATOA JAVIER ANTONIO | E31: VARIOS | F31: PROVEEDOR | G31: 29 | I31: 941 | J31: 600 | K31: 0.63761955 | L31: 0 | M31: CANCELADO | N31: 3 FILAS 80% MADERA FINA
A32: 44333 | B32: 44333 | C32: PCP5161 | D32: MENDOZA GUARDERAS JORGE MANUEL | E32: VARIOS | F32: PROVEEDOR | G32: 30 | H32: 350 | I32: 316 | J32: 245 | K32: 0.77531646 | L32: 0 | M32: CANCELADO | N32: CAMIONETADA
A33: 44333 | B33: 44333 | C33: PPA1778 | D33: MENDOZA GUARDERAS JORGE MANUEL | E33: VARIOS | F33: PROVEEDOR | G33: 31 | H33: 350 | I33: 251 | J33: 195 | K33: 0.77689243 | L33: 0 | M33: CANCELADO | N33: CAMIONETADA
A34: 44334 | B34: 44334 | C34: PCP5161 | D34: MENDOZA GUARDERAS JORGE MANUEL | E34: VARIOS | F34: PROVEEDOR | G34: 32 | H34: 350 | I34: 244 | J34: 190 | K34: 0.77868852 | L34: 0 | M34: CANCELADO | N34: CAMIONETADA
A35: 44334 | B35: 44334 | C35: PPA1778 | D35: MENDOZA GUARDERAS JORGE MANUEL | E35: VARIOS | F35: PROVEEDOR | G35: 33 | H35: 350 | I35: 344 | J35: 268 | K35: 0.77906977 | L35: 0 | M35: CANCELADO | N35: CAMIONETADA
A36: 44334 | B36: 44334 | C36: PPA1778 | D36: MENDOZA GUARDERAS JORGE MANUEL | E36: VARIOS | F36: PROVEEDOR | G36: 34 | H36: 350 | I36: 125 | J36: 95 | K36: 0.76 | L36: 0 | M36: CANCELADO | N36: POCOS TUCOS
A37: 44334 | B37: 44334 | C37: PBI0064 | D37: APOLO DIAS SEGUNDO PETER | E37: VARIOS | F37: PROVEEDOR | G37: 35 | I37: 2586 | J37: 2100 | K37: 0.81206497 | L37: 0 | M37: CANCELADO | N37: FC 4 FILAS MADERA GRUESA, 80 % LIVIANA
A38: 44334 | B38: 44334 | C38: PQX0247 | D38: APOLO DIAS SEGUNDO PETER | E38: VARIOS | F38: PROVEEDOR | G38: 36 | I38: 3051 | J38: 2590 | K38: 0.848902 | L38: 0 | M38: CANCELADO | N38: GD 4 FILAS MAS RELLLENO POSTERIOR DE 12 TUCOS MADERA GRUESA 75% LIVIANA
A39: 44335 | B39: 44335 | C39: NBF0031 | D39: COBEÑA QUINTERO RICARDO | E39: RIO FRIO ETAPA 2 | F39: BOSQUE | G39: 37 | I39: 3115 | J39: 0 | K39: 0 | L39: 0 | N39: 5 FILAS COMPLETAS HASTA ARRIBA. MADERA DE BUEN GROSOR.
A40: 44335 | B40: 44335 | C40: HBC6496 | D40: COBEÑA QUINTERO RICARDO | E40: RIO FRIO ETAPA 2 | F40: BOSQUE | G40: 38 | H40: 250 | I40: 1144 | J40: 0 | K40: 0 | L40: 0 | N40: 3 CAMIONETADAS
A41: 44335 | B41: 44335 | C41: MPA1139 | D41: BRAVO SOLORZANO ANIBAL ORLEY | E41: VARIOS | F41: PROVEEDOR | G41: 39 | H41: 180 | I41: 247 | J41: 200 | K41: 0.8097166 | L41: 200 | M41: PENDIENTE | N41: CAMIONETADA COMPRADA EN PLANTA CON 85% DE MADERA FINA
A42: 44335 | B42: 44335 | C42: OBT260 | D42: OLMEDO VELEZ LIWINTONG AUGUSTO | E42: VARIOS | F42: PROVEEDOR | G42: 40 | H42: 80 | I42: 103 | J42: 50 | K42: 0.48543689 | L42: 0 | M42: CANCELADO | N42: 16 TUCOS DE 3 PALMOS
...

Sheet LISTAS
C1: DATO ENVIADO | D1: ASERRADO | F1: SUMA | G1: =SUM(G2:G5) -> 247600 | H1: =SUM(H2:H5) -> 307221
A2: MES | B2: MAYO | C2: =SUMIFS(BITACORA!$H$4:$H$7322,BITACORA!$B$4:$B$7322,">="&$B$3,BITACORA!$B$4:$B$7322,"<="&$B$4) -> 247600 | D2: =SUMIFS(BITACORA!$I$4:$I$7322,BITACORA!$B$4:$B$7322,">="&$B$3,BITACORA!$B$4:$B$7322,"<="&$B$4) -> 307221 | F2: BOSQUE | G2: =SUM(C33:C41) -> 13740 | H2: =SUM(D33:D41) -> 38697
A3: FECHA DE INICIO | B3: 44321 | F3: FINCA | G3: =SUM(C24:C30) -> 800 | H3: =SUM(D24:D30) -> 33
A4: FECHA DE CORTE | B4: 44377 | F4: ACOPIO | G4: =SUM(C7:C21) -> 67900 | H4: =SUM(D7:D21) -> 67917
F5: PROVEEDOR | G5: =SUM(C44:C1004) -> 165160 | H5: =SUM(D44:D1004) -> 200574
A6: RESPONSABLE | B6: PUNTO DE PARTIDA | C6: BFT ENVIADO | D6: BFT ASERRADO | G6: BFT ENVIADO | H6: BFT RECIBIDO
A7: BASURTO SACON ANDRES FERNANDO | B7: TACHINA | C7: =SUMIFS(BITACORA!$H$4:$H$7322,BITACORA!$D$4:$D$7322,$A$7:$A$100,BITACORA!$E$4:$E$7322,$B$7:$B$100,BITACORA!$B$4:$B$7322,">="&$B$3,BITACORA!$B$4:$B$7322,"<="&$B$4) -> 13800 | D7: =SUMIFS(BITACORA!$I$4:$I$7322,BITACORA!$D$4:$D$7322,$A$7:$A$100,BITACORA!$E$4:$E$7322,$B$7:$B$100,BITACORA!$B$4:$B$7322,">="&$B$3,BITACORA!$B$4:$B$7322,"<="&$B$4) -> 15797 | E7: ACOPIOS
A8: ARIAS LARA MARCOS VINICIO | B8: TRES VIAS | C8: =SUMIFS(BITACORA!$H$4:$H$7322,BITACORA!$D$4:$D$7322,$A$7:$A$100,BITACORA!$E$4:$E$7322,$B$7:$B$100,BITACORA!$B$4:$B$7322,">="&$B$3,BITACORA!$B$4:$B$7322,"<="&$B$4) -> 32400 | D8: =SUMIFS(BITACORA!$I$4:$I$7322,BITACORA!$D$4:$D$7322,$A$7:$A$100,BITACORA!$E$4:$E$7322,$B$7:$B$100,BITACORA!$B$4:$B$7322,">="&$B$3,BITACORA!$B$4:$B$7322,"<="&$B$4) -> 30831
A9: ZAMBRANO ZAMBRANO JEFFERSON VITERILO | B9: QUININDE | C9: =SUMIFS(BITACORA!$H$4:$H$7322,BITACORA!$D$4:$D$7322,$A$7:$A$100,BITACORA!$E$4:$E$7322,$B$7:$B$100,BITACORA!$B$4:$B$7322,">="&$B$3,BITACORA!$B$4:$B$7322,"<="&$B$4) -> 12200 | D9: =SUMIFS(BITACORA!$I$4:$I$7322,BITACORA!$D$4:$D$7322,$A$7:$A$100,BITACORA!$E$4:$E$7322,$B$7:$B$100,BITACORA!$B$4:$B$7322,">="&$B$3,BITACORA!$B$4:$B$7322,"<="&$B$4) -> 10934
A10: COBEÑA QUINTERO RICARDO | B10: TAISHA | C10: =SUMIFS(BITACORA!$H$4:$H$7322,BITACORA!$D$4:$D$7322,$A$7:$A$100,BITACORA!$E$4:$E$7322,$B$7:$B$100,BITACORA!$B$4:$B$7322,">="&$B$3,BITACORA!$B$4:$B$7322,"<="&$B$4) -> 6000 | D10: =SUMIFS(BITACORA!$I$4:$I$7322,BITACORA!$D$4:$D$7322,$A$7:$A$100,BITACORA!$E$4:$E$7322,$B$7:$B$100,BITACORA!$B$4:$B$7322,">="&$B$3,BITACORA!$B$4:$B$7322,"<="&$B$4) -> 6187
A11: COBEÑA QUINTERO RICARDO | B11: ARAJUNO | C11: =SUMIFS(BITACORA!$H$4:$H$7322,BITACORA!$D$4:$D$7322,$A$7:$A$100,BITACORA!$E$4:$E$7322,$B$7:$B$100,BITACORA!$B$4:$B$7322,">="&$B$3,BITACORA!$B$4:$B$7322,"<="&$B$4) -> 3500 | D11: =SUMIFS(BITACORA!$I$4:$I$7322,BITACORA!$D$4:$D$7322,$A$7:$A$100,BITACORA!$E$4:$E$7322,$B$7:$B$100,BITACORA!$B$4:$B$7322,">="&$B$3,BITACORA!$B$4:$B$7322,"<="&$B$4) -> 4168
C12: =SUMIFS(BITACORA!$H$4:$H$7322,BITACORA!$D$4:$D$7322,$A$7:$A$100,BITACORA!$E$4:$E$7322,$B$7:$B$100,BITACORA!$B$4:$B$7322,">="&$B$3,BITACORA!$B$4:$B$7322,"<="&$B$4) -> 0 | D12: =SUMIFS(BITACORA!$I$4:$I$7322,BITACORA!$D$4:$D$7322,$A$7:$A$100,BITACORA!$E$4:$E$7322,$B$7:$B$100,BITACORA!$B$4:$B$7322,">="&$B$3,BITACORA!$B$4:$B$7322,"<="&$B$4) -> 0
C13: =SUMIFS(BITACORA!$H$4:$H$7322,BITACORA!$D$4:$D$7322,$A$7:$A$100,BITACORA!$E$4:$E$7322,$B$7:$B$100,BITACORA!$B$4:$B$7322,">="&$B$3,BITACORA!$B$4:$B$7322,"<="&$B$4) -> 0 | D13: =SUMIFS(BITACORA!$I$4:$I$7322,BITACORA!$D$4:$D$7322,$A$7:$A$100,BITACORA!$E$4:$E$7322,$B$7:$B$100,BITACORA!$B$4:$B$7322,">="&$B$3,BITACORA!$B$4:$B$7322,"<="&$B$4) -> 0
C14: =SUMIFS(BITACORA!$H$4:$H$7322,BITACORA!$D$4:$D$7322,$A$7:$A$100,BITACORA!$E$4:$E$7322,$B$7:$B$100,BITACORA!$B$4:$B$7322,">="&$B$3,BITACORA!$B$4:$B$7322,"<="&$B$4) -> 0 | D14: =SUMIFS(BITACORA!$I$4:$I$7322,BITACORA!$D$4:$D$7322,$A$7:$A$100,BITACORA!$E$4:$E$7322,$B$7:$B$100,BITACORA!$B$4:$B$7322,">="&$B$3,BITACORA!$B$4:$B$7322,"<="&$B$4) -> 0
C15: =SUMIFS(BITACORA!$H$4:$H$7322,BITACORA!$D$4:$D$7322,$A$7:$A$100,BITACORA!$E$4:$E$7322,$B$7:$B$100,BITACORA!$B$4:$B$7322,">="&$B$3,BITACORA!$B$4:$B$7322,"<="&$B$4) -> 0 | D15: =SUMIFS(BITACORA!$I$4:$I$7322,BITACORA!$D$4:$D$7322,$A$7:$A$100,BITACORA!$E$4:$E$7322,$B$7:$B$100,BITACORA!$B$4:$B$7322,">="&$B$3,BITACORA!$B$4:$B$7322,"<="&$B$4) -> 0
C16: =SUMIFS(BITACORA!$H$4:$H$7322,BITACORA!$D$4:$D$7322,$A$7:$A$100,BITACORA!$E$4:$E$7322,$B$7:$B$100,BITACORA!$B$4:$B$7322,">="&$B$3,BITACORA!$B$4:$B$7322,"<="&$B$4) -> 0 | D16: =SUMIFS(BITACORA!$I$4:$I$7322,BITACORA!$D$4:$D$7322,$A$7:$A$100,BITACORA!$E$4:$E$7322,$B$7:$B$100,BITACORA!$B$4:$B$7322,">="&$B$3,BITACORA!$B$4:$B$7322,"<="&$B$4) -> 0
C17: =SUMIFS(BITACORA!$H$4:$H$7322,BITACORA!$D$4:$D$7322,$A$7:$A$100,BITACORA!$E$4:$E$7322,$B$7:$B$100,BITACORA!$B$4:$B$7322,">="&$B$3,BITACORA!$B$4:$B$7322,"<="&$B$4) -> 0 | D17: =SUMIFS(BITACORA!$I$4:$I$7322,BITACORA!$D$4:$D$7322,$A$7:$A$100,BITACORA!$E$4:$E$7322,$B$7:$B$100,BITACORA!$B$4:$B$7322,">="&$B$3,BITACORA!$B$4:$B$7322,"<="&$B$4) -> 0
C18: =SUMIFS(BITACORA!$H$4:$H$7322,BITACORA!$D$4:$D$7322,$A$7:$A$100,BITACORA!$E$4:$E$7322,$B$7:$B$100,BITACORA!$B$4:$B$7322,">="&$B$3,BITACORA!$B$4:$B$7322,"<="&$B$4) -> 0 | D18: =SUMIFS(BITACORA!$I$4:$I$7322,BITACORA!$D$4:$D$7322,$A$7:$A$100,BITACORA!$E$4:$E$7322,$B$7:$B$100,BITACORA!$B$4:$B$7322,">="&$B$3,BITACORA!$B$4:$B$7322,"<="&$B$4) -> 0
C19: =SUMIFS(BITACORA!$H$4:$H$7322,BITACORA!$D$4:$D$7322,$A$7:$A$100,BITACORA!$E$4:$E$7322,$B$7:$B$100,BITACORA!$B$4:$B$7322,">="&$B$3,BITACORA!$B$4:$B$7322,"<="&$B$4) -> 0 | D19: =SUMIFS(BITACORA!$I$4:$I$7322,BITACORA!$D$4:$D$7322,$A$7:$A$100,BITACORA!$E$4:$E$7322,$B$7:$B$100,BITACORA!$B$4:$B$7322,">="&$B$3,BITACORA!$B$4:$B$7322,"<="&$B$4) -> 0
C20: =SUMIFS(BITACORA!$H$4:$H$7322,BITACORA!$D$4:$D$7322,$A$7:$A$100,BITACORA!$E$4:$E$7322,$B$7:$B$100,BITACORA!$B$4:$B$7322,">="&$B$3,BITACORA!$B$4:$B$7322,"<="&$B$4) -> 0 | D20: =SUMIFS(BITACORA!$I$4:$I$7322,BITACORA!$D$4:$D$7322,$A$7:$A$100,BITACORA!$E$4:$E$7322,$B$7:$B$100,BITACORA!$B$4:$B$7322,">="&$B$3,BITACORA!$B$4:$B$7322,"<="&$B$4) -> 0
C21: =SUMIFS(BITACORA!$H$4:$H$7322,BITACORA!$D$4:$D$7322,$A$7:$A$100,BITACORA!$E$4:$E$7322,$B$7:$B$100,BITACORA!$B$4:$B$7322,">="&$B$3,BITACORA!$B$4:$B$7322,"<="&$B$4) -> 0 | D21: =SUMIFS(BITACORA!$I$4:$I$7322,BITACORA!$D$4:$D$7322,$A$7:$A$100,BITACORA!$E$4:$E$7322,$B$7:$B$100,BITACORA!$B$4:$B$7322,">="&$B$3,BITACORA!$B$4:$B$7322,"<="&$B$4) -> 0
A24: MADERA DE PLANTA | B24: FINCA EN PLANTA | C24: =SUMIFS(BITACORA!$H$4:$H$7322,BITACORA!$D$4:$D$7322,$A$7:$A$100,BITACORA!$E$4:$E$7322,$B$7:$B$100,BITACORA!$B$4:$B$7322,">="&$B$3,BITACORA!$B$4:$B$7322,"<="&$B$4) -> 0 | D24: =SUMIFS(BITACORA!$I$4:$I$7322,BITACORA!$D$4:$D$7322,$A$7:$A$100,BITACORA!$E$4:$E$7322,$B$7:$B$100,BITACORA!$B$4:$B$7322,">="&$B$3,BITACORA!$B$4:$B$7322,"<="&$B$4) -> 33 | E24: FINCA
A25: MUENTES CORNEJO JAVIER EDWIN | B25: LA SANDIA | C25: =SUMIFS(BITACORA!$H$4:$H$7322,BITACORA!$D$4:$D$7322,$A$7:$A$100,BITACORA!$E$4:$E$7322,$B$7:$B$100,BITACORA!$B$4:$B$7322,">="&$B$3,BITACORA!$B$4:$B$7322,"<="&$B$4) -> 800 | D25: =SUMIFS(BITACORA!$I$4:$I$7322,BITACORA!$D$4:$D$7322,$A$7:$A$100,BITACORA!$E$4:$E$7322,$B$7:$B$100,BITACORA!$B$4:$B$7322,">="&$B$3,BITACORA!$B$4:$B$7322,"<="&$B$4) -> 0
C26: =SUMIFS(BITACORA!$H$4:$H$7322,BITACORA!$D$4:$D$7322,$A$7:$A$100,BITACORA!$E$4:$E$7322,$B$7:$B$100,BITACORA!$B$4:$B$7322,">="&$B$3,BITACORA!$B$4:$B$7322,"<="&$B$4) -> 0 | D26: =SUMIFS(BITACORA!$I$4:$I$7322,BITACORA!$D$4:$D$7322,$A$7:$A$100,BITACORA!$E$4:$E$7322,$B$7:$B$100,BITACORA!$B$4:$B$7322,">="&$B$3,BITACORA!$B$4:$B$7322,"<="&$B$4) -> 0
C27: =SUMIFS(BITACORA!$H$4:$H$7322,BITACORA!$D$4:$D$7322,$A$7:$A$100,BITACORA!$E$4:$E$7322,$B$7:$B$100,BITACORA!$B$4:$B$7322,">="&$B$3,BITACORA!$B$4:$B$7322,"<="&$B$4) -> 0 | D27: =SUMIFS(BITACORA!$I$4:$I$7322,BITACORA!$D$4:$D$7322,$A$7:$A$100,BITACORA!$E$4:$E$7322,$B$7:$B$100,BITACORA!$B$4:$B$7322,">="&$B$3,BITACORA!$B$4:$B$7322,"<="&$B$4) -> 0
C28: =SUMIFS(BITACORA!$H$4:$H$7322,BITACORA!$D$4:$D$7322,$A$7:$A$100,BITACORA!$E$4:$E$7322,$B$7:$B$100,BITACORA!$B$4:$B$7322,">="&$B$3,BITACORA!$B$4:$B$7322,"<="&$B$4) -> 0 | D28: =SUMIFS(BITACORA!$I$4:$I$7322,BITACORA!$D$4:$D$7322,$A$7:$A$100,BITACORA!$E$4:$E$7322,$B$7:$B$100,BITACORA!$B$4:$B$7322,">="&$B$3,BITACORA!$B$4:$B$7322,"<="&$B$4) -> 0
C29: =SUMIFS(BITACORA!$H$4:$H$7322,BITACORA!$D$4:$D$7322,$A$7:$A$100,BITACORA!$E$4:$E$7322,$B$7:$B$100,BITACORA!$B$4:$B$7322,">="&$B$3,BITACORA!$B$4:$B$7322,"<="&$B$4) -> 0 | D29: =SUMIFS(BITACORA!$I$4:$I$7322,BITACORA!$D$4:$D$7322,$A$7:$A$100,BITACORA!$E$4:$E$7322,$B$7:$B$100,BITACORA!$B$4:$B$7322,">="&$B$3,BITACORA!$B$4:$B$7322,"<="&$B$4) -> 0
C30: =SUMIFS(BITACORA!$H$4:$H$7322,BITACORA!$D$4:$D$7322,$A$7:$A$100,BITACORA!$E$4:$E$7322,$B$7:$B$100,BITACORA!$B$4:$B$7322,">="&$B$3,BITACORA!$B$4:$B$7322,"<="&$B$4) -> 0 | D30: =SUMIFS(BITACORA!$I$4:$I$7322,BITACORA!$D$4:$D$7322,$A$7:$A$100,BITACORA!$E$4:$E$7322,$B$7:$B$100,BITACORA!$B$4:$B$7322,">="&$B$3,BITACORA!$B$4:$B$7322,"<="&$B$4) -> 0
A33: VELIZ ZAMBRANO JAIME GREGORIO | B33: RIO FRIO | C33: =SUMIFS(BITACORA!$H$4:$H$7322,BITACORA!$D$4:$D$7322,$A$7:$A$100,BITACORA!$E$4:$E$7322,$B$7:$B$100,BITACORA!$B$4:$B$7322,">="&$B$3,BITACORA!$B$4:$B$7322,"<="&$B$4) -> 0 | D33: =SUMIFS(BITACORA!$I$4:$I$7322,BITACORA!$D$4:$D$7322,$A$7:$A$100,BITACORA!$E$4:$E$7322,$B$7:$B$100,BITACORA!$B$4:$B$7322,">="&$B$3,BITACORA!$B$4:$B$7322,"<="&$B$4) -> 15779 | E33: BOSQUE
A34: COBEÑA QUINTERO RICARDO | B34: RIO FRIO ETAPA 2 | C34: =SUMIFS(BITACORA!$H$4:$H$7322,BITACORA!$D$4:$D$7322,$A$7:$A$100,BITACORA!$E$4:$E$7322,$B$7:$B$100,BITACORA!$B$4:$B$7322,">="&$B$3,BITACORA!$B$4:$B$7322,"<="&$B$4) -> 5890 | D34: =SUMIFS(BITACORA!$I$4:$I$7322,BITACORA!$D$4:$D$7322,$A$7:$A$100,BITACORA!$E$4:$E$7322,$B$7:$B$100,BITACORA!$B$4:$B$7322,">="&$B$3,BITACORA!$B$4:$B$7322,"<="&$B$4) -> 12410
A35: MUENTES CORNEJO LUIS GONZAGA | B35: BOSQUE PUERTO NUEVO | C35: =SUMIFS(BITACORA!$H$4:$H$7322,BITACORA!$D$4:$D$7322,$A$7:$A$100,BITACORA!$E$4:$E$7322,$B$7:$B$100,BITACORA!$B$4:$B$7322,">="&$B$3,BITACORA!$B$4:$B$7322,"<="&$B$4) -> 7850 | D35: =SUMIFS(BITACORA!$I$4:$I$7322,BITACORA!$D$4:$D$7322,$A$7:$A$100,BITACORA!$E$4:$E$7322,$B$7:$B$100,BITACORA!$B$4:$B$7322,">="&$B$3,BITACORA!$B$4:$B$7322,"<="&$B$4) -> 10508
C36: =SUMIFS(BITACORA!$H$4:$H$7322,BITACORA!$D$4:$D$7322,$A$7:$A$100,BITACORA!$E$4:$E$7322,$B$7:$B$100,BITACORA!$B$4:$B$7322,">="&$B$3,BITACORA!$B$4:$B$7322,"<="&$B$4) -> 0 | D36: =SUMIFS(BITACORA!$I$4:$I$7322,BITACORA!$D$4:$D$7322,$A$7:$A$100,BITACORA!$E$4:$E$7322,$B$7:$B$100,BITACORA!$B$4:$B$7322,">="&$B$3,BITACORA!$B$4:$B$7322,"<="&$B$4) -> 0
C37: =SUMIFS(BITACORA!$H$4:$H$7322,BITACORA!$D$4:$D$7322,$A$7:$A$100,BITACORA!$E$4:$E$7322,$B$7:$B$100,BITACORA!$B$4:$B$7322,">="&$B$3,BITACORA!$B$4:$B$7322,"<="&$B$4) -> 0 | D37: =SUMIFS(BITACORA!$I$4:$I$7322,BITACORA!$D$4:$D$7322,$A$7:$A$100,BITACORA!$E$4:$E$7322,$B$7:$B$100,BITACORA!$B$4:$B$7322,">="&$B$3,BITACORA!$B$4:$B$7322,"<="&$B$4) -> 0
C38: =SUMIFS(BITACORA!$H$4:$H$7322,BITACORA!$D$4:$D$7322,$A$7:$A$100,BITACORA!$E$4:$E$7322,$B$7:$B$100,BITACORA!$B$4:$B$7322,">="&$B$3,BITACORA!$B$4:$B$7322,"<="&$B$4) -> 0 | D38: =SUMIFS(BITACORA!$I$4:$I$7322,BITACORA!$D$4:$D$7322,$A$7:$A$100,BITACORA!$E$4:$E$7322,$B$7:$B$100,BITACORA!$B$4:$B$7322,">="&$B$3,BITACORA!$B$4:$B$7322,"<="&$B$4) -> 0
C39: =SUMIFS(BITACORA!$H$4:$H$7322,BITACORA!$D$4:$D$7322,$A$7:$A$100,BITACORA!$E$4:$E$7322,$B$7:$B$100,BITACORA!$B$4:$B$7322,">="&$B$3,BITACORA!$B$4:$B$7322,"<="&$B$4) -> 0 | D39: =SUMIFS(BITACORA!$I$4:$I$7322,BITACORA!$D$4:$D$7322,$A$7:$A$100,BITACORA!$E$4:$E$7322,$B$7:$B$100,BITACORA!$B$4:$B$7322,">="&$B$3,BITACORA!$B$4:$B$7322,"<="&$B$4) -> 0
C40: =SUMIFS(BITACORA!$H$4:$H$7322,BITACORA!$D$4:$D$7322,$A$7:$A$100,BITACORA!$E$4:$E$7322,$B$7:$B$100,BITACORA!$B$4:$B$7322,">="&$B$3,BITACORA!$B$4:$B$7322,"<="&$B$4) -> 0 | D40: =SUMIFS(BITACORA!$I$4:$I$7322,BITACORA!$D$4:$D$7322,$A$7:$A$100,BITACORA!$E$4:$E$7322,$B$7:$B$100,BITACORA!$B$4:$B$7322,">="&$B$3,BITACORA!$B$4:$B$7322,"<="&$B$4) -> 0
C41: =SUMIFS(BITACORA!$H$4:$H$7322,BITACORA!$D$4:$D$7322,$A$7:$A$100,BITACORA!$E$4:$E$7322,$B$7:$B$100,BITACORA!$B$4:$B$7322,">="&$B$3,BITACORA!$B$4:$B$7322,"<="&$B$4) -> 0 | D41: =SUMIFS(BITACORA!$I$4:$I$7322,BITACORA!$D$4:$D$7322,$A$7:$A$100,BITACORA!$E$4:$E$7322,$B$7:$B$100,BITACORA!$B$4:$B$7322,">="&$B$3,BITACORA!$B$4:$B$7322,"<="&$B$4) -> 0
A44: ANAGUANO GALARRAGA FAUSTO | B44: VARIOS | C44: =SUMIFS(BITACORA!$H$4:$H$7322,BITACORA!$D$4:$D$7322,$A$7:$A$100,BITACORA!$E$4:$E$7322,$B$7:$B$100,BITACORA!$B$4:$B$7322,">="&$B$3,BITACORA!$B$4:$B$7322,"<="&$B$4) -> 0 | D44: =SUMIFS(BITACORA!$I$4:$I$7322,BITACORA!$D$4:$D$7322,$A$7:$A$100,BITACORA!$E$4:$E$7322,$B$7:$B$100,BITACORA!$B$4:$B$7322,">="&$B$3,BITACORA!$B$4:$B$7322,"<="&$B$4) -> 110 | E44: PROVEEDORES
A45: BRAVO BRAVO MILTON GABRIEL | B45: VARIOS | C45: =SUMIFS(BITACORA!$H$4:$H$7322,BITACORA!$D$4:$D$7322,$A$7:$A$100,BITACORA!$E$4:$E$7322,$B$7:$B$100,BITACORA!$B$4:$B$7322,">="&$B$3,BITACORA!$B$4:$B$7322,"<="&$B$4) -> 0 | D45: =SUMIFS(BITACORA!$I$4:$I$7322,BITACORA!$D$4:$D$7322,$A$7:$A$100,BITACORA!$E$4:$E$7322,$B$7:$B$100,BITACORA!$B$4:$B$7322,">="&$B$3,BITACORA!$B$4:$B$7322,"<="&$B$4) -> 320
A46: DOMINGUEZ CHIRIBOGA JORGE VICENTE | B46: VARIOS | C46: =SUMIFS(BITACORA!$H$4:$H$7322,BITACORA!$D$4:$D$7322,$A$7:$A$100,BITACORA!$E$4:$E$7322,$B$7:$B$100,BITACORA!$B$4:$B$7322,">="&$B$3,BITACORA!$B$4:$B$7322,"<="&$B$4) -> 3600 | D46: =SUMIFS(BITACORA!$I$4:$I$7322,BITACORA!$D$4:$D$7322,$A$7:$A$100,BITACORA!$E$4:$E$7322,$B$7:$B$100,BITACORA!$B$4:$B$7322,">="&$B$3,BITACORA!$B$4:$B$7322,"<="&$B$4) -> 5480
...

Sheet FLETES (#) MAYO
A1: MES | B1: ABRIL | C1: =COUNTIFS(BITACORA!B4:B7322,">="&B3,BITACORA!B4:B7322,"<="&B4) -> 138 | E1: TOTAL DE VIAJES FLETADOS | F1: =SUM(D7:D504) -> 18
D2: 3
A3: FECHA DE INICIO | B3: 44317 | D3: 4 | E3: 170 | F3: 180
A4: FECHA DE CORTE | B4: 44347 | D4: 5 | E4: 190 | F4: 200
D5: 6
A6: =IFERROR(__xludf.DUMMYFUNCTION("IMPORTRANGE(""https://docs.google.com/spreadsheets/d/1utvdjsQjm2nB6A8-WaesD8IPx5qFCLXNwJxEgiS8wno/edit?usp=sharing"",""TRANSPORTISTAS!A1:C500"")"),"TRANSPORTISTA") -> TRANSPORTISTA | B6: =IFERROR(__xludf.DUMMYFUNCTION("""COMPUTED_VALUE"""),"PLACA DEL VEHICULO") -> PLACA DEL VEHICULO | C6: =IFERROR(__xludf.DUMMYFUNCTION("""COMPUTED_VALUE"""),"CAPACIDAD (FILAS)") -> CAPACIDAD (FILAS) | D6: TOTAL DE VIAJES | E6: =LISTAS!$B7 -> TACHINA | F6: =LISTAS!$B8 -> TRES VIAS | G6: =LISTAS!$B9 -> QUININDE | H6: =LISTAS!$B10 -> TAISHA | I6: =LISTAS!$B11 -> ARAJUNO | J6: =LISTAS!$B12 -> 0 | K6: =LISTAS!$B13 -> 0 | L6: =LISTAS!$B14 -> 0 | M6: =LISTAS!$B15 -> 0 | N6: =LISTAS!$B16 -> 0 | O6: =LISTAS!$B17 -> 0 | P6: =LISTAS!$B18 -> 0 | Q6: =LISTAS!$B19 -> 0 | R6: =LISTAS!$B20 -> 0 | S6: =LISTAS!$B21 -> 0 | T6: =LISTAS!$B22 -> 0 | U6: =LISTAS!$B23 -> 0 | V6: =LISTAS!$B24 -> FINCA EN PLANTA | W6: =LISTAS!$B25 -> LA SANDIA | X6: =LISTAS!$B26 -> 0 | Y6: =LISTAS!$B27 -> 0 | Z6: =LISTAS!$B28 -> 0 | AA6: =LISTAS!$B29 -> 0 | AB6: =LISTAS!$B30 -> 0 | AC6: =LISTAS!$B31 -> 0 | AD6: =LISTAS!$B32 -> 0 | AE6: =LISTAS!$B33 -> RIO FRIO | AF6: =LISTAS!$B34 -> RIO FRIO ETAPA 2 | AG6: =LISTAS!$B35 -> BOSQUE PUERTO NUEVO | AH6: =LISTAS!$B36 -> 0 | AI6: =LISTAS!$B37 -> 0 | AJ6: =LISTAS!$B38 -> 0 | AK6: =LISTAS!$B39 -> 0 | AL6: =LISTAS!$B40 -> 0 | AM6: =LISTAS!$B41 -> 0
A7: =IFERROR(__xludf.DUMMYFUNCTION("""COMPUTED_VALUE"""),"Klever Enrique Moreira Cedeño") -> Klever Enrique Moreira Cedeño | B7: =IFERROR(__xludf.DUMMYFUNCTION("""COMPUTED_VALUE"""),"JAR4061") -> JAR4061 | C7: =IFERROR(__xludf.DUMMYFUNCTION("""COMPUTED_VALUE"""),3) -> 3 | D7: =SUM(E7:AM7) -> 0 | E7: =COUNTIFS(BITACORA!$C$4:$C$7322,$B$7:$B$501,BITACORA!$E$4:$E$7322,$E$6:$AM$6,BITACORA!$B$4:$B$7322,">="&$B$3,BITACORA!$B$4:$B$7322,"<="&$B$4) -> 0 | F7: =COUNTIFS(BITACORA!$C$4:$C$7322,$B$7:$B$501,BITACORA!$E$4:$E$7322,$E$6:$AM$6,BITACORA!$B$4:$B$7322,">="&$B$3,BITACORA!$B$4:$B$7322,"<="&$B$4) -> 0 | G7: =COUNTIFS(BITACORA!$C$4:$C$7322,$B$7:$B$501,BITACORA!$E$4:$E$7322,$E$6:$AM$6,BITACORA!$B$4:$B$7322,">="&$B$3,BITACORA!$B$4:$B$7322,"<="&$B$4) -> 0 | H7: =COUNTIFS(BITACORA!$C$4:$C$7322,$B$7:$B$501,BITACORA!$E$4:$E$7322,$E$6:$AM$6,BITACORA!$B$4:$B$7322,">="&$B$3,BITACORA!$B$4:$B$7322,"<="&$B$4) -> 0 | I7: =COUNTIFS(BITACORA!$C$4:$C$7322,$B$7:$B$501,BITACORA!$E$4:$E$7322,$E$6:$AM$6,BITACORA!$B$4:$B$7322,">="&$B$3,BITACORA!$B$4:$B$7322,"<="&$B$4) -> 0 | J7: =COUNTIFS(BITACORA!$C$4:$C$7322,$B$7:$B$501,BITACORA!$E$4:$E$7322,$E$6:$AM$6,BITACORA!$B$4:$B$7322,">="&$B$3,BITACORA!$B$4:$B$7322,"<="&$B$4) -> 0 | K7: =COUNTIFS(BITACORA!$C$4:$C$7322,$B$7:$B$501,BITACORA!$E$4:$E$7322,$E$6:$AM$6,BITACORA!$B$4:$B$7322,">="&$B$3,BITACORA!$B$4:$B$7322,"<="&$B$4) -> 0 | L7: =COUNTIFS(BITACORA!$C$4:$C$7322,$B$7:$B$501,BITACORA!$E$4:$E$7322,$E$6:$AM$6,BITACORA!$B$4:$B$7322,">="&$B$3,BITACORA!$B$4:$B$7322,"<="&$B$4) -> 0 | ... AM7: =COUNTIFS(BITACORA!$C$4:$C$7322,$B$7:$B$501,BITACORA!$E$4:$E$7322,$E$6:$AM$6,BITACORA!$B$4:$B$7322,">="&$B$3,BITACORA!$B$4:$B$7322,"<="&$B$4) -> 0
A8: =IFERROR(__xludf.DUMMYFUNCTION("""COMPUTED_VALUE"""),"Ricardo Coveña Quintero") -> Ricardo Coveña Quintero | B8: =IFERROR(__xludf.DUMMYFUNCTION("""COMPUTED_VALUE"""),"PPX0724") -> PPX0724 | C8: =IFERROR(__xludf.DUMMYFUNCTION("""COMPUTED_VALUE"""),3) -> 3 | D8: =SUM(E8:AM8) -> 0 | E8: =COUNTIFS(BITACORA!$C$4:$C$7322,$B$7:$B$501,BITACORA!$E$4:$E$7322,$E$6:$AM$6,BITACORA!$B$4:$B$7322,">="&$B$3,BITACORA!$B$4:$B$7322,"<="&$B$4) -> 0 | F8: =COUNTIFS(BITACORA!$C$4:$C$7322,$B$7:$B$501,BITACORA!$E$4:$E$7322,$E$6:$AM$6,BITACORA!$B$4:$B$7322,">="&$B$3,BITACORA!$B$4:$B$7322,"<="&$B$4) -> 0 | G8: =COUNTIFS(BITACORA!$C$4:$C$7322,$B$7:$B$501,BITACORA!$E$4:$E$7322,$E$6:$AM$6,BITACORA!$B$4:$B$7322,">="&$B$3,BITACORA!$B$4:$B$7322,"<="&$B$4) -> 0 | H8: =COUNTIFS(BITACORA!$C$4:$C$7322,$B$7:$B$501,BITACORA!$E$4:$E$7322,$E$6:$AM$6,BITACORA!$B$4:$B$7322,">="&$B$3,BITACORA!$B$4:$B$7322,"<="&$B$4) -> 0 | I8: =COUNTIFS(BITACORA!$C$4:$C$7322,$B$7:$B$501,BITACORA!$E$4:$E$7322,$E$6:$AM$6,BITACORA!$B$4:$B$7322,">="&$B$3,BITACORA!$B$4:$B$7322,"<="&$B$4) -> 0 | J8: =COUNTIFS(BITACORA!$C$4:$C$7322,$B$7:$B$501,BITACORA!$E$4:$E$7322,$E$6:$AM$6,BITACORA!$B$4:$B$7322,">="&$B$3,BITACORA!$B$4:$B$7322,"<="&$B$4) -> 0 | K8: =COUNTIFS(BITACORA!$C$4:$C$7322,$B$7:$B$501,BITACORA!$E$4:$E$7322,$E$6:$AM$6,BITACORA!$B$4:$B$7322,">="&$B$3,BITACORA!$B$4:$B$7322,"<="&$B$4) -> 0 | L8: =COUNTIFS(BITACORA!$C$4:$C$7322,$B$7:$B$501,BITACORA!$E$4:$E$7322,$E$6:$AM$6,BITACORA!$B$4:$B$7322,">="&$B$3,BITACORA!$B$4:$B$7322,"<="&$B$4) -> 0 | ... AM8: =COUNTIFS(BITACORA!$C$4:$C$7322,$B$7:$B$501,BITACORA!$E$4:$E$7322,$E$6:$AM$6,BITACORA!$B$4:$B$7322,">="&$B$3,BITACORA!$B$4:$B$7322,"<="&$B$4) -> 0
A9: =IFERROR(__xludf.DUMMYFUNCTION("""COMPUTED_VALUE"""),"Cesar Octavio Aguilar Loor") -> Cesar Octavio Aguilar Loor | B9: =IFERROR(__xludf.DUMMYFUNCTION("""COMPUTED_VALUE"""),"MCW0186") -> MCW0186 | C9: =IFERROR(__xludf.DUMMYFUNCTION("""COMPUTED_VALUE"""),4) -> 4 | D9: =SUM(E9:AM9) -> 1 | E9: =COUNTIFS(BITACORA!$C$4:$C$7322,$B$7:$B$501,BITACORA!$E$4:$E$7322,$E$6:$AM$6,BITACORA!$B$4:$B$7322,">="&$B$3,BITACORA!$B$4:$B$7322,"<="&$B$4) -> 0 | F9: =COUNTIFS(BITACORA!$C$4:$C$7322,$B$7:$B$501,BITACORA!$E$4:$E$7322,$E$6:$AM$6,BITACORA!$B$4:$B$7322,">="&$B$3,BITACORA!$B$4:$B$7322,"<="&$B$4) -> 1 | G9: =COUNTIFS(BITACORA!$C$4:$C$7322,$B$7:$B$501,BITACORA!$E$4:$E$7322,$E$6:$AM$6,BITACORA!$B$4:$B$7322,">="&$B$3,BITACORA!$B$4:$B$7322,"<="&$B$4) -> 0 | H9: =COUNTIFS(BITACORA!$C$4:$C$7322,$B$7:$B$501,BITACORA!$E$4:$E$7322,$E$6:$AM$6,BITACORA!$B$4:$B$7322,">="&$B$3,BITACORA!$B$4:$B$7322,"<="&$B$4) -> 0 | I9: =COUNTIFS(BITACORA!$C$4:$C$7322,$B$7:$B$501,BITACORA!$E$4:$E$7322,$E$6:$AM$6,BITACORA!$B$4:$B$7322,">="&$B$3,BITACORA!$B$4:$B$7322,"<="&$B$4) -> 0 | J9: =COUNTIFS(BITACORA!$C$4:$C$7322,$B$7:$B$501,BITACORA!$E$4:$E$7322,$E$6:$AM$6,BITACORA!$B$4:$B$7322,">="&$B$3,BITACORA!$B$4:$B$7322,"<="&$B$4) -> 0 | K9: =COUNTIFS(BITACORA!$C$4:$C$7322,$B$7:$B$501,BITACORA!$E$4:$E$7322,$E$6:$AM$6,BITACORA!$B$4:$B$7322,">="&$B$3,BITACORA!$B$4:$B$7322,"<="&$B$4) -> 0 | L9: =COUNTIFS(BITACORA!$C$4:$C$7322,$B$7:$B$501,BITACORA!$E$4:$E$7322,$E$6:$AM$6,BITACORA!$B$4:$B$7322,">="&$B$3,BITACORA!$B$4:$B$7322,"<="&$B$4) -> 0 | ... AM9: =COUNTIFS(BITACORA!$C$4:$C$7322,$B$7:$B$501,BITACORA!$E$4:$E$7322,$E$6:$AM$6,BITACORA!$B$4:$B$7322,">="&$B$3,BITACORA!$B$4:$B$7322,"<="&$B$4) -> 0
A10: =IFERROR(__xludf.DUMMYFUNCTION("""COMPUTED_VALUE"""),"Jonathan Jehova Vera Mendoza") -> Jonathan Jehova Vera Mendoza | B10: =IFERROR(__xludf.DUMMYFUNCTION("""COMPUTED_VALUE"""),"JAA3367") -> JAA3367 | C10: =IFERROR(__xludf.DUMMYFUNCTION("""COMPUTED_VALUE"""),4) -> 4 | D10: =SUM(E10:AM10) -> 0 | E10: =COUNTIFS(BITACORA!$C$4:$C$7322,$B$7:$B$501,BITACORA!$E$4:$E$7322,$E$6:$AM$6,BITACORA!$B$4:$B$7322,">="&$B$3,BITACORA!$B$4:$B$7322,"<="&$B$4) -> 0 | F10: =COUNTIFS(BITACORA!$C$4:$C$7322,$B$7:$B$501,BITACORA!$E$4:$E$7322,$E$6:$AM$6,BITACORA!$B$4:$B$7322,">="&$B$3,BITACORA!$B$4:$B$7322,"<="&$B$4) -> 0 | G10: =COUNTIFS(BITACORA!$C$4:$C$7322,$B$7:$B$501,BITACORA!$E$4:$E$7322,$E$6:$AM$6,BITACORA!$B$4:$B$7322,">="&$B$3,BITACORA!$B$4:$B$7322,"<="&$B$4) -> 0 | H10: =COUNTIFS(BITACORA!$C$4:$C$7322,$B$7:$B$501,BITACORA!$E$4:$E$7322,$E$6:$AM$6,BITACORA!$B$4:$B$7322,">="&$B$3,BITACORA!$B$4:$B$7322,"<="&$B$4) -> 0 | I10: =COUNTIFS(BITACORA!$C$4:$C$7322,$B$7:$B$501,BITACORA!$E$4:$E$7322,$E$6:$AM$6,BITACORA!$B$4:$B$7322,">="&$B$3,BITACORA!$B$4:$B$7322,"<="&$B$4) -> 0 | J10: =COUNTIFS(BITACORA!$C$4:$C$7322,$B$7:$B$501,BITACORA!$E$4:$E$7322,$E$6:$AM$6,BITACORA!$B$4:$B$7322,">="&$B$3,BITACORA!$B$4:$B$7322,"<="&$B$4) -> 0 | K10: =COUNTIFS(BITACORA!$C$4:$C$7322,$B$7:$B$501,BITACORA!$E$4:$E$7322,$E$6:$AM$6,BITACORA!$B$4:$B$7322,">="&$B$3,BITACORA!$B$4:$B$7322,"<="&$B$4) -> 0 | L10: =COUNTIFS(BITACORA!$C$4:$C$7322,$B$7:$B$501,BITACORA!$E$4:$E$7322,$E$6:$AM$6,BITACORA!$B$4:$B$7322,">="&$B$3,BITACORA!$B$4:$B$7322,"<="&$B$4) -> 0 | ... AM10: =COUNTIFS(BITACORA!$C$4:$C$7322,$B$7:$B$501,BITACORA!$E$4:$E$7322,$E$6:$AM$6,BITACORA!$B$4:$B$7322,">="&$B$3,BITACORA!$B$4:$B$7322,"<="&$B$4) -> 0
A11: =IFERROR(__xludf.DUMMYFUNCTION("""COMPUTED_VALUE"""),"Emerson Fabricio Moreira Alcivar") -> Emerson Fabricio Moreira Alcivar | B11: =IFERROR(__xludf.DUMMYFUNCTION("""COMPUTED_VALUE"""),"JAA3375") -> JAA3375 | C11: =IFERROR(__xludf.DUMMYFUNCTION("""COMPUTED_VALUE"""),4) -> 4 | D11: =SUM(E11:AM11) -> 3 | E11: =COUNTIFS(BITACORA!$C$4:$C$7322,$B$7:$B$501,BITACORA!$E$4:$E$7322,$E$6:$AM$6,BITACORA!$B$4:$B$7322,">="&$B$3,BITACORA!$B$4:$B$7322,"<="&$B$4) -> 0 | F11: =COUNTIFS(BITACORA!$C$4:$C$7322,$B$7:$B$501,BITACORA!$E$4:$E$7322,$E$6:$AM$6,BITACORA!$B$4:$B$7322,">="&$B$3,BITACORA!$B$4:$B$7322,"<="&$B$4) -> 3 | G11: =COUNTIFS(BITACORA!$C$4:$C$7322,$B$7:$B$501,BITACORA!$E$4:$E$7322,$E$6:$AM$6,BITACORA!$B$4:$B$7322,">="&$B$3,BITACORA!$B$4:$B$7322,"<="&$B$4) -> 0 | H11: =COUNTIFS(BITACORA!$C$4:$C$7322,$B$7:$B$501,BITACORA!$E$4:$E$7322,$E$6:$AM$6,BITACORA!$B$4:$B$7322,">="&$B$3,BITACORA!$B$4:$B$7322,"<="&$B$4) -> 0 | I11: =COUNTIFS(BITACORA!$C$4:$C$7322,$B$7:$B$501,BITACORA!$E$4:$E$7322,$E$6:$AM$6,BITACORA!$B$4:$B$7322,">="&$B$3,BITACORA!$B$4:$B$7322,"<="&$B$4) -> 0 | J11: =COUNTIFS(BITACORA!$C$4:$C$7322,$B$7:$B$501,BITACORA!$E$4:$E$7322,$E$6:$AM$6,BITACORA!$B$4:$B$7322,">="&$B$3,BITACORA!$B$4:$B$7322,"<="&$B$4) -> 0 | K11: =COUNTIFS(BITACORA!$C$4:$C$7322,$B$7:$B$501,BITACORA!$E$4:$E$7322,$E$6:$AM$6,BITACORA!$B$4:$B$7322,">="&$B$3,BITACORA!$B$4:$B$7322,"<="&$B$4) -> 0 | L11: =COUNTIFS(BITACORA!$C$4:$C$7322,$B$7:$B$501,BITACORA!$E$4:$E$7322,$E$6:$AM$6,BITACORA!$B$4:$B$7322,">="&$B$3,BITACORA!$B$4:$B$7322,"<="&$B$4) -> 0 | ... AM11: =COUNTIFS(BITACORA!$C$4:$C$7322,$B$7:$B$501,BITACORA!$E$4:$E$7322,$E$6:$AM$6,BITACORA!$B$4:$B$7322,">="&$B$3,BITACORA!$B$4:$B$7322,"<="&$B$4) -> 0
A12: =IFERROR(__xludf.DUMMYFUNCTION("""COMPUTED_VALUE"""),"Cedeño Barveran Marcelo German") -> Cedeño Barveran Marcelo German | B12: =IFERROR(__xludf.DUMMYFUNCTION("""COMPUTED_VALUE"""),"MAP0286") -> MAP0286 | C12: =IFERROR(__xludf.DUMMYFUNCTION("""COMPUTED_VALUE"""),4) -> 4 | D12: =SUM(E12:AM12) -> 0 | E12: =COUNTIFS(BITACORA!$C$4:$C$7322,$B$7:$B$501,BITACORA!$E$4:$E$7322,$E$6:$AM$6,BITACORA!$B$4:$B$7322,">="&$B$3,BITACORA!$B$4:$B$7322,"<="&$B$4) -> 0 | F12: =COUNTIFS(BITACORA!$C$4:$C$7322,$B$7:$B$501,BITACORA!$E$4:$E$7322,$E$6:$AM$6,BITACORA!$B$4:$B$7322,">="&$B$3,BITACORA!$B$4:$B$7322,"<="&$B$4) -> 0 | G12: =COUNTIFS(BITACORA!$C$4:$C$7322,$B$7:$B$501,BITACORA!$E$4:$E$7322,$E$6:$AM$6,BITACORA!$B$4:$B$7322,">="&$B$3,BITACORA!$B$4:$B$7322,"<="&$B$4) -> 0 | H12: =COUNTIFS(BITACORA!$C$4:$C$7322,$B$7:$B$501,BITACORA!$E$4:$E$7322,$E$6:$AM$6,BITACORA!$B$4:$B$7322,">="&$B$3,BITACORA!$B$4:$B$7322,"<="&$B$4) -> 0 | I12: =COUNTIFS(BITACORA!$C$4:$C$7322,$B$7:$B$501,BITACORA!$E$4:$E$7322,$E$6:$AM$6,BITACORA!$B$4:$B$7322,">="&$B$3,BITACORA!$B$4:$B$7322,"<="&$B$4) -> 0 | J12: =COUNTIFS(BITACORA!$C$4:$C$7322,$B$7:$B$501,BITACORA!$E$4:$E$7322,$E$6:$AM$6,BITACORA!$B$4:$B$7322,">="&$B$3,BITACORA!$B$4:$B$7322,"<="&$B$4) -> 0 | K12: =COUNTIFS(BITACORA!$C$4:$C$7322,$B$7:$B$501,BITACORA!$E$4:$E$7322,$E$6:$AM$6,BITACORA!$B$4:$B$7322,">="&$B$3,BITACORA!$B$4:$B$7322,"<="&$B$4) -> 0 | L12: =COUNTIFS(BITACORA!$C$4:$C$7322,$B$7:$B$501,BITACORA!$E$4:$E$7322,$E$6:$AM$6,BITACORA!$B$4:$B$7322,">="&$B$3,BITACORA!$B$4:$B$7322,"<="&$B$4) -> 0 | ... AM12: =COUNTIFS(BITACORA!$C$4:$C$7322,$B$7:$B$501,BITACORA!$E$4:$E$7322,$E$6:$AM$6,BITACORA!$B$4:$B$7322,">="&$B$3,BITACORA!$B$4:$B$7322,"<="&$B$4) -> 0
A13: =IFERROR(__xludf.DUMMYFUNCTION("""COMPUTED_VALUE"""),"Jonathan Alejandro Diaz Montes") -> Jonathan Alejandro Diaz Montes | B13: =IFERROR(__xludf.DUMMYFUNCTION("""COMPUTED_VALUE"""),"PQX0243") -> PQX0243 | C13: =IFERROR(__xludf.DUMMYFUNCTION("""COMPUTED_VALUE"""),4) -> 4 | D13: =SUM(E13:AM13) -> 0 | E13: =COUNTIFS(BITACORA!$C$4:$C$7322,$B$7:$B$501,BITACORA!$E$4:$E$7322,$E$6:$AM$6,BITACORA!$B$4:$B$7322,">="&$B$3,BITACORA!$B$4:$B$7322,"<="&$B$4) -> 0 | F13: =COUNTIFS(BITACORA!$C$4:$C$7322,$B$7:$B$501,BITACORA!$E$4:$E$7322,$E$6:$AM$6,BITACORA!$B$4:$B$7322,">="&$B$3,BITACORA!$B$4:$B$7322,"<="&$B$4) -> 0 | G13: =COUNTIFS(BITACORA!$C$4:$C$7322,$B$7:$B$501,BITACORA!$E$4:$E$7322,$E$6:$AM$6,BITACORA!$B$4:$B$7322,">="&$B$3,BITACORA!$B$4:$B$7322,"<="&$B$4) -> 0 | H13: =COUNTIFS(BITACORA!$C$4:$C$7322,$B$7:$B$501,BITACORA!$E$4:$E$7322,$E$6:$AM$6,BITACORA!$B$4:$B$7322,">="&$B$3,BITACORA!$B$4:$B$7322,"<="&$B$4) -> 0 | I13: =COUNTIFS(BITACORA!$C$4:$C$7322,$B$7:$B$501,BITACORA!$E$4:$E$7322,$E$6:$AM$6,BITACORA!$B$4:$B$7322,">="&$B$3,BITACORA!$B$4:$B$7322,"<="&$B$4) -> 0 | J13: =COUNTIFS(BITACORA!$C$4:$C$7322,$B$7:$B$501,BITACORA!$E$4:$E$7322,$E$6:$AM$6,BITACORA!$B$4:$B$7322,">="&$B$3,BITACORA!$B$4:$B$7322,"<="&$B$4) -> 0 | K13: =COUNTIFS(BITACORA!$C$4:$C$7322,$B$7:$B$501,BITACORA!$E$4:$E$7322,$E$6:$AM$6,BITACORA!$B$4:$B$7322,">="&$B$3,BITACORA!$B$4:$B$7322,"<="&$B$4) -> 0 | L13: =COUNTIFS(BITACORA!$C$4:$C$7322,$B$7:$B$501,BITACORA!$E$4:$E$7322,$E$6:$AM$6,BITACORA!$B$4:$B$7322,">="&$B$3,BITACORA!$B$4:$B$7322,"<="&$B$4) -> 0 | ... AM13: =COUNTIFS(BITACORA!$C$4:$C$7322,$B$7:$B$501,BITACORA!$E$4:$E$7322,$E$6:$AM$6,BITACORA!$B$4:$B$7322,">="&$B$3,BITACORA!$B$4:$B$7322,"<="&$B$4) -> 0
A14: =IFERROR(__xludf.DUMMYFUNCTION("""COMPUTED_VALUE"""),"Freddy Amador Napa Rosado") -> Freddy Amador Napa Rosado | B14: =IFERROR(__xludf.DUMMYFUNCTION("""COMPUTED_VALUE"""),"PIB0529") -> PIB0529 | C14: =IFERROR(__xludf.DUMMYFUNCTION("""COMPUTED_VALUE"""),4) -> 4 | D14: =SUM(E14:AM14) -> 0 | E14: =COUNTIFS(BITACORA!$C$4:$C$7322,$B$7:$B$501,BITACORA!$E$4:$E$7322,$E$6:$AM$6,BITACORA!$B$4:$B$7322,">="&$B$3,BITACORA!$B$4:$B$7322,"<="&$B$4) -> 0 | F14: =COUNTIFS(BITACORA!$C$4:$C$7322,$B$7:$B$501,BITACORA!$E$4:$E$7322,$E$6:$AM$6,BITACORA!$B$4:$B$7322,">="&$B$3,BITACORA!$B$4:$B$7322,"<="&$B$4) -> 0 | G14: =COUNTIFS(BITACORA!$C$4:$C$7322,$B$7:$B$501,BITACORA!$E$4:$E$7322,$E$6:$AM$6,BITACORA!$B$4:$B$7322,">="&$B$3,BITACORA!$B$4:$B$7322,"<="&$B$4) -> 0 | H14: =COUNTIFS(BITACORA!$C$4:$C$7322,$B$7:$B$501,BITACORA!$E$4:$E$7322,$E$6:$AM$6,BITACORA!$B$4:$B$7322,">="&$B$3,BITACORA!$B$4:$B$7322,"<="&$B$4) -> 0 | I14: =COUNTIFS(BITACORA!$C$4:$C$7322,$B$7:$B$501,BITACORA!$E$4:$E$7322,$E$6:$AM$6,BITACORA!$B$4:$B$7322,">="&$B$3,BITACORA!$B$4:$B$7322,"<="&$B$4) -> 0 | J14: =COUNTIFS(BITACORA!$C$4:$C$7322,$B$7:$B$501,BITACORA!$E$4:$E$7322,$E$6:$AM$6,BITACORA!$B$4:$B$7322,">="&$B$3,BITACORA!$B$4:$B$7322,"<="&$B$4) -> 0 | K14: =COUNTIFS(BITACORA!$C$4:$C$7322,$B$7:$B$501,BITACORA!$E$4:$E$7322,$E$6:$AM$6,BITACORA!$B$4:$B$7322,">="&$B$3,BITACORA!$B$4:$B$7322,"<="&$B$4) -> 0 | L14: =COUNTIFS(BITACORA!$C$4:$C$7322,$B$7:$B$501,BITACORA!$E$4:$E$7322,$E$6:$AM$6,BITACORA!$B$4:$B$7322,">="&$B$3,BITACORA!$B$4:$B$7322,"<="&$B$4) -> 0 | ... AM14: =COUNTIFS(BITACORA!$C$4:$C$7322,$B$7:$B$501,BITACORA!$E$4:$E$7322,$E$6:$AM$6,BITACORA!$B$4:$B$7322,">="&$B$3,BITACORA!$B$4:$B$7322,"<="&$B$4) -> 0
A15: =IFERROR(__xludf.DUMMYFUNCTION("""COMPUTED_VALUE"""),"Diego Adrian Mendoza Velez") -> Diego Adrian Mendoza Velez | B15: =IFERROR(__xludf.DUMMYFUNCTION("""COMPUTED_VALUE"""),"JAA3376") -> JAA3376 | C15: =IFERROR(__xludf.DUMMYFUNCTION("""COMPUTED_VALUE"""),4) -> 4 | D15: =SUM(E15:AM15) -> 0 | E15: =COUNTIFS(BITACORA!$C$4:$C$7322,$B$7:$B$501,BITACORA!$E$4:$E$7322,$E$6:$AM$6,BITACORA!$B$4:$B$7322,">="&$B$3,BITACORA!$B$4:$B$7322,"<="&$B$4) -> 0 | F15: =COUNTIFS(BITACORA!$C$4:$C$7322,$B$7:$B$501,BITACORA!$E$4:$E$7322,$E$6:$AM$6,BITACORA!$B$4:$B$7322,">="&$B$3,BITACORA!$B$4:$B$7322,"<="&$B$4) -> 0 | G15: =COUNTIFS(BITACORA!$C$4:$C$7322,$B$7:$B$501,BITACORA!$E$4:$E$7322,$E$6:$AM$6,BITACORA!$B$4:$B$7322,">="&$B$3,BITACORA!$B$4:$B$7322,"<="&$B$4) -> 0 | H15: =COUNTIFS(BITACORA!$C$4:$C$7322,$B$7:$B$501,BITACORA!$E$4:$E$7322,$E$6:$AM$6,BITACORA!$B$4:$B$7322,">="&$B$3,BITACORA!$B$4:$B$7322,"<="&$B$4) -> 0 | I15: =COUNTIFS(BITACORA!$C$4:$C$7322,$B$7:$B$501,BITACORA!$E$4:$E$7322,$E$6:$AM$6,BITACORA!$B$4:$B$7322,">="&$B$3,BITACORA!$B$4:$B$7322,"<="&$B$4) -> 0 | J15: =COUNTIFS(BITACORA!$C$4:$C$7322,$B$7:$B$501,BITACORA!$E$4:$E$7322,$E$6:$AM$6,BITACORA!$B$4:$B$7322,">="&$B$3,BITACORA!$B$4:$B$7322,"<="&$B$4) -> 0 | K15: =COUNTIFS(BITACORA!$C$4:$C$7322,$B$7:$B$501,BITACORA!$E$4:$E$7322,$E$6:$AM$6,BITACORA!$B$4:$B$7322,">="&$B$3,BITACORA!$B$4:$B$7322,"<="&$B$4) -> 0 | L15: =COUNTIFS(BITACORA!$C$4:$C$7322,$B$7:$B$501,BITACORA!$E$4:$E$7322,$E$6:$AM$6,BITACORA!$B$4:$B$7322,">="&$B$3,BITACORA!$B$4:$B$7322,"<="&$B$4) -> 0 | ... AM15: =COUNTIFS(BITACORA!$C$4:$C$7322,$B$7:$B$501,BITACORA!$E$4:$E$7322,$E$6:$AM$6,BITACORA!$B$4:$B$7322,">="&$B$3,BITACORA!$B$4:$B$7322,"<="&$B$4) -> 0
A16: =IFERROR(__xludf.DUMMYFUNCTION("""COMPUTED_VALUE"""),"Oscar Jose Loor Basurto") -> Oscar Jose Loor Basurto | B16: =IFERROR(__xludf.DUMMYFUNCTION("""COMPUTED_VALUE"""),"PJB0702") -> PJB0702 | C16: =IFERROR(__xludf.DUMMYFUNCTION("""COMPUTED_VALUE"""),4) -> 4 | D16: =SUM(E16:AM16) -> 0 | E16: =COUNTIFS(BITACORA!$C$4:$C$7322,$B$7:$B$501,BITACORA!$E$4:$E$7322,$E$6:$AM$6,BITACORA!$B$4:$B$7322,">="&$B$3,BITACORA!$B$4:$B$7322,"<="&$B$4) -> 0 | F16: =COUNTIFS(BITACORA!$C$4:$C$7322,$B$7:$B$501,BITACORA!$E$4:$E$7322,$E$6:$AM$6,BITACORA!$B$4:$B$7322,">="&$B$3,BITACORA!$B$4:$B$7322,"<="&$B$4) -> 0 | G16: =COUNTIFS(BITACORA!$C$4:$C$7322,$B$7:$B$501,BITACORA!$E$4:$E$7322,$E$6:$AM$6,BITACORA!$B$4:$B$7322,">="&$B$3,BITACORA!$B$4:$B$7322,"<="&$B$4) -> 0 | H16: =COUNTIFS(BITACORA!$C$4:$C$7322,$B$7:$B$501,BITACORA!$E$4:$E$7322,$E$6:$AM$6,BITACORA!$B$4:$B$7322,">="&$B$3,BITACORA!$B$4:$B$7322,"<="&$B$4) -> 0 | I16: =COUNTIFS(BITACORA!$C$4:$C$7322,$B$7:$B$501,BITACORA!$E$4:$E$7322,$E$6:$AM$6,BITACORA!$B$4:$B$7322,">="&$B$3,BITACORA!$B$4:$B$7322,"<="&$B$4) -> 0 | J16: =COUNTIFS(BITACORA!$C$4:$C$7322,$B$7:$B$501,BITACORA!$E$4:$E$7322,$E$6:$AM$6,BITACORA!$B$4:$B$7322,">="&$B$3,BITACORA!$B$4:$B$7322,"<="&$B$4) -> 0 | K16: =COUNTIFS(BITACORA!$C$4:$C$7322,$B$7:$B$501,BITACORA!$E$4:$E$7322,$E$6:$AM$6,BITACORA!$B$4:$B$7322,">="&$B$3,BITACORA!$B$4:$B$7322,"<="&$B$4) -> 0 | L16: =COUNTIFS(BITACORA!$C$4:$C$7322,$B$7:$B$501,BITACORA!$E$4:$E$7322,$E$6:$AM$6,BITACORA!$B$4:$B$7322,">="&$B$3,BITACORA!$B$4:$B$7322,"<="&$B$4) -> 0 | ... AM16: =COUNTIFS(BITACORA!$C$4:$C$7322,$B$7:$B$501,BITACORA!$E$4:$E$7322,$E$6:$AM$6,BITACORA!$B$4:$B$7322,">="&$B$3,BITACORA!$B$4:$B$7322,"<="&$B$4) -> 0
A17: =IFERROR(__xludf.DUMMYFUNCTION("""COMPUTED_VALUE"""),"Angulo Saltos Marlon Fabian") -> Angulo Saltos Marlon Fabian | B17: =IFERROR(__xludf.DUMMYFUNCTION("""COMPUTED_VALUE"""),"GKX0511") -> GKX0511 | C17: =IFERROR(__xludf.DUMMYFUNCTION("""COMPUTED_VALUE"""),4) -> 4 | D17: =SUM(E17:AM17) -> 0 | E17: =COUNTIFS(BITACORA!$C$4:$C$7322,$B$7:$B$501,BITACORA!$E$4:$E$7322,$E$6:$AM$6,BITACORA!$B$4:$B$7322,">="&$B$3,BITACORA!$B$4:$B$7322,"<="&$B$4) -> 0 | F17: =COUNTIFS(BITACORA!$C$4:$C$7322,$B$7:$B$501,BITACORA!$E$4:$E$7322,$E$6:$AM$6,BITACORA!$B$4:$B$7322,">="&$B$3,BITACORA!$B$4:$B$7322,"<="&$B$4) -> 0 | G17: =COUNTIFS(BITACORA!$C$4:$C$7322,$B$7:$B$501,BITACORA!$E$4:$E$7322,$E$6:$AM$6,BITACORA!$B$4:$B$7322,">="&$B$3,BITACORA!$B$4:$B$7322,"<="&$B$4) -> 0 | H17: =COUNTIFS(BITACORA!$C$4:$C$7322,$B$7:$B$501,BITACORA!$E$4:$E$7322,$E$6:$AM$6,BITACORA!$B$4:$B$7322,">="&$B$3,BITACORA!$B$4:$B$7322,"<="&$B$4) -> 0 | I17: =COUNTIFS(BITACORA!$C$4:$C$7322,$B$7:$B$501,BITACORA!$E$4:$E$7322,$E$6:$AM$6,BITACORA!$B$4:$B$7322,">="&$B$3,BITACORA!$B$4:$B$7322,"<="&$B$4) -> 0 | J17: =COUNTIFS(BITACORA!$C$4:$C$7322,$B$7:$B$501,BITACORA!$E$4:$E$7322,$E$6:$AM$6,BITACORA!$B$4:$B$7322,">="&$B$3,BITACORA!$B$4:$B$7322,"<="&$B$4) -> 0 | K17: =COUNTIFS(BITACORA!$C$4:$C$7322,$B$7:$B$501,BITACORA!$E$4:$E$7322,$E$6:$AM$6,BITACORA!$B$4:$B$7322,">="&$B$3,BITACORA!$B$4:$B$7322,"<="&$B$4) -> 0 | L17: =COUNTIFS(BITACORA!$C$4:$C$7322,$B$7:$B$501,BITACORA!$E$4:$E$7322,$E$6:$AM$6,BITACORA!$B$4:$B$7322,">="&$B$3,BITACORA!$B$4:$B$7322,"<="&$B$4) -> 0 | ... AM17: =COUNTIFS(BITACORA!$C$4:$C$7322,$B$7:$B$501,BITACORA!$E$4:$E$7322,$E$6:$AM$6,BITACORA!$B$4:$B$7322,">="&$B$3,BITACORA!$B$4:$B$7322,"<="&$B$4) -> 0
A18: =IFERROR(__xludf.DUMMYFUNCTION("""COMPUTED_VALUE"""),"Enner Eliezer Cevallos Burgos") -> Enner Eliezer Cevallos Burgos | B18: =IFERROR(__xludf.DUMMYFUNCTION("""COMPUTED_VALUE"""),"PZI0105") -> PZI0105 | C18: =IFERROR(__xludf.DUMMYFUNCTION("""COMPUTED_VALUE"""),5) -> 5 | D18: =SUM(E18:AM18) -> 1 | E18: =COUNTIFS(BITACORA!$C$4:$C$7322,$B$7:$B$501,BITACORA!$E$4:$E$7322,$E$6:$AM$6,BITACORA!$B$4:$B$7322,">="&$B$3,BITACORA!$B$4:$B$7322,"<="&$B$4) -> 0 | F18: =COUNTIFS(BITACORA!$C$4:$C$7322,$B$7:$B$501,BITACORA!$E$4:$E$7322,$E$6:$AM$6,BITACORA!$B$4:$B$7322,">="&$B$3,BITACORA!$B$4:$B$7322,"<="&$B$4) -> 1 | G18: =COUNTIFS(BITACORA!$C$4:$C$7322,$B$7:$B$501,BITACORA!$E$4:$E$7322,$E$6:$AM$6,BITACORA!$B$4:$B$7322,">="&$B$3,BITACORA!$B$4:$B$7322,"<="&$B$4) -> 0 | H18: =COUNTIFS(BITACORA!$C$4:$C$7322,$B$7:$B$501,BITACORA!$E$4:$E$7322,$E$6:$AM$6,BITACORA!$B$4:$B$7322,">="&$B$3,BITACORA!$B$4:$B$7322,"<="&$B$4) -> 0 | I18: =COUNTIFS(BITACORA!$C$4:$C$7322,$B$7:$B$501,BITACORA!$E$4:$E$7322,$E$6:$AM$6,BITACORA!$B$4:$B$7322,">="&$B$3,BITACORA!$B$4:$B$7322,"<="&$B$4) -> 0 | J18: =COUNTIFS(BITACORA!$C$4:$C$7322,$B$7:$B$501,BITACORA!$E$4:$E$7322,$E$6:$AM$6,BITACORA!$B$4:$B$7322,">="&$B$3,BITACORA!$B$4:$B$7322,"<="&$B$4) -> 0 | K18: =COUNTIFS(BITACORA!$C$4:$C$7322,$B$7:$B$501,BITACORA!$E$4:$E$7322,$E$6:$AM$6,BITACORA!$B$4:$B$7322,">="&$B$3,BITACORA!$B$4:$B$7322,"<="&$B$4) -> 0 | L18: =COUNTIFS(BITACORA!$C$4:$C$7322,$B$7:$B$501,BITACORA!$E$4:$E$7322,$E$6:$AM$6,BITACORA!$B$4:$B$7322,">="&$B$3,BITACORA!$B$4:$B$7322,"<="&$B$4) -> 0 | ... AM18: =COUNTIFS(BITACORA!$C$4:$C$7322,$B$7:$B$501,BITACORA!$E$4:$E$7322,$E$6:$AM$6,BITACORA!$B$4:$B$7322,">="&$B$3,BITACORA!$B$4:$B$7322,"<="&$B$4) -> 0
A19: =IFERROR(__xludf.DUMMYFUNCTION("""COMPUTED_VALUE"""),"Luis Javier Jaramillo Vera") -> Luis Javier Jaramillo Vera | B19: =IFERROR(__xludf.DUMMYFUNCTION("""COMPUTED_VALUE"""),"HAJ0694") -> HAJ0694 | C19: =IFERROR(__xludf.DUMMYFUNCTION("""COMPUTED_VALUE"""),5) -> 5 | D19: =SUM(E19:AM19) -> 0 | E19: =COUNTIFS(BITACORA!$C$4:$C$7322,$B$7:$B$501,BITACORA!$E$4:$E$7322,$E$6:$AM$6,BITACORA!$B$4:$B$7322,">="&$B$3,BITACORA!$B$4:$B$7322,"<="&$B$4) -> 0 | F19: =COUNTIFS(BITACORA!$C$4:$C$7322,$B$7:$B$501,BITACORA!$E$4:$E$7322,$E$6:$AM$6,BITACORA!$B$4:$B$7322,">="&$B$3,BITACORA!$B$4:$B$7322,"<="&$B$4) -> 0 | G19: =COUNTIFS(BITACORA!$C$4:$C$7322,$B$7:$B$501,BITACORA!$E$4:$E$7322,$E$6:$AM$6,BITACORA!$B$4:$B$7322,">="&$B$3,BITACORA!$B$4:$B$7322,"<="&$B$4) -> 0 | H19: =COUNTIFS(BITACORA!$C$4:$C$7322,$B$7:$B$501,BITACORA!$E$4:$E$7322,$E$6:$AM$6,BITACORA!$B$4:$B$7322,">="&$B$3,BITACORA!$B$4:$B$7322,"<="&$B$4) -> 0 | I19: =COUNTIFS(BITACORA!$C$4:$C$7322,$B$7:$B$501,BITACORA!$E$4:$E$7322,$E$6:$AM$6,BITACORA!$B$4:$B$7322,">="&$B$3,BITACORA!$B$4:$B$7322,"<="&$B$4) -> 0 | J19: =COUNTIFS(BITACORA!$C$4:$C$7322,$B$7:$B$501,BITACORA!$E$4:$E$7322,$E$6:$AM$6,BITACORA!$B$4:$B$7322,">="&$B$3,BITACORA!$B$4:$B$7322,"<="&$B$4) -> 0 | K19: =COUNTIFS(BITACORA!$C$4:$C$7322,$B$7:$B$501,BITACORA!$E$4:$E$7322,$E$6:$AM$6,BITACORA!$B$4:$B$7322,">="&$B$3,BITACORA!$B$4:$B$7322,"<="&$B$4) -> 0 | L19: =COUNTIFS(BITACORA!$C$4:$C$7322,$B$7:$B$501,BITACORA!$E$4:$E$7322,$E$6:$AM$6,BITACORA!$B$4:$B$7322,">="&$B$3,BITACORA!$B$4:$B$7322,"<="&$B$4) -> 0 | ... AM19: =COUNTIFS(BITACORA!$C$4:$C$7322,$B$7:$B$501,BITACORA!$E$4:$E$7322,$E$6:$AM$6,BITACORA!$B$4:$B$7322,">="&$B$3,BITACORA!$B$4:$B$7322,"<="&$B$4) -> 0
A20: =IFERROR(__xludf.DUMMYFUNCTION("""COMPUTED_VALUE"""),"Gabriel Rolando Muentes Cornejo") -> Gabriel Rolando Muentes Cornejo | B20: =IFERROR(__xludf.DUMMYFUNCTION("""COMPUTED_VALUE"""),"BAC0784") -> BAC0784 | C20: =IFERROR(__xludf.DUMMYFUNCTION("""COMPUTED_VALUE"""),5) -> 5 | D20: =SUM(E20:AM20) -> 0 | E20: =COUNTIFS(BITACORA!$C$4:$C$7322,$B$7:$B$501,BITACORA!$E$4:$E$7322,$E$6:$AM$6,BITACORA!$B$4:$B$7322,">="&$B$3,BITACORA!$B$4:$B$7322,"<="&$B$4) -> 0 | F20: =COUNTIFS(BITACORA!$C$4:$C$7322,$B$7:$B$501,BITACORA!$E$4:$E$7322,$E$6:$AM$6,BITACORA!$B$4:$B$7322,">="&$B$3,BITACORA!$B$4:$B$7322,"<="&$B$4) -> 0 | G20: =COUNTIFS(BITACORA!$C$4:$C$7322,$B$7:$B$501,BITACORA!$E$4:$E$7322,$E$6:$AM$6,BITACORA!$B$4:$B$7322,">="&$B$3,BITACORA!$B$4:$B$7322,"<="&$B$4) -> 0 | H20: =COUNTIFS(BITACORA!$C$4:$C$7322,$B$7:$B$501,BITACORA!$E$4:$E$7322,$E$6:$AM$6,BITACORA!$B$4:$B$7322,">="&$B$3,BITACORA!$B$4:$B$7322,"<="&$B$4) -> 0 | I20: =COUNTIFS(BITACORA!$C$4:$C$7322,$B$7:$B$501,BITACORA!$E$4:$E$7322,$E$6:$AM$6,BITACORA!$B$4:$B$7322,">="&$B$3,BITACORA!$B$4:$B$7322,"<="&$B$4) -> 0 | J20: =COUNTIFS(BITACORA!$C$4:$C$7322,$B$7:$B$501,BITACORA!$E$4:$E$7322,$E$6:$AM$6,BITACORA!$B$4:$B$7322,">="&$B$3,BITACORA!$B$4:$B$7322,"<="&$B$4) -> 0 | K20: =COUNTIFS(BITACORA!$C$4:$C$7322,$B$7:$B$501,BITACORA!$E$4:$E$7322,$E$6:$AM$6,BITACORA!$B$4:$B$7322,">="&$B$3,BITACORA!$B$4:$B$7322,"<="&$B$4) -> 0 | L20: =COUNTIFS(BITACORA!$C$4:$C$7322,$B$7:$B$501,BITACORA!$E$4:$E$7322,$E$6:$AM$6,BITACORA!$B$4:$B$7322,">="&$B$3,BITACORA!$B$4:$B$7322,"<="&$B$4) -> 0 | ... AM20: =COUNTIFS(BITACORA!$C$4:$C$7322,$B$7:$B$501,BITACORA!$E$4:$E$7322,$E$6:$AM$6,BITACORA!$B$4:$B$7322,">="&$B$3,BITACORA!$B$4:$B$7322,"<="&$B$4) -> 0
A21: =IFERROR(__xludf.DUMMYFUNCTION("""COMPUTED_VALUE"""),"Nexar Celestino Vargas Intrigo") -> Nexar Celestino Vargas Intrigo | B21: =IFERROR(__xludf.DUMMYFUNCTION("""COMPUTED_VALUE"""),"MAA4517") -> MAA4517 | C21: =IFERROR(__xludf.DUMMYFUNCTION("""COMPUTED_VALUE"""),5) -> 5 | D21: =SUM(E21:AM21) -> 0 | E21: =COUNTIFS(BITACORA!$C$4:$C$7322,$B$7:$B$501,BITACORA!$E$4:$E$7322,$E$6:$AM$6,BITACORA!$B$4:$B$7322,">="&$B$3,BITACORA!$B$4:$B$7322,"<="&$B$4) -> 0 | F21: =COUNTIFS(BITACORA!$C$4:$C$7322,$B$7:$B$501,BITACORA!$E$4:$E$7322,$E$6:$AM$6,BITACORA!$B$4:$B$7322,">="&$B$3,BITACORA!$B$4:$B$7322,"<="&$B$4) -> 0 | G21: =COUNTIFS(BITACORA!$C$4:$C$7322,$B$7:$B$501,BITACORA!$E$4:$E$7322,$E$6:$AM$6,BITACORA!$B$4:$B$7322,">="&$B$3,BITACORA!$B$4:$B$7322,"<="&$B$4) -> 0 | H21: =COUNTIFS(BITACORA!$C$4:$C$7322,$B$7:$B$501,BITACORA!$E$4:$E$7322,$E$6:$AM$6,BITACORA!$B$4:$B$7322,">="&$B$3,BITACORA!$B$4:$B$7322,"<="&$B$4) -> 0 | I21: =COUNTIFS(BITACORA!$C$4:$C$7322,$B$7:$B$501,BITACORA!$E$4:$E$7322,$E$6:$AM$6,BITACORA!$B$4:$B$7322,">="&$B$3,BITACORA!$B$4:$B$7322,"<="&$B$4) -> 0 | J21: =COUNTIFS(BITACORA!$C$4:$C$7322,$B$7:$B$501,BITACORA!$E$4:$E$7322,$E$6:$AM$6,BITACORA!$B$4:$B$7322,">="&$B$3,BITACORA!$B$4:$B$7322,"<="&$B$4) -> 0 | K21: =COUNTIFS(BITACORA!$C$4:$C$7322,$B$7:$B$501,BITACORA!$E$4:$E$7322,$E$6:$AM$6,BITACORA!$B$4:$B$7322,">="&$B$3,BITACORA!$B$4:$B$7322,"<="&$B$4) -> 0 | L21: =COUNTIFS(BITACORA!$C$4:$C$7322,$B$7:$B$501,BITACORA!$E$4:$E$7322,$E$6:$AM$6,BITACORA!$B$4:$B$7322,">="&$B$3,BITACORA!$B$4:$B$7322,"<="&$B$4) -> 0 | ... AM21: =COUNTIFS(BITACORA!$C$4:$C$7322,$B$7:$B$501,BITACORA!$E$4:$E$7322,$E$6:$AM$6,BITACORA!$B$4:$B$7322,">="&$B$3,BITACORA!$B$4:$B$7322,"<="&$B$4) -> 0
A22: =IFERROR(__xludf.DUMMYFUNCTION("""COMPUTED_VALUE"""),"Edison Gabriel Aules Sanchez") -> Edison Gabriel Aules Sanchez | B22: =IFERROR(__xludf.DUMMYFUNCTION("""COMPUTED_VALUE"""),"ABB2285") -> ABB2285 | C22: =IFERROR(__xludf.DUMMYFUNCTION("""COMPUTED_VALUE"""),5) -> 5 | D22: =SUM(E22:AM22) -> 0 | E22: =COUNTIFS(BITACORA!$C$4:$C$7322,$B$7:$B$501,BITACORA!$E$4:$E$7322,$E$6:$AM$6,BITACORA!$B$4:$B$7322,">="&$B$3,BITACORA!$B$4:$B$7322,"<="&$B$4) -> 0 | F22: =COUNTIFS(BITACORA!$C$4:$C$7322,$B$7:$B$501,BITACORA!$E$4:$E$7322,$E$6:$AM$6,BITACORA!$B$4:$B$7322,">="&$B$3,BITACORA!$B$4:$B$7322,"<="&$B$4) -> 0 | G22: =COUNTIFS(BITACORA!$C$4:$C$7322,$B$7:$B$501,BITACORA!$E$4:$E$7322,$E$6:$AM$6,BITACORA!$B$4:$B$7322,">="&$B$3,BITACORA!$B$4:$B$7322,"<="&$B$4) -> 0 | H22: =COUNTIFS(BITACORA!$C$4:$C$7322,$B$7:$B$501,BITACORA!$E$4:$E$7322,$E$6:$AM$6,BITACORA!$B$4:$B$7322,">="&$B$3,BITACORA!$B$4:$B$7322,"<="&$B$4) -> 0 | I22: =COUNTIFS(BITACORA!$C$4:$C$7322,$B$7:$B$501,BITACORA!$E$4:$E$7322,$E$6:$AM$6,BITACORA!$B$4:$B$7322,">="&$B$3,BITACORA!$B$4:$B$7322,"<="&$B$4) -> 0 | J22: =COUNTIFS(BITACORA!$C$4:$C$7322,$B$7:$B$501,BITACORA!$E$4:$E$7322,$E$6:$AM$6,BITACORA!$B$4:$B$7322,">="&$B$3,BITACORA!$B$4:$B$7322,"<="&$B$4) -> 0 | K22: =COUNTIFS(BITACORA!$C$4:$C$7322,$B$7:$B$501,BITACORA!$E$4:$E$7322,$E$6:$AM$6,BITACORA!$B$4:$B$7322,">="&$B$3,BITACORA!$B$4:$B$7322,"<="&$B$4) -> 0 | L22: =COUNTIFS(BITACORA!$C$4:$C$7322,$B$7:$B$501,BITACORA!$E$4:$E$7322,$E$6:$AM$6,BITACORA!$B$4:$B$7322,">="&$B$3,BITACORA!$B$4:$B$7322,"<="&$B$4) -> 0 | ... AM22: =COUNTIFS(BITACORA!$C$4:$C$7322,$B$7:$B$501,BITACORA!$E$4:$E$7322,$E$6:$AM$6,BITACORA!$B$4:$B$7322,">="&$B$3,BITACORA!$B$4:$B$7322,"<="&$B$4) -> 0
A23: =IFERROR(__xludf.DUMMYFUNCTION("""COMPUTED_VALUE"""),"Byron Gregorio Garcia Tumbaco") -> Byron Gregorio Garcia Tumbaco | B23: =IFERROR(__xludf.DUMMYFUNCTION("""COMPUTED_VALUE"""),"XBA6758") -> XBA6758 | C23: =IFERROR(__xludf.DUMMYFUNCTION("""COMPUTED_VALUE"""),5) -> 5 | D23: =SUM(E23:AM23) -> 0 | E23: =COUNTIFS(BITACORA!$C$4:$C$7322,$B$7:$B$501,BITACORA!$E$4:$E$7322,$E$6:$AM$6,BITACORA!$B$4:$B$7322,">="&$B$3,BITACORA!$B$4:$B$7322,"<="&$B$4) -> 0 | F23: =COUNTIFS(BITACORA!$C$4:$C$7322,$B$7:$B$501,BITACORA!$E$4:$E$7322,$E$6:$AM$6,BITACORA!$B$4:$B$7322,">="&$B$3,BITACORA!$B$4:$B$7322,"<="&$B$4) -> 0 | G23: =COUNTIFS(BITACORA!$C$4:$C$7322,$B$7:$B$501,BITACORA!$E$4:$E$7322,$E$6:$AM$6,BITACORA!$B$4:$B$7322,">="&$B$3,BITACORA!$B$4:$B$7322,"<="&$B$4) -> 0 | H23: =COUNTIFS(BITACORA!$C$4:$C$7322,$B$7:$B$501,BITACORA!$E$4:$E$7322,$E$6:$AM$6,BITACORA!$B$4:$B$7322,">="&$B$3,BITACORA!$B$4:$B$7322,"<="&$B$4) -> 0 | I23: =COUNTIFS(BITACORA!$C$4:$C$7322,$B$7:$B$501,BITACORA!$E$4:$E$7322,$E$6:$AM$6,BITACORA!$B$4:$B$7322,">="&$B$3,BITACORA!$B$4:$B$7322,"<="&$B$4) -> 0 | J23: =COUNTIFS(BITACORA!$C$4:$C$7322,$B$7:$B$501,BITACORA!$E$4:$E$7322,$E$6:$AM$6,BITACORA!$B$4:$B$7322,">="&$B$3,BITACORA!$B$4:$B$7322,"<="&$B$4) -> 0 | K23: =COUNTIFS(BITACORA!$C$4:$C$7322,$B$7:$B$501,BITACORA!$E$4:$E$7322,$E$6:$AM$6,BITACORA!$B$4:$B$7322,">="&$B$3,BITACORA!$B$4:$B$7322,"<="&$B$4) -> 0 | L23: =COUNTIFS(BITACORA!$C$4:$C$7322,$B$7:$B$501,BITACORA!$E$4:$E$7322,$E$6:$AM$6,BITACORA!$B$4:$B$7322,">="&$B$3,BITACORA!$B$4:$B$7322,"<="&$B$4) -> 0 | ... AM23: =COUNTIFS(BITACORA!$C$4:$C$7322,$B$7:$B$501,BITACORA!$E$4:$E$7322,$E$6:$AM$6,BITACORA!$B$4:$B$7322,">="&$B$3,BITACORA!$B$4:$B$7322,"<="&$B$4) -> 0
A24: =IFERROR(__xludf.DUMMYFUNCTION("""COMPUTED_VALUE"""),"Byron Gregorio Garcia Tumbaco") -> Byron Gregorio Garcia Tumbaco | B24: =IFERROR(__xludf.DUMMYFUNCTION("""COMPUTED_VALUE"""),"QAA1814") -> QAA1814 | C24: =IFERROR(__xludf.DUMMYFUNCTION("""COMPUTED_VALUE"""),6) -> 6 | D24: =SUM(E24:AM24) -> 0 | E24: =COUNTIFS(BITACORA!$C$4:$C$7322,$B$7:$B$501,BITACORA!$E$4:$E$7322,$E$6:$AM$6,BITACORA!$B$4:$B$7322,">="&$B$3,BITACORA!$B$4:$B$7322,"<="&$B$4) -> 0 | F24: =COUNTIFS(BITACORA!$C$4:$C$7322,$B$7:$B$501,BITACORA!$E$4:$E$7322,$E$6:$AM$6,BITACORA!$B$4:$B$7322,">="&$B$3,BITACORA!$B$4:$B$7322,"<="&$B$4) -> 0 | G24: =COUNTIFS(BITACORA!$C$4:$C$7322,$B$7:$B$501,BITACORA!$E$4:$E$7322,$E$6:$AM$6,BITACORA!$B$4:$B$7322,">="&$B$3,BITACORA!$B$4:$B$7322,"<="&$B$4) -> 0 | H24: =COUNTIFS(BITACORA!$C$4:$C$7322,$B$7:$B$501,BITACORA!$E$4:$E$7322,$E$6:$AM$6,BITACORA!$B$4:$B$7322,">="&$B$3,BITACORA!$B$4:$B$7322,"<="&$B$4) -> 0 | I24: =COUNTIFS(BITACORA!$C$4:$C$7322,$B$7:$B$501,BITACORA!$E$4:$E$7322,$E$6:$AM$6,BITACORA!$B$4:$B$7322,">="&$B$3,BITACORA!$B$4:$B$7322,"<="&$B$4) -> 0 | J24: =COUNTIFS(BITACORA!$C$4:$C$7322,$B$7:$B$501,BITACORA!$E$4:$E$7322,$E$6:$AM$6,BITACORA!$B$4:$B$7322,">="&$B$3,BITACORA!$B$4:$B$7322,"<="&$B$4) -> 0 | K24: =COUNTIFS(BITACORA!$C$4:$C$7322,$B$7:$B$501,BITACORA!$E$4:$E$7322,$E$6:$AM$6,BITACORA!$B$4:$B$7322,">="&$B$3,BITACORA!$B$4:$B$7322,"<="&$B$4) -> 0 | L24: =COUNTIFS(BITACORA!$C$4:$C$7322,$B$7:$B$501,BITACORA!$E$4:$E$7322,$E$6:$AM$6,BITACORA!$B$4:$B$7322,">="&$B$3,BITACORA!$B$4:$B$7322,"<="&$B$4) -> 0 | ... AM24: =COUNTIFS(BITACORA!$C$4:$C$7322,$B$7:$B$501,BITACORA!$E$4:$E$7322,$E$6:$AM$6,BITACORA!$B$4:$B$7322,">="&$B$3,BITACORA!$B$4:$B$7322,"<="&$B$4) -> 0
A25: =IFERROR(__xludf.DUMMYFUNCTION("""COMPUTED_VALUE"""),"Miguel Angel Quishpe Gordon") -> Miguel Angel Quishpe Gordon | B25: =IFERROR(__xludf.DUMMYFUNCTION("""COMPUTED_VALUE"""),"PYP0743") -> PYP0743 | C25: =IFERROR(__xludf.DUMMYFUNCTION("""COMPUTED_VALUE"""),5) -> 5 | D25: =SUM(E25:AM25) -> 0 | E25: =COUNTIFS(BITACORA!$C$4:$C$7322,$B$7:$B$501,BITACORA!$E$4:$E$7322,$E$6:$AM$6,BITACORA!$B$4:$B$7322,">="&$B$3,BITACORA!$B$4:$B$7322,"<="&$B$4) -> 0 | F25: =COUNTIFS(BITACORA!$C$4:$C$7322,$B$7:$B$501,BITACORA!$E$4:$E$7322,$E$6:$AM$6,BITACORA!$B$4:$B$7322,">="&$B$3,BITACORA!$B$4:$B$7322,"<="&$B$4) -> 0 | G25: =COUNTIFS(BITACORA!$C$4:$C$7322,$B$7:$B$501,BITACORA!$E$4:$E$7322,$E$6:$AM$6,BITACORA!$B$4:$B$7322,">="&$B$3,BITACORA!$B$4:$B$7322,"<="&$B$4) -> 0 | H25: =COUNTIFS(BITACORA!$C$4:$C$7322,$B$7:$B$501,BITACORA!$E$4:$E$7322,$E$6:$AM$6,BITACORA!$B$4:$B$7322,">="&$B$3,BITACORA!$B$4:$B$7322,"<="&$B$4) -> 0 | I25: =COUNTIFS(BITACORA!$C$4:$C$7322,$B$7:$B$501,BITACORA!$E$4:$E$7322,$E$6:$AM$6,BITACORA!$B$4:$B$7322,">="&$B$3,BITACORA!$B$4:$B$7322,"<="&$B$4) -> 0 | J25: =COUNTIFS(BITACORA!$C$4:$C$7322,$B$7:$B$501,BITACORA!$E$4:$E$7322,$E$6:$AM$6,BITACORA!$B$4:$B$7322,">="&$B$3,BITACORA!$B$4:$B$7322,"<="&$B$4) -> 0 | K25: =COUNTIFS(BITACORA!$C$4:$C$7322,$B$7:$B$501,BITACORA!$E$4:$E$7322,$E$6:$AM$6,BITACORA!$B$4:$B$7322,">="&$B$3,BITACORA!$B$4:$B$7322,"<="&$B$4) -> 0 | L25: =COUNTIFS(BITACORA!$C$4:$C$7322,$B$7:$B$501,BITACORA!$E$4:$E$7322,$E$6:$AM$6,BITACORA!$B$4:$B$7322,">="&$B$3,BITACORA!$B$4:$B$7322,"<="&$B$4) -> 0 | ... AM25: =COUNTIFS(BITACORA!$C$4:$C$7322,$B$7:$B$501,BITACORA!$E$4:$E$7322,$E$6:$AM$6,BITACORA!$B$4:$B$7322,">="&$B$3,BITACORA!$B$4:$B$7322,"<="&$B$4) -> 0
A26: =IFERROR(__xludf.DUMMYFUNCTION("""COMPUTED_VALUE"""),"Miguel Angel Quishpe Gordon") -> Miguel Angel Quishpe Gordon | B26: =IFERROR(__xludf.DUMMYFUNCTION("""COMPUTED_VALUE"""),"IAE0151") -> IAE0151 | C26: =IFERROR(__xludf.DUMMYFUNCTION("""COMPUTED_VALUE"""),6) -> 6 | D26: =SUM(E26:AM26) -> 0 | E26: =COUNTIFS(BITACORA!$C$4:$C$7322,$B$7:$B$501,BITACORA!$E$4:$E$7322,$E$6:$AM$6,BITACORA!$B$4:$B$7322,">="&$B$3,BITACORA!$B$4:$B$7322,"<="&$B$4) -> 0 | F26: =COUNTIFS(BITACORA!$C$4:$C$7322,$B$7:$B$501,BITACORA!$E$4:$E$7322,$E$6:$AM$6,BITACORA!$B$4:$B$7322,">="&$B$3,BITACORA!$B$4:$B$7322,"<="&$B$4) -> 0 | G26: =COUNTIFS(BITACORA!$C$4:$C$7322,$B$7:$B$501,BITACORA!$E$4:$E$7322,$E$6:$AM$6,BITACORA!$B$4:$B$7322,">="&$B$3,BITACORA!$B$4:$B$7322,"<="&$B$4) -> 0 | H26: =COUNTIFS(BITACORA!$C$4:$C$7322,$B$7:$B$501,BITACORA!$E$4:$E$7322,$E$6:$AM$6,BITACORA!$B$4:$B$7322,">="&$B$3,BITACORA!$B$4:$B$7322,"<="&$B$4) -> 0 | I26: =COUNTIFS(BITACORA!$C$4:$C$7322,$B$7:$B$501,BITACORA!$E$4:$E$7322,$E$6:$AM$6,BITACORA!$B$4:$B$7322,">="&$B$3,BITACORA!$B$4:$B$7322,"<="&$B$4) -> 0 | J26: =COUNTIFS(BITACORA!$C$4:$C$7322,$B$7:$B$501,BITACORA!$E$4:$E$7322,$E$6:$AM$6,BITACORA!$B$4:$B$7322,">="&$B$3,BITACORA!$B$4:$B$7322,"<="&$B$4) -> 0 | K26: =COUNTIFS(BITACORA!$C$4:$C$7322,$B$7:$B$501,BITACORA!$E$4:$E$7322,$E$6:$AM$6,BITACORA!$B$4:$B$7322,">="&$B$3,BITACORA!$B$4:$B$7322,"<="&$B$4) -> 0 | L26: =COUNTIFS(BITACORA!$C$4:$C$7322,$B$7:$B$501,BITACORA!$E$4:$E$7322,$E$6:$AM$6,BITACORA!$B$4:$B$7322,">="&$B$3,BITACORA!$B$4:$B$7322,"<="&$B$4) -> 0 | ... AM26: =COUNTIFS(BITACORA!$C$4:$C$7322,$B$7:$B$501,BITACORA!$E$4:$E$7322,$E$6:$AM$6,BITACORA!$B$4:$B$7322,">="&$B$3,BITACORA!$B$4:$B$7322,"<="&$B$4) -> 0
A27: =IFERROR(__xludf.DUMMYFUNCTION("""COMPUTED_VALUE"""),"Cesar Luis Muentes Cornejo") -> Cesar Luis Muentes Cornejo | B27: =IFERROR(__xludf.DUMMYFUNCTION("""COMPUTED_VALUE"""),"OAH0651") -> OAH0651 | C27: =IFERROR(__xludf.DUMMYFUNCTION("""COMPUTED_VALUE"""),5) -> 5 | D27: =SUM(E27:AM27) -> 0 | E27: =COUNTIFS(BITACORA!$C$4:$C$7322,$B$7:$B$501,BITACORA!$E$4:$E$7322,$E$6:$AM$6,BITACORA!$B$4:$B$7322,">="&$B$3,BITACORA!$B$4:$B$7322,"<="&$B$4) -> 0 | F27: =COUNTIFS(BITACORA!$C$4:$C$7322,$B$7:$B$501,BITACORA!$E$4:$E$7322,$E$6:$AM$6,BITACORA!$B$4:$B$7322,">="&$B$3,BITACORA!$B$4:$B$7322,"<="&$B$4) -> 0 | G27: =COUNTIFS(BITACORA!$C$4:$C$7322,$B$7:$B$501,BITACORA!$E$4:$E$7322,$E$6:$AM$6,BITACORA!$B$4:$B$7322,">="&$B$3,BITACORA!$B$4:$B$7322,"<="&$B$4) -> 0 | H27: =COUNTIFS(BITACORA!$C$4:$C$7322,$B$7:$B$501,BITACORA!$E$4:$E$7322,$E$6:$AM$6,BITACORA!$B$4:$B$7322,">="&$B$3,BITACORA!$B$4:$B$7322,"<="&$B$4) -> 0 | I27: =COUNTIFS(BITACORA!$C$4:$C$7322,$B$7:$B$501,BITACORA!$E$4:$E$7322,$E$6:$AM$6,BITACORA!$B$4:$B$7322,">="&$B$3,BITACORA!$B$4:$B$7322,"<="&$B$4) -> 0 | J27: =COUNTIFS(BITACORA!$C$4:$C$7322,$B$7:$B$501,BITACORA!$E$4:$E$7322,$E$6:$AM$6,BITACORA!$B$4:$B$7322,">="&$B$3,BITACORA!$B$4:$B$7322,"<="&$B$4) -> 0 | K27: =COUNTIFS(BITACORA!$C$4:$C$7322,$B$7:$B$501,BITACORA!$E$4:$E$7322,$E$6:$AM$6,BITACORA!$B$4:$B$7322,">="&$B$3,BITACORA!$B$4:$B$7322,"<="&$B$4) -> 0 | L27: =COUNTIFS(BITACORA!$C$4:$C$7322,$B$7:$B$501,BITACORA!$E$4:$E$7322,$E$6:$AM$6,BITACORA!$B$4:$B$7322,">="&$B$3,BITACORA!$B$4:$B$7322,"<="&$B$4) -> 0 | ... AM27: =COUNTIFS(BITACORA!$C$4:$C$7322,$B$7:$B$501,BITACORA!$E$4:$E$7322,$E$6:$AM$6,BITACORA!$B$4:$B$7322,">="&$B$3,BITACORA!$B$4:$B$7322,"<="&$B$4) -> 0
