Workbook

Sheet Viajes y Cargas
A2: REPORTE DE VIAJES Y CARGA SEMANA - MES
B3: MES | C3: MARZO
A5: CAMION | C5: SEMANA 01 al 07 | D5: SEMANA 06 08 al 14 | E5: SEMANA 15 al 21 | F5: SEMANA 22 al 28 | G5: SEMANA 29 al 31 | H5: TOTAL
A6: CAB-01 | B6: VUELTAS | C6: 0 | D6: 4 | E6: 12 | F6: 6 | G6: 4 | H6: =SUM(C6:G6) -> 26
B7: CARGA | C7: =0/1000 -> 0 | D7: =89950/1000 -> 89.95 | E7: =298355/1000 -> 298.355 | F7: =99400/1000 -> 99.4 | G7: =72820/1000 -> 72.82 | H7: =SUM(C7:G7) -> 560.525
A8: CAB-02 | B8: VUELTAS | C8: 6 | D8: 19 | E8: 6 | F8: 16 | G8: 1 | H8: =SUM(C8:G8) -> 48
B9: CARGA | C9: =123460/1000 -> 123.46 | D9: =429550/1000 -> 429.55 | E9: =113930/1000 -> 113.93 | F9: =377810/1000 -> 377.81 | G9: =35140/1000 -> 35.14 | H9: =SUM(C9:G9) -> 1079.89
A10: CAB-03 | B10: VUELTAS | C10: 8 | D10: 19 | E10: 11 | F10: 10 | G10: 9 | H10: =SUM(C10:G10) -> 57
B11: CARGA | C11: =134544/1000 -> 134.544 | D11: =370130/1000 -> 370.13 | E11: =166940/1000 -> 166.94 | F11: =203780/1000 -> 203.78 | G11: =200320/1000 -> 200.32 | H11: =SUM(C11:G11) -> 1075.714
A12: CAB-05 | B12: VUELTAS | C12: 4 | D12: 22 | E12: 6 | F12: 3 | H12: =SUM(C12:G12) -> 35
B13: CARGA | C13: =65140/1000 -> 65.14 | D13: =427490/1000 -> 427.49 | E13: =130910/1000 -> 130.91 | F13: =45230/1000 -> 45.23 | H13: =SUM(C13:G13) -> 668.77
A14: CAB-06 | B14: VUELTAS | C14: 7 | D14: 17 | E14: 6 | F14: 7 | G14: 1 | H14: =SUM(C14:G14) -> 38
B15: CARGA | C15: =145000/1000 -> 145 | D15: =373760/1000 -> 373.76 | E15: =122690/1000 -> 122.69 | F15: =155030/1000 -> 155.03 | G15: =23330/1000 -> 23.33 | H15: =SUM(C15:G15) -> 819.81
A16: CAB-07 | B16: VUELTAS | C16: 1 | D16: 17 | E16: 5 | F16: 7 | G16: 2 | H16: =SUM(C16:G16) -> 32
B17: CARGA | C17: =20690/1000 -> 20.69 | D17: =338890/1000 -> 338.89 | E17: =106710/1000 -> 106.71 | F17: =209550/1000 -> 209.55 | G17: =70250/1000 -> 70.25 | H17: =SUM(C17:G17) -> 746.09
A18: CAB-08 | B18: VUELTAS | C18: 7 | D18: 17 | E18: 8 | F18: 5 | H18: =SUM(C18:G18) -> 37
B19: CARGA | C19: =142070/1000 -> 142.07 | D19: =366730/1000 -> 366.73 | E19: =173070/1000 -> 173.07 | F19: =175640/1000 -> 175.64 | H19: =SUM(C19:G19) -> 857.51
A20: CAB-09 | B20: VUELTAS | C20: 4 | D20: 11 | E20: 7 | F20: 7 | G20: 1 | H20: =SUM(C20:G20) -> 30
B21: CARGA | C21: =82180/1000 -> 82.18 | D21: =210410/1000 -> 210.41 | E21: =165945/1000 -> 165.945 | F21: =144090/1000 -> 144.09 | G21: =35100/1000 -> 35.1 | H21: =SUM(C21:G21) -> 637.725
A22: CAB-10 | B22: VUELTAS | C22: 0 | D22: 0 | E22: 0 | F22: 3 | G22: 5 | H22: =SUM(C22:G22) -> 8
B23: CARGA | C23: =0/1000 -> 0 | D23: =0/1000 -> 0 | E23: =0/1000 -> 0 | F23: =61650/1000 -> 61.65 | G23: =97980/1000 -> 97.98 | H23: =SUM(C23:G23) -> 159.63
A24: CAB-11 | B24: VUELTAS | C24: 8 | D24: 20 | E24: 8 | F24: 6 | G24: 1 | H24: =SUM(C24:G24) -> 43
B25: CARGA | C25: =151450/1000 -> 151.45 | D25: =413500/1000 -> 413.5 | E25: =167910/1000 -> 167.91 | F25: =195590/1000 -> 195.59 | G25: =30110/1000 -> 30.11 | H25: =SUM(C25:G25) -> 958.56
A26: CAB-12 | B26: VUELTAS | C26: 5 | D26: 7 | E26: 5 | F26: 5 | G26: 2 | H26: =SUM(C26:G26) -> 24
B27: CARGA | C27: =87230/1000 -> 87.23 | D27: =148160/1000 -> 148.16 | E27: =108840/1000 -> 108.84 | F27: =118610/1000 -> 118.61 | G27: =37380/1000 -> 37.38 | H27: =SUM(C27:G27) -> 500.22
A28: CAM-02 Plataforma | B28: VUELTAS | C28: 0 | D28: 0 | E28: 0 | F28: 4 | G28: 1 | H28: =SUM(C28:G28) -> 5
B29: CARGA | C29: =0/1000 -> 0 | D29: 0 | E29: =0/1000 -> 0 | F29: =41710/1000 -> 41.71 | G29: =11800/1000 -> 11.8 | H29: =SUM(C29:G29) -> 53.51
A30: CAM-04 Plataforma | B30: VUELTAS | C30: 0 | D30: 1 | E30: 0 | F30: 0 | H30: =SUM(C30:G30) -> 1
B31: CARGA | C31: =0/1000 -> 0 | D31: =5900/1000 -> 5.9 | E31: =0/1000 -> 0 | F31: =0/1000 -> 0 | H31: =SUM(C31:G31) -> 5.9
A32: CAM-05 Plataforma | B32: VUELTAS | C32: 0 | D32: 1 | E32: 0 | F32: 1 | H32: =SUM(C32:G32) -> 2
B33: CARGA | C33: =0/1000 -> 0 | D33: =11090/1000 -> 11.09 | E33: =0/1000 -> 0 | F33: =12420/1000 -> 12.42 | H33: =SUM(C33:G33) -> 23.51
A34: CAM-07 | B34: VUELTAS | C34: 2 | D34: 2 | E34: 0 | F34: 0 | H34: =SUM(C34:G34) -> 4
B35: CARGA | C35: =10520/1000 -> 10.52 | D35: =9300/1000 -> 9.3 | E35: =0/1000 -> 0 | F35: =0/1000 -> 0 | H35: =SUM(C35:G35) -> 19.82
A36: CAM-08 | B36: VUELTAS | C36: 6 | D36: 7 | E36: 6 | F36: 4 | G36: 2 | H36: =SUM(C36:G36) -> 25
B37: CARGA | C37: =33420/1000 -> 33.42 | D37: =54840/1000 -> 54.84 | E37: =46655/1000 -> 46.655 | F37: =29630/1000 -> 29.63 | G37: =18670/1000 -> 18.67 | H37: =SUM(C37:G37) -> 183.215 | I37: =+F37/F36 -> 7.4075
A38: CAM-09 | B38: VUELTAS | C38: 4 | D38: 3 | E38: 3 | F38: 3 | G38: 1 | H38: =SUM(C38:G38) -> 14
B39: CARGA | C39: =37840/1000 -> 37.84 | D39: =36540/1000 -> 36.54 | E39: =34190/1000 -> 34.19 | F39: =37950/1000 -> 37.95 | G39: =12120/1000 -> 12.12 | H39: =SUM(C39:G39) -> 158.64 | J39: =+E39/E38 -> 11.396667
A40: VOL-02 | B40: VUELTAS | C40: 10 | D40: 21 | E40: 20 | F40: 9 | G40: 3 | H40: =SUM(C40:G40) -> 63
B41: CARGA | C41: =78300/1000 -> 78.3 | D41: =201030/1000 -> 201.03 | E41: =102535/1000 -> 102.535 | F41: =58440/1000 -> 58.44 | G41: =30500/1000 -> 30.5 | H41: =SUM(C41:G41) -> 470.805 | J41: =+E41/E40 -> 5.12675
A42: VOL-04 | B42: VUELTAS | C42: 18 | D42: 23 | E42: 14 | F42: 13 | H42: =SUM(C42:G42) -> 68
...

Sheet BITACORA
A1: BITACORA DE VIAJES Y USO DE CAMIONES
A3: FECHA | B3: CAMION | C3: RUTA | D3: HORA DE SALIDA | E3: HORA DE LLEGADA | F3: CARGA | G3: PESO | H3: CHOFER | I3: NOVEDADES
A4: 44256 | B4: PARTICULAR | C4: HIGHNESS ENTERPRISE CO.,.LTD | D4: 0.44444444 | E4: 0.62986111 | F4: DESPACHO DE HARINA DE CAMARON | G4: 25000 | H4: JOSE APO
A5: 44256 | B5: PARTICULAR | C5: HIGHNESS ENTERPRISE CO.,.LTD | D5: 0.45069444 | E5: 0.63472222 | F5: DESPACHO DE HARINA DE CAMARON | G5: 25000 | H5: EDUARDO DUARTE
A6: 44256 | B6: PARTICULAR | C6: ALEXANDER PANCHANA LIBERTAD | D6: 0.55902778 | E6: 0.61527778 | F6: PAÑOS USADOS | G6: 2530 | H6: ANTONIO MALAVE PEREZ
A7: 44256 | B7: PARTICULAR | C7: COMBUSPETROL | D7: 0.54444444 | E7: 0.61319444 | F7: BUNKER | G7: 35370 | H7: JOSE LEON
A8: 44256 | B8: CAM-8 | C8: FRIGOLANDIA-CEPROMAR | D8: 0.57916667 | E8: 0.39652778 | F8: SUBPRODUCTO DE DORADO | G8: 7240 | H8: CESAR INTRIAGO
A9: 44256 | B9: PARTICULAR | C9: COMBUSPETROL | D9: 0.62152778 | E9: 0.59652778 | F9: BUNKER | G9: 35340 | H9: DAVID GONZALEZ
A10: 44256 | B10: CAB-11 | C10: TAURA FORTIDEX | D10: 0.63819444 | E10: 0.72430556 | F10: TRASLADO DE HARINA DE CAMARON | G10: 21070 | H10: FEDERICO PIONCE
A11: 44256 | B11: PLATAFORMA | C11: MUELLE FORTIDEX | D11: 0.65416667 | E11: 0.675 | F11: INGRESO DE MALLAS USADAS | G11: 1220 | H11: JAVIER ICAZA
A12: 44256 | B12: CAB-8 | C12: GISIS S.A. | D12: 0.67222222 | E12: 0.72986111 | F12: DESPACHO DE HIDROLIZADO DE PESCADO | G12: 23470 | H12: CARLOS VILLAACRESES
A13: 44256 | B13: CAB-9 | C13: TAURA FORTIDEX | D13: 0.67708333 | E13: 0.70763889 | F13: TRASLADO DE HARINA DE CAMARON | G13: 21070 | H13: GALO TUAZA
A14: 44256 | B14: CAB-2 | C14: TAURA FORTIDEX | D14: 0.68472222 | E14: 0.81597222 | F14: TRASLADO DE HARINA DE CAMARON | G14: 21090 | H14: ANDERSON VALENCIA
A15: 44256 | B15: CAM-7 | C15: DOCAPES | D15: 0.97152778 | E15: 0.41319444 | F15: SUBPRODUCTO DE MERLUZA | G15: 6780 | H15: JAIME ALBAN
... A64: 44259 | B64: VOL-2 | C64: B/P SAN JORGE | D64: 0.70972222 | E64: 0.71666667 | F64: MORENILLO | G64: 11290 | H64: FIDEL CRESPIN
A65: 44259 | B65: CAB-11 | C65: BIOMAR | D65: 0.74652778 | F65: INGRESO DE 16 IBC | G65: 18480 | H65: FEDERICO PIONCE
A66: 44259 | B66: VOL-2 | C66: B/P SAN JORGE | D66: 0.76319444 | E66: 0.77569444 | F66: MORENILLO-POLLA-GALLINAZA-SARDINA | G66: 3050 | H66: FIDEL CRESPIN
A67: 44259 | B67: CAB-5 | C67: GISIS S.A. | D67: 0.78819444 | E67: 0.37430556 | F67: DEVOLUCION DE 5 BINES VACIOS IBC | G67: 310 | H67: VICTOR QUINDE
A68: 44259 | B68: PARTICULAR | C68: HERNAN MAZZINI | D68: 0.80972222 | E68: 0.89652778 | F68: POLLA-BAGRE-GALLINA | G68: 8400 | H68: HENRIQUE CHALEN
A69: 44259 | B69: CAB-3 | C69: SALICA | D69: 0.82152778 | E69: 0.37083333 | F69: AGUA DE COCCION | G69: 11214 | H69: EDGAR CASTRO
A70: 44259 | B70: VOL-2 | C70: B/P PARDELA | D70: 0.825 | E70: 0.83472222 | F70: MORENILLO | G70: 3840 | H70: FIDEL CRESPIN
A71: 44259 | B71: PARTICULAR | C71: HERNAN MAZZINI | D71: 0.83958333 | E71: 0.85694444 | F71: POLLA-BAGRE | G71: 9220 | H71: MARCOS QUITIO
A72: 44259 | B72: CAM-8 | C72: CEPROFISH | D72: 0.91527778 | E72: 0.44930556 | F72: SUBPRODUCTO DE DORADO | G72: 2160 | H72: CESAR INTRIAGO
A73: 44259 | B73: PARTICULAR | C73: JUAN DELGADO | D73: 0.9375 | E73: 0.99375 | F73: SUBPRODUCTO DE ALBACORA | G73: 12265 | H73: VICTOR SILVA
A74: 44259 | B74: VOL-2 | C74: HERNAN MAZZINI | D74: 0.93958333 | E74: 0.95138889 | F74: POLLA BAGRE | G74: 10620 | H74: FIDEL CRESPIN
A75: 44259 | B75: CAB-9 | C75: GISIS S.A. | D75: 0.94305556 | E75: 0.39305556 | F75: DESPACHO ACEITE DE PESCADO | G75: 20450 | H75: GALO TUAZA
A76: 44259 | B76: VOL-4 | C76: B/P ANGEL | D76: 0.99166667 | E76: 0 | F76: MORENILLO | G76: 630 | H76: FIDEL CRESPIN
A77: 44260 | B77: PARTICULAR | C77: HERNAN MAZZINI | D77: 0.015277778 | E77: 0.036805556 | F77: GALLINA | G77: 7220 | H77: MARCOS QUITIO
... A337: 44267 | B337: PARTICULAR | C337: HERNAN MAZZINI | D337: 0.96180556 | E337: 0.0055555556 | F337: SARDINA | G337: 2660 | H337: ENRIQUE CHALEN
A338: 44267 | B338: CAB-9 | C338: B/P VB III | D338: 23:08 | E338: 0.10625 | F338: SARDINA | G338: 23110 | H338: GALO TUAZA
A339: 44267 | B339: PARTICULAR | C339: LADY SOLIS | D339: 0.98333333 | E339: 0.072222222 | F339: MORENILLO | G339: 11140 | H339: JUAN MATEO
A340: 44268 | B340: CAM-9 | C340: SEAFMAN | D340: 0.052777778 | E340: 0.28263889 | F340: SUBPRODUCTO DE ATUN COCIDO - VISCERAS AGALLAS | G340: 11490 | H340: ALFREDO CEDEÑO
A341: 44268 | B341: CAB-3 | C341: B/P ALZOMAR - B/P DIYAIMAR IV - B/P JOEL | D341: 0.084722222 | E341: 0.093055556 | F341: HOJA - CARA | G341: 10960 | H341: EDGAR CASTRO
A342: 44268 | B342: PARTICULAR | C342: HERNAN MAZZINI | D342: 0.088888889 | E342: 0.13611111 | F342: GALLINA | G342: 4670 | H342: MARCOS QUITIO
A343: 44268 | B343: CAM-8 | C343: CEPROMAR - FRIGOLANDIA - CEPROFISH | D343: 0.12291667 | E343: 0.13472222 | F343: SUB PRODUCTO DE DORADO - VISCERAS | G343: 10140 | H343: CESAR INTRIAGO
A344: 44268 | B344: CAB-12 | C344: PROMOPESCA | D344: 0.12569444 | E344: 0.1375 | F344: SUBPODUCTO DE ATUN COCIDO-CRUDO | G344: 22240 | H344: SANTIAGO MALDONADO
A345: 44268 | B345: PARTICULAR | C345: XIAMEN SEASHINE CEREALS DEVELOPMENT CO., LTD | D345: 0.35069444 | E345: 0.55208333 | F345: DESPACHO DE HARINA DE PESCADO | G345: 26500 | H345: EDUARDO DUARTE
A346: 44268 | B346: PARTICULAR | C346: XIAMEN SEASHINE CEREALS DEVELOPMENT CO., LTD | D346: 0.35347222 | E346: 0.56388889 | F346: DESPACHO DE HARINA DE PESCADO | G346: 26500 | H346: ALEXIS BASANTE
A347: 44268 | B347: PARTICULAR | C347: XIAMEN SEASHINE CEREALS DEVELOPMENT CO., LTD | D347: 0.35763889 | E347: 0.55 | F347: DESPACHO DE HARINA DE PESCADO | G347: 26500 | H347: JOSE APO
A348: 44268 | B348: CAB-7 | C348: B/P MARIANITA | D348: 0.35555556 | E348: 0.36111111 | F348: BOTELLA | G348: 22950 | H348: RENE MARQUEZ
...

Sheet Camiones
A2: Cam-02 | B2: =+BITACORA!B1017 -> Traslado de Harina Jambeli | C2: =+BITACORA!C1017 -> 49.81 | D2: =+C2/C4 -> 0.93085405
B3: =+BITACORA!B1018 -> Ingreso Varios | C3: =+BITACORA!C1018 -> 3.7 | D3: =+C3/C4 -> 0.069145954
A4: Total de carga | C4: =SUM(C2:C3) -> 53.51 | D4: =SUM(D2:D3) -> 1
A9: Cam-04 | B9: =+BITACORA!B1019 -> Ingreso Varios | C9: =+BITACORA!C1019 -> 5.9 | D9: =+C9/C10 -> 1
A10: Total de carga | C10: =SUM(C9:C9) -> 5.9 | D10: =SUM(D9:D9) -> 1
A16: Cam-05 | B16: =+BITACORA!B1020 -> Traslado de Harina Jambeli | C16: =+BITACORA!C1020 -> 23.51 | D16: =+C16/C17 -> 1
A17: Total de carga | C17: =SUM(C16:C16) -> 23.51 | D17: =SUM(D16:D16) -> 1
A23: Cam-07 | B23: =+BITACORA!B1021 -> Sub-Prod. Pelagicos | C23: =+BITACORA!C1021 -> 19.82 | D23: =+C23/C24 -> 1
A24: Total de carga | C24: =SUM(C23:C23) -> 19.82 | D24: =SUM(D23:D23) -> 1
A29: Cam-08 | B29: =+BITACORA!B1022 -> Sub-Prod. Pelagicos | C29: =+BITACORA!C1022 -> 178.515 | D29: =+C29/C31 -> 0.97434708
B30: =+BITACORA!B1023 -> Ingreso Varios | C30: =+BITACORA!C1023 -> 4.7 | D30: =+C30/C31 -> 0.025652921
A31: Total de carga | C31: =SUM(C29:C30) -> 183.215 | D31: =SUM(D29:D30) -> 1
A35: Cam-09 | B35: =+BITACORA!B1024 -> Sub-Prod. Pelagicos Seafman | C35: =+BITACORA!C1024 -> 158.38 | D35: =+C35/C37 -> 0.99836107
B36: =+BITACORA!B1025 -> Ingreso Varios | C36: =+BITACORA!C1025 -> 0.26 | D36: =+C36/C37 -> 0.0016389309
A37: Total de carga | C37: =SUM(C35:C36) -> 158.64 | D37: =SUM(D35:D36) -> 1
A42: Vol-02 | B42: =+BITACORA!B1026 -> Materia Prima | C42: =+BITACORA!C1026 -> 440.305 | D42: =+C42/C44 -> 0.93521734
B43: =+BITACORA!B1027 -> Mat./Contruccion | C43: =+BITACORA!C1027 -> 30.5 | D43: =+C43/C44 -> 0.064782659
A44: Total de carga | C44: =SUM(C42:C43) -> 470.805 | D44: =SUM(D42:D43) -> 1
A48: Vol-04 | B48: =+BITACORA!B1028 -> Materia Prima | C48: =+BITACORA!C1028 -> 386.695 | D48: =+C48/C49 -> 1
A49: Total de carga | C49: =SUM(C48:C48) -> 386.695 | D49: =SUM(D48:D48) -> 1

Sheet Cargas por remolque
B1: DISCO | C1: REMOLQUE | D1: TIPOS DE CARGA | E1: TON./CARGA | F1: PORCENTAJE POR CARGA | G1: PORCENTAJE POR REMOLQUE | H1: TOTAL/TON. REMOLQUE
B2: Cab-01 | C2: BAÑERA | D2: =+BITACORA!B959 -> Materia Prima | E2: =+BITACORA!C959 -> 98.135 | F2: =+E2/E7 -> 0.17507694 | G2: =+F2 -> 0.17507694 | H2: =+E2 -> 98.135
C3: PLATAFORMA | D3: =+BITACORA!B960 -> Despacho Hidrolizado Venta | E3: =+BITACORA!C960 -> 23.35 | F3: =+E3/E7 -> 0.041657375 | G3: =+F3+F4+F5 -> 0.75167031 | H3: =+E3+E4+E5 -> 421.33
D4: =+BITACORA!B961 -> Traslado Har./Pescado Jambeli | E4: =+BITACORA!C961 -> 387.26 | F4: =+E4/E7 -> 0.69088801
D5: =+BITACORA!B962 -> Ingreso Varios | E5: =+BITACORA!C962 -> 10.72 | F5: =+E5/E7 -> 0.019124928
C6: TANQUERO | D6: =+BITACORA!B963 -> A./Cocción Salica | E6: =+BITACORA!C963 -> 41.06 | F6: =+E6/E7 -> 0.073252754 | G6: =+F6 -> 0.073252754 | H6: =+E6 -> 41.06
B7: Total de carga | E7: =SUM(E2:E6) -> 560.525 | F7: =SUBTOTAL(9,F2:F6) -> 1 | G7: =SUBTOTAL(9,G2:G6) -> 1
B21: DISCO | C21: REMOLQUE | D21: TIPOS DE CARGA | E21: TON./CARGA | F21: PORCENTAJE POR CARGA | G21: PORCENTAJE POR REMOLQUE | H21: TOTAL/TON. REMOLQUE
B22: Cab-02 | C22: BAÑERA | D22: =+BITACORA!B964 -> Materia Prima | E22: =+BITACORA!C964 -> 409.27 | F22: =+E22/E28 -> 0.3789923 | G22: =+F22+F23 -> 0.69631166 | H22: =+E22+E23 -> 751.94
D23: =+BITACORA!B965 -> Scrap Atun Salica | E23: =+BITACORA!C965 -> 342.67 | F23: =+E23/E28 -> 0.31731936
C24: CONTENEDOR | D24: =+BITACORA!B966 -> Despacho Harina venta | E24: =+BITACORA!C966 -> 70.28 | F24: =+E24/E28 -> 0.065080703 | G24: =+F24 -> 0.065080703 | H24: =+E24 -> 70.28
C25: PLATAFORMA | D25: =+BITACORA!B967 -> Traslado Har./Pescado Jambeli | E25: =+BITACORA!C967 -> 175.42 | F25: =+E25/E28 -> 0.16244247 | G25: =+F25+F26 -> 0.18197224 | H25: =+E25+E26 -> 196.51
D26: =+BITACORA!B968 -> Traslado Har./Camaron Taura | E26: =+BITACORA!C968 -> 21.09 | F26: =+E26/E28 -> 0.019529767
C27: TANQUERO | D27: =+BITACORA!B969 -> A./Cocción Salica | E27: =+BITACORA!C969 -> 61.16 | F27: =+E27/E28 -> 0.056635398 | G27: =+F27 -> 0.056635398 | H27: =+E27 -> 61.16
B28: Total de carga | E28: =SUM(E22:E27) -> 1079.89 | F28: =SUM(F22:F27) -> 1 | G28: =SUM(G22:G27) -> 1
B46: DISCO | C46: REMOLQUE | D46: TIPOS DE CARGA | E46: TON./CARGA | F46: PORCENTAJE POR CARGA | G46: PORCENTAJE POR REMOLQUE | H46: TOTAL/TON. REMOLQUE
B47: Cab-03 | C47: BAÑERA | D47: =+BITACORA!B970 -> Materia Prima | E47: =+BITACORA!C970 -> 649.87 | F47: =+E47/E51 -> 0.60412898 | G47: =+F47+F48 -> 0.77070671 | H47: =+E47+E48 -> 829.06
D48: =+BITACORA!B971 -> Scrap Atun Salica | E48: =+BITACORA!C971 -> 179.19 | F48: =+E48/E51 -> 0.16657773
C49: PLATAFORMA | D49: =+BITACORA!B972 -> Traslado Har./Pescado Jambeli | E49: =+BITACORA!C972 -> 105.26 | F49: =+E49/E51 -> 0.097851288 | G49: =+F49 -> 0.097851288 | H49: =+E49 -> 105.26
C50: TANQUERO | D50: =+BITACORA!B973 -> A./Cocción Salica | E50: =+BITACORA!C973 -> 141.394 | F50: =+E50/E51 -> 0.131442 | G50: =+F50 -> 0.131442 | H50: =+E50 -> 141.394
B51: Total de carga | E51: =SUM(E47:E50) -> 1075.714 | F51: =SUM(F47:F50) -> 1 | G51: =SUM(G47:G50) -> 1
B67: DISCO | C67: REMOLQUE | D67: TIPOS DE CARGA | E67: TON./CARGA | F67: PORCENTAJE POR CARGA | G67: PORCENTAJE POR REMOLQUE | H67: TOTAL/TON. REMOLQUE
B68: Cab-05 | C68: BAÑERA | D68: =+BITACORA!B974 -> Materia Prima | E68: =+BITACORA!C974 -> 518.26 | F68: =+E68/E72 -> 0.77494505 | G68: =+F68 -> 0.77494505 | H68: =+E68 -> 518.26
C69: PLATAFORMA | D69: =+BITACORA!B975 -> Traslado Har./Pescado Jambeli | E69: =+BITACORA!C975 -> 127.23 | F69: =+E69/E72 -> 0.19024478 | G69: =+F69+F70+F71 -> 0.22505495 | H69: =+E69+E70+E71 -> 150.51
D70: =+BITACORA!B976 -> Ingreso Varios | E70: =+BITACORA!C976 -> 0.31 | F70: =+E70/E72 -> 0.00046353754
D71: =+BITACORA!B977 -> Despacho Hidrolizado Venta | E71: =+BITACORA!C977 -> 22.97 | F71: =+E71/E72 -> 0.034346636
B72: Total de carga | E72: =SUM(E68:E71) -> 668.77 | F72: =SUM(F68:F71) -> 1 | G72: =SUM(G68:G71) -> 1
B87: DISCO | C87: REMOLQUE | D87: TIPOS DE CARGA | E87: TON./CARGA | F87: PORCENTAJE POR CARGA | G87: PORCENTAJE POR REMOLQUE | H87: TOTAL/TON. REMOLQUE
B88: Cab-06 | C88: BAÑERA | D88: =+BITACORA!B978 -> Materia Prima | E88: =+BITACORA!C978 -> 609.18 | F88: =+E88/E93 -> 0.74307461 | G88: =+F88 -> 0.74307461 | H88: =+E88 -> 609.18
C89: CONTENEDOR | D89: =+BITACORA!B979 -> Despacho Harina venta | E89: =+BITACORA!C979 -> 25.36 | F89: =+E89/E93 -> 0.030933997 | G89: =+F89 -> 0.030933997 | H89: =+E89 -> 25.36
C90: PLATAFORMA | D90: =+BITACORA!B980 -> Despacho Hidrolizado Venta | E90: =+BITACORA!C980 -> 23.33 | F90: =+E90/E93 -> 0.028457813 | G90: =+F90+F91 -> 0.1961918 | H90: =+E90+E91 -> 160.84
D91: =+BITACORA!B981 -> Traslado Har./Pescado Jambeli | E91: =+BITACORA!C981 -> 137.51 | F91: =+E91/E93 -> 0.16773399
C92: TANQUERO | D92: =+BITACORA!B982 -> A./Cocción Salica | E92: =+BITACORA!C982 -> 24.43 | F92: =+E92/E93 -> 0.029799588 | G92: =+F92 -> 0.029799588 | H92: =+E92 -> 24.43
B93: Total de carga | E93: =SUM(E88:E92) -> 819.81 | F93: =SUM(F88:F92) -> 1 | G93: =SUM(G88:G92) -> 1
B109: DISCO | C109: REMOLQUE | D109: TIPOS DE CARGA | E109: TON./CARGA | F109: PORCENTAJE POR CARGA | G109: PORCENTAJE POR REMOLQUE | H109: TOTAL/TON. REMOLQUE
B110: Cab-07 | C110: BAÑERA | D110: =+BITACORA!B983 -> Materia Prima | E110: =+BITACORA!C983 -> 372.75 | F110: =+E110/E115 -> 0.49960461 | G110: =+F110 -> 0.49960461 | H110: =+E110 -> 372.75
C111: CONTENEDOR | D111: =+BITACORA!B984 -> Despacho Harina venta | E111: =+BITACORA!C984 -> 300.91 | F111: =+E111/E115 -> 0.40331595 | G111: =+F111 -> 0.40331595 | H111: =+E111 -> 300.91
C112: PLATAFORMA | D112: =+BITACORA!B985 -> Traslado Har./Pescado Jambeli | E112: =+BITACORA!C985 -> 50.9 | F112: =+E112/E115 -> 0.068222332 | G112: =+F112+F113 -> 0.070165798 | H112: =+E112+E113 -> 52.35
D113: =+BITACORA!B986 -> Ingreso Varios | E113: =+BITACORA!C986 -> 1.45 | F113: =+E113/E115 -> 0.0019434653
C114: TANQUERO | D114: =+BITACORA!B987 -> Despacho de Aceite | E114: =+BITACORA!C987 -> 20.08 | F114: =+E114/E115 -> 0.026913643 | G114: =+F114 -> 0.026913643 | H114: =+E114 -> 20.08
...

Sheet Rendimiento Choferes
A2: REPORTE DE VIAJES Y CARGA POR RENDIMIENTO | K2: Castro Choez Edgar
D3: MES | E3: MARZO | K3: Iñiga Bohorquez Hugo
K4: Maldonado Reyes Santiago
A5: NOMINA | B5: UNIDAD | C5: REMOLQUE | D5: VUELTAS | E5: CARGA TRANSPORTADA | F5: CAPACIDAD CAMION TM | G5: CAPACIDAD NOMINAL DISPONIBLE | H5: REND. / VIAJE | I5: % USO CAMION TM | K5: Marquez Arias Rene
A6: Sr. Castro Choez Edgar David | B6: CAB-01 | C6: BAÑERA | D6: 3 | E6: =+(64640)/1000 -> 64.64 | F6: 20 | G6: =+F6*D6 -> 60 | H6: =+(E6/G6)-1 -> 0.077333333 | I6: =1+H6 -> 1.0773333 | K6: Pionce Pachay Federico
C7: PLATAFORMA | D7: 3 | E7: =+(74870)/1000 -> 74.87 | F7: 30 | G7: =+F7*D7 -> 90 | H7: =+(E7/G7)-1 -> -0.16811111 | I7: =1+H7 -> 0.83188889 | K7: Quinde Flores Victor
B8: CAB-03 | C8: BAÑERA | D8: 40 | E8: =+(753675)/1000 -> 753.675 | F8: 20 | G8: =+F8*D8 -> 800 | H8: =+(E8/G8)-1 -> -0.05790625 | I8: =1+H8 -> 0.94209375 | K8: Tuaza Vargas Galo
C9: PLATAFORMA | D9: 5 | E9: =+(105260)/1000 -> 105.26 | F9: 30 | G9: =+F9*D9 -> 150 | H9: =+(E9/G9)-1 -> -0.29826667 | I9: =1+H9 -> 0.70173333 | K9: Valencia Yagual Anderson
C10: TANQUERO | D10: 7 | E10: =+(141394)/1000 -> 141.394 | F10: 30 | G10: =+F10*D10 -> 210 | H10: =+(E10/G10)-1 -> -0.32669524 | I10: =1+H10 -> 0.67330476 | K10: Villacreses De La A Carlos
B11: Vol-04 | D11: 1 | E11: =+(5250)/1000 -> 5.25 | F11: 8 | G11: =+F11*D11 -> 8 | H11: =+(E11/G11)-1 -> -0.34375 | I11: =1+H11 -> 0.65625 | K11: Villon De Los Angeles Pablo | S11: 48
D12: =SUM(D6:D11) -> 59 | E12: =SUM(E6:E11) -> 1145.089 | G12: =SUM(G6:G11) -> 1318 | H12: =+(E12/G12)-1 -> -0.13119196 | I12: =1+H12 -> 0.86880804 | S12: =+#REF!-T12 -> #REF!
A13: Carga Promedio del Conductor =======================================> | G13: =+E12/D12 -> 19.408288
A15: Sr. Iñiga Bohorquez Hugo Roberto | B15: CAB-01 | C15: BAÑERA | D15: 2 | E15: =+(33495)/1000 -> 33.495 | F15: 20 | G15: =+F15*D15 -> 40 | H15: =+(E15/G15)-1 -> -0.162625 | I15: =1+H15 -> 0.837375
C16: PLATAFORMA | D16: 10 | E16: =+(193960)/1000 -> 193.96 | F16: 30 | G16: =+F16*D16 -> 300 | H16: =+(E16/G16)-1 -> -0.35346667 | I16: =1+H16 -> 0.64653333
C17: TANQUERO | D17: 2 | E17: =+(41060)/1000 -> 41.06 | F17: 30 | G17: =+F17*D17 -> 60 | H17: =+(E17/G17)-1 -> -0.31566667 | I17: =1+H17 -> 0.68433333
D18: =SUM(D15:D17) -> 14 | E18: =SUM(E15:E17) -> 268.515 | G18: =+SUM(G15:G17) -> 400 | H18: =+(E18/G18)-1 -> -0.3287125 | I18: =1+H18 -> 0.6712875
A19: Carga Promedio del Conductor =======================================> | G19: =+E18/D18 -> 19.179643
A21: Sr. Maldonado Reyes Santiago Rafael | B21: CAB-12 | C21: BAÑERA | D21: 23 | E21: =+(483030)/1000 -> 483.03 | F21: 20 | G21: =+F21*D21 -> 460 | H21: =+(E21/G21)-1 -> 0.050065217 | I21: =1+H21 -> 1.0500652
D22: =SUM(D21:D21) -> 23 | E22: =SUM(E21:E21) -> 483.03 | G22: =SUM(G21:G21) -> 460 | H22: =+(E22/G22)-1 -> 0.050065217 | I22: =1+H22 -> 1.0500652
A23: Carga Promedio del Conductor =======================================> | G23: =+E22/D22 -> 21.001304
A25: Sr. Marquez Arias Rene Alejandrino | B25: CAB-02 | C25: BAÑERA | D25: 1 | E25: =+(13980)/1000 -> 13.98 | F25: 20 | G25: =+F25*D25 -> 20 | H25: =+(E25/G25)-1 -> -0.301 | I25: =1+H25 -> 0.699
B26: CAB-07 | C26: BAÑERA | D26: 19 | E26: =+(372750)/1000 -> 372.75 | F26: 20 | G26: =+F26*D26 -> 380 | H26: =+(E26/G26)-1 -> -0.019078947 | I26: =1+H26 -> 0.98092105
C27: CONTENEDOR | D27: 9 | E27: =+(300910)/1000 -> 300.91 | F27: 30 | G27: =+F27*D27 -> 270 | H27: =+(E27/G27)-1 -> 0.11448148 | I27: =1+H27 -> 1.1144815
C28: PLATAFORMA | D28: 1 | E28: =+(1450)/1000 -> 1.45 | F28: 30 | G28: =+F28*D28 -> 30 | H28: =+(E28/G28)-1 -> -0.95166667 | I28: =1+H28 -> 0.048333333
C29: TANQUERO | D29: 1 | E29: =+(20080)/1000 -> 20.08 | F29: 30 | G29: =+F29*D29 -> 30 | H29: =+(E29/G29)-1 -> -0.33066667 | I29: =1+H29 -> 0.66933333
B30: VOL-02 | D30: 3 | E30: =+(20760)/1000 -> 20.76 | F30: 8 | G30: =+F30*D30 -> 24 | H30: =+(E30/G30)-1 -> -0.135 | I30: =1+H30 -> 0.865
D31: =SUM(D25:D30) -> 34 | E31: =SUM(E25:E30) -> 729.93 | G31: =SUM(G25:G30) -> 754 | H31: =+(E31/G31)-1 -> -0.031923077 | I31: =1+H31 -> 0.96807692
A32: Carga Promedio del Conductor =======================================> | G32: =+E31/D31 -> 21.468529
A34: Sr. Pionce Pachay Federico Demecio | B34: CAB-07 | C34: BAÑERA | D34: 24 | E34: =+(444090)/1000 -> 444.09 | F34: 20 | G34: =+F34*D34 -> 480 | H34: =+(E34/G34)-1 -> -0.0748125 | I34: =1+H34 -> 0.9251875
C35: CONTENEDOR | D35: 9 | E35: =+(288030)/1000 -> 288.03 | F35: 30 | G35: =+F35*D35 -> 270 | H35: =+(E35/G35)-1 -> 0.066777778 | I35: =1+H35 -> 1.0667778
C36: PLATAFORMA | D36: 10 | E36: =+(226440)/1000 -> 226.44 | F36: 30 | G36: =+F36*D36 -> 300 | H36: =+(E36/G36)-1 -> -0.2452 | I36: =1+H36 -> 0.7548
D37: =SUM(D34:D36) -> 43 | E37: =SUM(E34:E36) -> 958.56 | G37: =SUM(G34:G36) -> 1050 | H37: =+(E37/G37)-1 -> -0.087085714 | I37: =1+H37 -> 0.91291429
A38: Carga Promedio del Conductor =======================================> | G38: =+E37/D37 -> 22.292093
A40: Sr. Quinde Flores Victor Eloy | B40: CAB-05 | C40: BAÑERA | D40: 27 | E40: =+(518260)/1000 -> 518.26 | F40: 20 | G40: =+F40*D40 -> 540 | H40: =+(E40/G40)-1 -> -0.040259259 | I40: =1+H40 -> 0.95974074
C41: PLATAFORMA | D41: 8 | E41: =+(150510)/1000 -> 150.51 | F41: 30 | G41: =+F41*D41 -> 240 | H41: =+(E41/G41)-1 -> -0.372875 | I41: =1+H41 -> 0.627125
B42: CAM-05 | D42: 1 | E42: =+(12420)/1000 -> 12.42 | F42: 8 | G42: =+F42*D42 -> 8 | H42: =+(E42/G42)-1 -> 0.5525 | I42: =1+H42 -> 1.5525
D43: =SUM(D40:D42) -> 36 | E43: =SUM(E40:E42) -> 681.19 | G43: =SUM(G40:G42) -> 788 | H43: =+(E43/G43)-1 -> -0.13554569 | I43: =1+H43 -> 0.86445431
A44: Carga Promedio del Conductor =======================================> | G44: =+E43/D43 -> 18.921944
A46: Sr. Tuaza Vargas Victor Galo | B46: CAB-01 | C46: PLATAFORMA | D46: 1 | E46: =+(25310)/1000 -> 25.31 | F46: 30 | G46: =+F46*D46 -> 30 | H46: =+(E46/G46)-1 -> -0.15633333 | I46: =1+H46 -> 0.84366667
B47: CAB-09 | C47: BAÑERA | D47: 15 | E47: =+(300275)/1000 -> 300.275 | F47: 20 | G47: =+F47*D47 -> 300 | H47: =+(E47/G47)-1 -> 0.00091666667 | I47: =1+H47 -> 1.0009167
...

Sheet Hoja1
E6: Nombre | F6: Camiones | J6: Arrastres
F7: Vuetas | G7: Carga | H7: % | I7: Media | J7: Vueltas | K7: Cargas | L7: % | M7: Media
D8: 1 | E8: Sr. Castro Choez Edgar | J8: =+'Rendimiento Choferes'!D12 -> 59 | K8: =+'Rendimiento Choferes'!E12 -> 1145.089 | L8: =+'Rendimiento Choferes'!I12 -> 0.86880804 | M8: =+'Rendimiento Choferes'!G13 -> 19.408288
D9: 2 | E9: Sr. Iñiga Bohorquez Hugo | J9: =+'Rendimiento Choferes'!D18 -> 14 | K9: =+'Rendimiento Choferes'!E18 -> 268.515 | L9: =+'Rendimiento Choferes'!I18 -> 0.6712875 | M9: =+'Rendimiento Choferes'!G19 -> 19.179643
D10: 3 | E10: Sr. Maldonado Reyes Santiago | J10: =+'Rendimiento Choferes'!D22 -> 23 | K10: =+'Rendimiento Choferes'!E22 -> 483.03 | L10: =+'Rendimiento Choferes'!I22 -> 1.0500652 | M10: =+'Rendimiento Choferes'!G23 -> 21.001304
D11: 4 | E11: Sr. Marquez Arias Rene | J11: =+'Rendimiento Choferes'!D31 -> 34 | K11: 530.46 | L11: 0.95 | M11: 23.06
D12: 5 | E12: Sr. Pionce Pachay Federico Demecio | J12: =+'Rendimiento Choferes'!D37 -> 43 | K12: =+'Rendimiento Choferes'!E37 -> 958.56 | L12: =+'Rendimiento Choferes'!I31 -> 0.96807692 | M12: =+'Rendimiento Choferes'!G32 -> 21.468529
D13: 6 | E13: Sr. Quinde Flores Victor Eloy | J13: =+'Rendimiento Choferes'!D43 -> 36 | K13: =+'Rendimiento Choferes'!E43 -> 681.19 | L13: =+'Rendimiento Choferes'!I43 -> 0.86445431 | M13: =+'Rendimiento Choferes'!G44 -> 18.921944
D14: 7 | E14: Sr. Tuaza Vargas Victor Galo | J14: =+'Rendimiento Choferes'!D52 -> 32 | K14: =+'Rendimiento Choferes'!E52 -> 674.125 | L14: =+'Rendimiento Choferes'!I52 -> 0.85548858 | M14: =+'Rendimiento Choferes'!G53 -> 21.066406
D15: 8 | E15: Sr. Valencia Yagual Anderson | J15: =+'Rendimiento Choferes'!D59 -> 47 | K15: =+'Rendimiento Choferes'!E59 -> 1065.91 | L15: =+'Rendimiento Choferes'!I59 -> 1.0055755 | M15: =+'Rendimiento Choferes'!G60 -> 22.678936
D16: 9 | E16: Sr. Villacreses De La A Carlos | J16: =+'Rendimiento Choferes'!D66 -> 36 | K16: =+'Rendimiento Choferes'!E66 -> 834.04 | L16: =+'Rendimiento Choferes'!I66 -> 0.95866667 | M16: =+'Rendimiento Choferes'!G67 -> 23.167778
D17: 10 | E17: Sr. Villon De Los Angeles Pablo | J17: =+'Rendimiento Choferes'!D72 -> 39 | K17: =+'Rendimiento Choferes'!E72 -> 837 | L17: =+'Rendimiento Choferes'!I72 -> 0.96206897 | M17: =+'Rendimiento Choferes'!G73 -> 21.461538
D18: 11 | E18: Sr. Alvan Garcia Jaime Enrique | F18: =+'Rendimiento Choferes'!D84 -> 15 | G18: =+'Rendimiento Choferes'!E84 -> 125.82 | H18: =+'Rendimiento Choferes'!I84 -> 0.93895522 | I18: =+'Rendimiento Choferes'!G85 -> 8.388
D19: 12 | E19: Sr. Crespin Figueroa Fidel Edberto | F19: =+'Rendimiento Choferes'!D89 -> 70 | G19: =+'Rendimiento Choferes'!E89 -> 400.625 | H19: =+'Rendimiento Choferes'!I89 -> 0.71540179 | I19: =+'Rendimiento Choferes'!G90 -> 5.7232143
D20: 13 | E20: Sr. Intriago Pincay Cesar Emiliano | F20: =+'Rendimiento Choferes'!D93 -> 24 | G20: =+'Rendimiento Choferes'!E93 -> 174.985 | H20: =+'Rendimiento Choferes'!I93 -> 0.60758681 | I20: =+'Rendimiento Choferes'!G94 -> 7.2910417
E26: Ordenes de Trabajo
F27: Abiertas
F28: Cerradas
F29: En Proceso
F30: Promedio de dias
E32: Promedio Dias Compras
E34: Dispnibilidad Promedio de equipos
