Workbook

Sheet ROL_UNIFICADO
A1: ROL UNIFICADO MES NOVIEMBRE 2020
F3: 1° QUINCENA | H3: 2° QUINCENA
A4: ÀREA DE PENDULA | C4: SUELDO BASICO | D4: SUELDO EXTRA | E4: DIAS SEG/SUELDO | F4: V. TRABAJOS FIJOS | G4: V. TRABAJOS EXTRAS | H4: V. TRABAJOS FIJOS | I4: V. TRABAJOS EXTRAS | J4: PERMISO IESS | K4: VACACIONES | L4: TOTAL BRUTO | M4: DSCTO 9,45% IESS | N4: SUB-TOTAL SUELDO | O4: DECIMO 3RO | P4: DECIMO 4TO | Q4: TOTAL BENEFICIOS | R4: FONDO RESERVA | S4: OTROS VALORES | T4: BONIFICACION | U4: TOTAL INGRESOS | V4: OTROS DSCTOS | W4: MULTA | X4: ANTICIPOS | Y4: ALIMENTACION | Z4: PRESTAMO QUIROGRA | AA4: TOTAL EGRESOS | AB4: VALOR NETO DEL MES | AC4: ABONO1 | AD4: ABONO2 | AE4: ABONO3 | AF4: SALDO A RECIBIR
A5: 1 | B5: BAQUE MERO ROBERTH DANIEL | C5: =IF(L5>=401.41,401.41,IF(L5<401.41,L5)) -> 401.41 | D5: =+L5-C5 -> 129.8231 | E5: =+C5/13.3803 -> 30.000075 | F5: =+'TALLER ACTIVOS'!BF7 -> 405.33568 | G5: =+[1]TALLER!BB7 -> 0 | H5: =+'TALLER ACTIVOS'!CX7 -> 125.89741 | I5: =+[1]TALLER!CT7 -> 0 | L5: =+F5+G5+H5+I5+K5+J5 -> 531.2331 | M5: =IF(L5>=401.41,37.933,IF(L5<401.41,L5*9.45%)) -> 37.933 | N5: =+L5-M5 -> 493.3001 | O5: =IF(E5>=30,33.45,IF(E5<30,E5*1.115)) -> 33.45 | P5: =IF(E5>=30,33.33,IF(E5<30,E5*1.111)) -> 33.33 | Q5: =+O5+P5 -> 66.78 | R5: =33.45/30*E5 -> 33.450083 | U5: =N5+Q5+R5+S5+T5 -> 593.53018 | Z5: 46.63 | AA5: =+W5+V5+X5+Y5+Z5 -> 46.63 | AB5: =+U5-AA5 -> 546.90018 | AF5: =+AB5-AC5-AD5-AE5 -> 546.90018
A6: =A5+1 -> 2 | B6: RISCO ZAMBRANO JEFFERSON CECILIO | C6: =IF(L6>=401.41,401.41,IF(L6<401.41,L6)) -> 401.41 | D6: =+L6-C6 -> 99.937188 | E6: =+C6/13.3803 -> 30.000075 | F6: =+'TALLER ACTIVOS'!BF8 -> 384.23382 | G6: =+[1]TALLER!BB8 -> 0 | H6: =+'TALLER ACTIVOS'!CX8 -> 117.11337 | I6: =+[1]TALLER!CT8 -> 0 | L6: =+F6+G6+H6+I6+K6+J6 -> 501.34719 | M6: =IF(L6>=401.41,37.933,IF(L6<401.41,L6*9.45%)) -> 37.933 | N6: =+L6-M6 -> 463.41419 | O6: =IF(E6>=30,33.45,IF(E6<30,E6*1.115)) -> 33.45 | P6: =IF(E6>=30,33.33,IF(E6<30,E6*1.111)) -> 33.33 | Q6: =+O6+P6 -> 66.78 | R6: =33.45/30*E6 -> 33.450083 | U6: =N6+Q6+R6+S6+T6 -> 563.64427 | AA6: =+W6+V6+X6+Y6+Z6 -> 0 | AB6: =+U6-AA6 -> 563.64427 | AF6: =+AB6-AC6-AD6-AE6 -> 563.64427
A7: =A6+1 -> 3 | B7: CHANALATA TONATO CESAR AUGUSTO | C7: =IF(L7>=401.41,401.41,IF(L7<401.41,L7)) -> 401.41 | D7: =+L7-C7 -> 110.26075 | E7: =+C7/13.3803 -> 30.000075 | F7: =+'TALLER ACTIVOS'!BF9 -> 375.89941 | G7: =+[1]TALLER!BB9 -> 0 | H7: =+'TALLER ACTIVOS'!CX9 -> 135.77134 | I7: =+[1]TALLER!CT9 -> 0 | L7: =+F7+G7+H7+I7+K7+J7 -> 511.67075 | M7: =IF(L7>=401.41,37.933,IF(L7<401.41,L7*9.45%)) -> 37.933 | N7: =+L7-M7 -> 473.73775 | O7: =IF(E7>=30,33.45,IF(E7<30,E7*1.115)) -> 33.45 | P7: =IF(E7>=30,33.33,IF(E7<30,E7*1.111)) -> 33.33 | Q7: =+O7+P7 -> 66.78 | R7: =33.45/30*E7 -> 33.450083 | U7: =N7+Q7+R7+S7+T7 -> 573.96783 | AA7: =+W7+V7+X7+Y7+Z7 -> 0 | AB7: =+U7-AA7 -> 573.96783 | AF7: =+AB7-AC7-AD7-AE7 -> 573.96783
A8: =A7+1 -> 4 | B8: JATIVA REINA LUIS ENRIQUE | C8: =IF(L8>=401.41,401.41,IF(L8<401.41,L8)) -> 401.41 | D8: =+L8-C8 -> 195.22121 | E8: =+C8/13.3803 -> 30.000075 | F8: =+'TALLER ACTIVOS'!BF10 -> 415.95953 | G8: =+[1]TALLER!BB10 -> 0 | H8: =+'TALLER ACTIVOS'!CX10 -> 180.67168 | I8: =+[1]TALLER!CT10 -> 0 | L8: =+F8+G8+H8+I8+K8+J8 -> 596.63121 | M8: =IF(L8>=401.41,37.933,IF(L8<401.41,L8*9.45%)) -> 37.933 | N8: =+L8-M8 -> 558.69821 | O8: =IF(E8>=30,33.45,IF(E8<30,E8*1.115)) -> 33.45 | P8: =IF(E8>=30,33.33,IF(E8<30,E8*1.111)) -> 33.33 | Q8: =+O8+P8 -> 66.78 | R8: =33.45/30*E8 -> 33.450083 | U8: =N8+Q8+R8+S8+T8 -> 658.92829 | AA8: =+W8+V8+X8+Y8+Z8 -> 0 | AB8: =+U8-AA8 -> 658.92829 | AF8: =+AB8-AC8-AD8-AE8 -> 658.92829
A9: =A8+1 -> 5 | B9: FERNANDEZ RISCO ALEX BLADIMIR | C9: =IF(L9>=401.41,401.41,IF(L9<401.41,L9)) -> 401.41 | D9: =+L9-C9 -> 184.20984 | E9: =+C9/13.3803 -> 30.000075 | F9: =+'TALLER ACTIVOS'!BF11 -> 416.88156 | G9: =+[1]TALLER!BB11 -> 0 | H9: =+'TALLER ACTIVOS'!CX11 -> 168.73828 | I9: =+[1]TALLER!CT11 -> 0 | L9: =+F9+G9+H9+I9+K9+J9 -> 585.61984 | M9: =IF(L9>=401.41,37.933,IF(L9<401.41,L9*9.45%)) -> 37.933 | N9: =+L9-M9 -> 547.68684 | O9: =IF(E9>=30,33.45,IF(E9<30,E9*1.115)) -> 33.45 | P9: =IF(E9>=30,33.33,IF(E9<30,E9*1.111)) -> 33.33 | Q9: =+O9+P9 -> 66.78 | R9: =33.45/30*E9 -> 33.450083 | U9: =N9+Q9+R9+S9+T9 -> 647.91692 | AA9: =+W9+V9+X9+Y9+Z9 -> 0 | AB9: =+U9-AA9 -> 647.91692 | AF9: =+AB9-AC9-AD9-AE9 -> 647.91692
A10: =A9+1 -> 6 | B10: LOOR TONATO JESUS MANUEL | C10: =IF(L10>=401.41,401.41,IF(L10<401.41,L10)) -> 401.41 | D10: =+L10-C10 -> 131.67328 | E10: =+C10/13.3803 -> 30.000075 | F10: =+'TALLER ACTIVOS'!BF12 -> 365.44755 | G10: =+[1]TALLER!BB12 -> 0 | H10: =+'TALLER ACTIVOS'!CX12 -> 167.63573 | I10: =+[1]TALLER!CT12 -> 0 | L10: =+F10+G10+H10+I10+K10+J10 -> 533.08328 | M10: =IF(L10>=401.41,37.933,IF(L10<401.41,L10*9.45%)) -> 37.933 | N10: =+L10-M10 -> 495.15028 | O10: =IF(E10>=30,33.45,IF(E10<30,E10*1.115)) -> 33.45 | P10: =IF(E10>=30,33.33,IF(E10<30,E10*1.111)) -> 33.33 | Q10: =+O10+P10 -> 66.78 | R10: =33.45/30*E10 -> 33.450083 | U10: =N10+Q10+R10+S10+T10 -> 595.38037 | AA10: =+W10+V10+X10+Y10+Z10 -> 0 | AB10: =+U10-AA10 -> 595.38037 | AF10: =+AB10-AC10-AD10-AE10 -> 595.38037
A11: =A10+1 -> 7 | B11: HERRERA PEÑARRIETA ARIEL GABRIEL | C11: =IF(L11>=401.41,401.41,IF(L11<401.41,L11)) -> 401.41 | D11: =+L11-C11 -> 196.59178 | E11: =+C11/13.3803 -> 30.000075 | F11: =+'TALLER ACTIVOS'!BF13 -> 416.51127 | G11: =+[1]TALLER!BB13 -> 0 | H11: =+'TALLER ACTIVOS'!CX13 -> 181.49052 | I11: =+[1]TALLER!CT13 -> 0 | L11: =+F11+G11+H11+I11+K11+J11 -> 598.00178 | M11: =IF(L11>=401.41,37.933,IF(L11<401.41,L11*9.45%)) -> 37.933 | N11: =+L11-M11 -> 560.06878 | O11: =IF(E11>=30,33.45,IF(E11<30,E11*1.115)) -> 33.45 | P11: =IF(E11>=30,33.33,IF(E11<30,E11*1.111)) -> 33.33 | Q11: =+O11+P11 -> 66.78 | R11: =33.45/30*E11 -> 33.450083 | U11: =N11+Q11+R11+S11+T11 -> 660.29887 | AA11: =+W11+V11+X11+Y11+Z11 -> 0 | AB11: =+U11-AA11 -> 660.29887 | AF11: =+AB11-AC11-AD11-AE11 -> 660.29887
A12: =A11+1 -> 8 | B12: SANCHEZ TES JUAN CARLOS | C12: =IF(L12>=401.41,401.41,IF(L12<401.41,L12)) -> 401.41 | D12: =+L12-C12 -> 89.639273 | E12: =+C12/13.3803 -> 30.000075 | F12: =+'TALLER ACTIVOS'!BF14 -> 379.64569 | G12: =+[1]TALLER!BB16 -> 0 | H12: =+'TALLER ACTIVOS'!CX14 -> 111.40358 | I12: =+[1]TALLER!CT16 -> 0 | L12: =+F12+G12+H12+I12+K12+J12 -> 491.04927 | M12: =IF(L12>=401.41,37.933,IF(L12<401.41,L12*9.45%)) -> 37.933 | N12: =+L12-M12 -> 453.11627 | O12: =IF(E12>=30,33.45,IF(E12<30,E12*1.115)) -> 33.45 | P12: =IF(E12>=30,33.33,IF(E12<30,E12*1.111)) -> 33.33 | Q12: =+O12+P12 -> 66.78 | R12: =33.45/30*E12 -> 33.450083 | U12: =N12+Q12+R12+S12+T12 -> 553.34636 | AA12: =+W12+V12+X12+Y12+Z12 -> 0 | AB12: =+U12-AA12 -> 553.34636 | AF12: =+AB12-AC12-AD12-AE12 -> 553.34636
A13: =A12+1 -> 9 | B13: VERA SALDARRIAGA EDISON ADOLFO | C13: =IF(L13>=401.41,401.41,IF(L13<401.41,L13)) -> 401.41 | D13: =+L13-C13 -> 114.52123 | E13: =+C13/13.3803 -> 30.000075 | F13: =+'TALLER ACTIVOS'!BF15 -> 381.99346 | G13: =+[1]TALLER!BB19 -> 0 | H13: =+'TALLER ACTIVOS'!CX15 -> 133.93777 | I13: =+[1]TALLER!CT10 -> 0 | L13: =+F13+G13+H13+I13+K13+J13 -> 515.93123 | M13: =IF(L13>=401.41,37.933,IF(L13<401.41,L13*9.45%)) -> 37.933 | N13: =+L13-M13 -> 477.99823 | O13: =IF(E13>=30,33.45,IF(E13<30,E13*1.115)) -> 33.45 | P13: =IF(E13>=30,33.33,IF(E13<30,E13*1.111)) -> 33.33 | Q13: =+O13+P13 -> 66.78 | U13: =N13+Q13+R13+S13+T13 -> 544.77823 | AA13: =+W13+V13+X13+Y13+Z13 -> 0 | AB13: =+U13-AA13 -> 544.77823 | AF13: =+AB13-AC13-AD13-AE13 -> 544.77823
A14: DESVINCULADOS
A15: =A13+1 -> 10 | B15: CEVALLOS RODRIGUEZ EVER LEONEL | C15: =IF(L15>=401.41,401.41,IF(L15<401.41,L15)) -> 401.41 | D15: =+L15-C15 -> 99.473403 | E15: =+C15/13.3803 -> 30.000075 | F15: =+'TALLER RETIRADOS'!BF7 -> 343.44812 | G15: =+[1]TALLER!BB20 -> 0 | H15: =+'TALLER RETIRADOS'!CX7 -> 157.43529 | I15: =+[1]TALLER!CT11 -> 0 | L15: =+F15+G15+H15+I15+K15+J15 -> 500.8834 | M15: =IF(L15>=401.41,37.933,IF(L15<401.41,L15*9.45%)) -> 37.933 | N15: =+L15-M15 -> 462.9504 | O15: =IF(E15>=30,33.45,IF(E15<30,E15*1.115)) -> 33.45 | P15: =IF(E15>=30,33.33,IF(E15<30,E15*1.111)) -> 33.33 | Q15: =+O15+P15 -> 66.78 | U15: =N15+Q15+R15+S15+T15 -> 529.7304 | V15: 529.7304 | AA15: =+W15+V15+X15+Y15+Z15 -> 529.7304 | AB15: =+U15-AA15 -> 0 | AF15: =+AB15-AC15-AD15-AE15 -> 0
A16: =A15+1 -> 11 | B16: CEVALLOS RODRIGUEZ JOSE VINICIO | C16: =IF(L16>=401.41,401.41,IF(L16<401.41,L16)) -> 401.41 | D16: =+L16-C16 -> 84.43436 | E16: =+C16/13.3803 -> 30.000075 | F16: =+'TALLER RETIRADOS'!BF8 -> 351.90659 | G16: =+[1]TALLER!BB21 -> 0 | H16: =+'TALLER RETIRADOS'!CX8 -> 133.93777 | I16: =+[1]TALLER!CT12 -> 0 | L16: =+F16+G16+H16+I16+K16+J16 -> 485.84436 | M16: =IF(L16>=401.41,37.933,IF(L16<401.41,L16*9.45%)) -> 37.933 | N16: =+L16-M16 -> 447.91136 | O16: =IF(E16>=30,33.45,IF(E16<30,E16*1.115)) -> 33.45 | P16: =IF(E16>=30,33.33,IF(E16<30,E16*1.111)) -> 33.33 | Q16: =+O16+P16 -> 66.78 | U16: =N16+Q16+R16+S16+T16 -> 514.69136 | V16: 514.69136 | AA16: =+W16+V16+X16+Y16+Z16 -> 514.69136 | AB16: =+U16-AA16 -> 0 | AF16: =+AB16-AC16-AD16-AE16 -> 0
A17: =A16+1 -> 12 | B17: GARCIA VERA EGDO BRYAN | C17: =IF(L17>=401.41,401.41,IF(L17<401.41,L17)) -> 401.41 | D17: =+L17-C17 -> 96.798315 | E17: =+C17/13.3803 -> 30.000075 | F17: =+'TALLER RETIRADOS'!BF9 -> 340.77303 | G17: =+[1]TALLER!BB15 -> 0 | H17: =+'TALLER RETIRADOS'!CX9 -> 157.43529 | I17: =+[1]TALLER!CT15 -> 0 | L17: =+F17+G17+H17+I17+K17+J17 -> 498.20832 | M17: =IF(L17>=401.41,37.933,IF(L17<401.41,L17*9.45%)) -> 37.933 | N17: =+L17-M17 -> 460.27532 | O17: =IF(E17>=30,33.45,IF(E17<30,E17*1.115)) -> 33.45 | P17: =IF(E17>=30,33.33,IF(E17<30,E17*1.111)) -> 33.33 | Q17: =+O17+P17 -> 66.78 | R17: =33.45/30*E17 -> 33.450083 | U17: =N17+Q17+R17+S17+T17 -> 560.5054 | V17: 560.5054 | AA17: =+W17+V17+X17+Y17+Z17 -> 560.5054 | AB17: =+U17-AA17 -> 0 | AF17: =+AB17-AC17-AD17-AE17 -> 0
A18: =A17+1 -> 13 | B18: MENDOZA ROSADO ANTENOR ALBERTO | C18: =IF(L18>=401.41,401.41,IF(L18<401.41,L18)) -> 401.41 | D18: =+L18-C18 -> 99.223695 | E18: =+C18/13.3803 -> 30.000075 | F18: =+'TALLER RETIRADOS'!BF10 -> 339.66244 | G18: =+[1]TALLER!BB23 -> 0 | H18: =+'TALLER RETIRADOS'!CX10 -> 160.97126 | I18: =+[1]TALLER!CT16 -> 0 | L18: =+F18+G18+H18+I18+K18+J18 -> 500.63369 | M18: =IF(L18>=401.41,37.933,IF(L18<401.41,L18*9.45%)) -> 37.933 | N18: =+L18-M18 -> 462.70069 | O18: =IF(E18>=30,33.45,IF(E18<30,E18*1.115)) -> 33.45 | P18: =IF(E18>=30,33.33,IF(E18<30,E18*1.111)) -> 33.33 | Q18: =+O18+P18 -> 66.78 | R18: =33.45/30*E18 -> 33.450083 | U18: =N18+Q18+R18+S18+T18 -> 562.93078 | V18: 562.93078 | AA18: =+W18+V18+X18+Y18+Z18 -> 562.93078 | AB18: =+U18-AA18 -> 0 | AF18: =+AB18-AC18-AD18-AE18 -> 0
A19: =A18+1 -> 14 | B19: ACOSTA ZAMBRANO EFFREN EULICE | C19: =IF(L19>=401.41,401.41,IF(L19<401.41,L19)) -> 401.41 | D19: =+L19-C19 -> 182.8242 | E19: =+C19/13.3803 -> 30.000075 | F19: =+'TALLER RETIRADOS'!BF77 -> 321.34295 | G19: =+[1]TALLER!BB18 -> 0 | H19: ='TALLER RETIRADOS'!CX77+'TALLER RETIRADOS'!DC77 -> 262.89125 | I19: =+[1]TALLER!CT17 -> 0 | L19: =+F19+G19+H19+I19+K19+J19 -> 584.2342 | M19: =IF(L19>=401.41,37.933,IF(L19<401.41,L19*9.45%)) -> 37.933 | N19: =+L19-M19 -> 546.3012 | O19: =IF(E19>=30,33.45,IF(E19<30,E19*1.115)) -> 33.45 | P19: =IF(E19>=30,33.33,IF(E19<30,E19*1.111)) -> 33.33 | Q19: =+O19+P19 -> 66.78 | R19: =33.45/30*E19 -> 33.450083 | U19: =N19+Q19+R19+S19+T19 -> 646.53129 | V19: 646.53129 | AA19: =+W19+V19+X19+Y19+Z19 -> 646.53129 | AB19: =+U19-AA19 -> 0 | AF19: =+AB19-AC19-AD19-AE19 -> 0
A20: =A19+1 -> 15 | B20: ALCIVAR CEDEÑO CALIXTO PRIMITIVO | C20: =IF(L20>=401.41,401.41,IF(L20<401.41,L20)) -> 401.41 | D20: =+L20-C20 -> 189.88416 | E20: =+C20/13.3803 -> 30.000075 | F20: =+'TALLER RETIRADOS'!BF78 -> 379.64569 | G20: =+[1]TALLER!BB14 -> 0 | H20: ='TALLER RETIRADOS'!CX78+'TALLER RETIRADOS'!DC78 -> 211.64847 | I20: =+[1]TALLER!CT18 -> 0 | L20: =+F20+G20+H20+I20+K20+J20 -> 591.29416 | M20: =IF(L20>=401.41,37.933,IF(L20<401.41,L20*9.45%)) -> 37.933 | N20: =+L20-M20 -> 553.36116 | O20: =IF(E20>=30,33.45,IF(E20<30,E20*1.115)) -> 33.45 | P20: =IF(E20>=30,33.33,IF(E20<30,E20*1.111)) -> 33.33 | Q20: =+O20+P20 -> 66.78 | R20: =33.45/30*E20 -> 33.450083 | U20: =N20+Q20+R20+S20+T20 -> 653.59124 | V20: 653.59124 | AA20: =+W20+V20+X20+Y20+Z20 -> 653.59124 | AB20: =+U20-AA20 -> 0 | AF20: =+AB20-AC20-AD20-AE20 -> 0
A21: 16 | B21: CRUZATTE MUÑOZ PEDRO ANTONIO | C21: =IF(L21>=401.41,401.41,IF(L21<401.41,L21)) -> 401.41 | D21: =+L21-C21 -> 194.89029 | E21: =+C21/13.3803 -> 30.000075 | F21: =+'TALLER RETIRADOS'!BF79 -> 356.94754 | G21: =+[1]TALLER!BB22 -> 0 | H21: ='TALLER RETIRADOS'!CX79+'TALLER RETIRADOS'!DC79 -> 239.35274 | I21: =+[1]TALLER!CT19 -> 0 | L21: =+F21+G21+H21+I21+K21+J21 -> 596.30029 | M21: =IF(L21>=401.41,37.933,IF(L21<401.41,L21*9.45%)) -> 37.933 | N21: =+L21-M21 -> 558.36729 | O21: =IF(E21>=30,33.45,IF(E21<30,E21*1.115)) -> 33.45 | P21: =IF(E21>=30,33.33,IF(E21<30,E21*1.111)) -> 33.33 | Q21: =+O21+P21 -> 66.78 | R21: =33.45/30*E21 -> 33.450083 | U21: =N21+Q21+R21+S21+T21 -> 658.59737 | V21: 658.59737 | AA21: =+W21+V21+X21+Y21+Z21 -> 658.59737 | AB21: =+U21-AA21 -> 0 | AF21: =+AB21-AC21-AD21-AE21 -> 0
A22: =A21+1 -> 17 | B22: LUDEÑA MORALES SANTOS NARCISO | C22: =IF(L22>=401.41,401.41,IF(L22<401.41,L22)) -> 401.41 | D22: =+L22-C22 -> 193.01323 | E22: =+C22/13.3803 -> 30.000075 | F22: =+'TALLER RETIRADOS'!BF80 -> 377.90637 | G22: =+[1]TALLER!BB17 -> 0 | H22: ='TALLER RETIRADOS'!CX80+'TALLER RETIRADOS'!DC80 -> 216.51687 | I22: =+[1]TALLER!CT20 -> 0 | L22: =+F22+G22+H22+I22+K22+J22 -> 594.42323 | M22: =IF(L22>=401.41,37.933,IF(L22<401.41,L22*9.45%)) -> 37.933 | N22: =+L22-M22 -> 556.49023 | O22: =IF(E22>=30,33.45,IF(E22<30,E22*1.115)) -> 33.45 | P22: =IF(E22>=30,33.33,IF(E22<30,E22*1.111)) -> 33.33 | Q22: =+O22+P22 -> 66.78 | R22: =33.45/30*E22 -> 33.450083 | U22: =N22+Q22+R22+S22+T22 -> 656.72032 | V22: 656.72032 | AA22: =+W22+V22+X22+Y22+Z22 -> 656.72032 | AB22: =+U22-AA22 -> 0 | AF22: =+AB22-AC22-AD22-AE22 -> 0
A23: ÀREA DE SIERRA DE MESA O CANTEADORA
A24: =A22+1 -> 18 | B24: PACHECO MONTOYA JENIFFER KATHERINE | C24: =IF(L24>=401.41,401.41,IF(L24<401.41,L24)) -> 401.41 | D24: =+L24-C24 -> 98.617095 | E24: =+C24/13.3803 -> 30.000075 | F24: =+'TALLER ACTIVOS'!BF19 -> 326.43248 | G24: 0 | H24: =+'TALLER ACTIVOS'!CX19 -> 173.59461 | I24: 0 | L24: =+F24+G24+H24+I24+K24+J24 -> 500.0271 | M24: =IF(L24>=401.41,37.933,IF(L24<401.41,L24*9.45%)) -> 37.933 | N24: =+L24-M24 -> 462.0941 | O24: =IF(E24>=30,33.45,IF(E24<30,E24*1.115)) -> 33.45 | P24: =IF(E24>=30,33.33,IF(E24<30,E24*1.111)) -> 33.33 | Q24: =+O24+P24 -> 66.78 | U24: =N24+Q24+R24+S24+T24 -> 528.8741 | AA24: =+W24+V24+X24+Y24+Z24 -> 0 | AB24: =+U24-AA24 -> 528.8741 | AF24: =+AB24-AC24-AD24-AE24 -> 528.8741
A25: =A24+1 -> 19 | B25: RUIZ MAYOR ENRIQUE GABRIEL | C25: =IF(L25>=401.41,401.41,IF(L25<401.41,L25)) -> 401.41 | D25: =+L25-C25 -> 38.893759 | E25: =+C25/13.3803 -> 30.000075 | F25: =+'TALLER ACTIVOS'!BF20 -> 314 | G25: 0 | H25: =+'TALLER ACTIVOS'!CX20 -> 126.30376 | I25: 0 | L25: =+F25+G25+H25+I25+K25+J25 -> 440.30376 | M25: =IF(L25>=401.41,37.933,IF(L25<401.41,L25*9.45%)) -> 37.933 | N25: =+L25-M25 -> 402.37076 | O25: =IF(E25>=30,33.45,IF(E25<30,E25*1.115)) -> 33.45 | P25: =IF(E25>=30,33.33,IF(E25<30,E25*1.111)) -> 33.33 | Q25: =+O25+P25 -> 66.78 | U25: =N25+Q25+R25+S25+T25 -> 469.15076 | Z25: 77.04 | AA25: =+W25+V25+X25+Y25+Z25 -> 77.04 | AB25: =+U25-AA25 -> 392.11076 | AF25: =+AB25-AC25-AD25-AE25 -> 392.11076
A26: =A25+1 -> 20 | B26: VALENCIA ORTEGA JORGE LUIS | C26: =IF(L26>=401.41,401.41,IF(L26<401.41,L26)) -> 401.41 | D26: =+L26-C26 -> 117.66716 | E26: =+C26/13.3803 -> 30.000075 | F26: =+'TALLER ACTIVOS'!BF21 -> 314 | G26: 0 | H26: =+'TALLER ACTIVOS'!CX21 -> 205.07716 | I26: 0 | L26: =+F26+G26+H26+I26+K26+J26 -> 519.07716 | M26: =IF(L26>=401.41,37.933,IF(L26<401.41,L26*9.45%)) -> 37.933 | N26: =+L26-M26 -> 481.14416 | O26: =IF(E26>=30,33.45,IF(E26<30,E26*1.115)) -> 33.45 | P26: =IF(E26>=30,33.33,IF(E26<30,E26*1.111)) -> 33.33 | Q26: =+O26+P26 -> 66.78 | R26: =33.45/30*E26 -> 33.450083 | U26: =N26+Q26+R26+S26+T26 -> 581.37425 | AA26: =+W26+V26+X26+Y26+Z26 -> 0 | AB26: =+U26-AA26 -> 581.37425 | AF26: =+AB26-AC26-AD26-AE26 -> 581.37425
A27: =A26+1 -> 21 | B27: BARREIRO VELEZ CRISTHIAN GEOVANNY | C27: =IF(L27>=401.41,401.41,IF(L27<401.41,L27)) -> 401.41 | D27: =+L27-C27 -> 234.11507 | E27: =+C27/13.3803 -> 30.000075 | F27: =+'TALLER ACTIVOS'!BF22 -> 402.90766 | G27: 0 | H27: =+'TALLER ACTIVOS'!CX22 -> 232.61741 | I27: 0 | L27: =+F27+G27+H27+I27+K27+J27 -> 635.52507 | M27: =IF(L27>=401.41,37.933,IF(L27<401.41,L27*9.45%)) -> 37.933 | N27: =+L27-M27 -> 597.59207 | O27: =IF(E27>=30,33.45,IF(E27<30,E27*1.115)) -> 33.45 | P27: =IF(E27>=30,33.33,IF(E27<30,E27*1.111)) -> 33.33 | Q27: =+O27+P27 -> 66.78 | R27: =33.45/30*E27 -> 33.450083 | U27: =N27+Q27+R27+S27+T27 -> 697.82215 | AA27: =+W27+V27+X27+Y27+Z27 -> 0 | AB27: =+U27-AA27 -> 697.82215 | AF27: =+AB27-AC27-AD27-AE27 -> 697.82215
A28: =A27+1 -> 22 | B28: ZAMBRANO VARGAS YORDI EMEREGILDO | C28: =IF(L28>=401.41,401.41,IF(L28<401.41,L28)) -> 401.41 | D28: =+L28-C28 -> 199.59194 | E28: =+C28/13.3803 -> 30.000075 | F28: =+'TALLER ACTIVOS'!BF23 -> 394.18846 | G28: 0 | H28: =+'TALLER ACTIVOS'!CX23 -> 206.81348 | I28: 0 | L28: =+F28+G28+H28+I28+K28+J28 -> 601.00194 | M28: =IF(L28>=401.41,37.933,IF(L28<401.41,L28*9.45%)) -> 37.933 | N28: =+L28-M28 -> 563.06894 | O28: =IF(E28>=30,33.45,IF(E28<30,E28*1.115)) -> 33.45 | P28: =IF(E28>=30,33.33,IF(E28<30,E28*1.111)) -> 33.33 | Q28: =+O28+P28 -> 66.78 | R28: =33.45/30*E28 -> 33.450083 | U28: =N28+Q28+R28+S28+T28 -> 663.29902 | AA28: =+W28+V28+X28+Y28+Z28 -> 0 | AB28: =+U28-AA28 -> 663.29902 | AF28: =+AB28-AC28-AD28-AE28 -> 663.29902
A29: =A28+1 -> 23 | B29: ZAMBRANO ROSADO SOFIA LUCIOLA | C29: =IF(L29>=401.41,401.41,IF(L29<401.41,L29)) -> 401.41 | D29: =+L29-C29 -> 308.66551 | E29: =+C29/13.3803 -> 30.000075 | F29: =+'TALLER ACTIVOS'!BF24 -> 432.73997 | G29: 0 | H29: =+'TALLER ACTIVOS'!CX24 -> 277.33554 | I29: 0 | L29: =+F29+G29+H29+I29+K29+J29 -> 710.07551 | M29: =IF(L29>=401.41,37.933,IF(L29<401.41,L29*9.45%)) -> 37.933 | N29: =+L29-M29 -> 672.14251 | O29: =IF(E29>=30,33.45,IF(E29<30,E29*1.115)) -> 33.45 | P29: =IF(E29>=30,33.33,IF(E29<30,E29*1.111)) -> 33.33 | Q29: =+O29+P29 -> 66.78 | U29: =N29+Q29+R29+S29+T29 -> 738.92251 | AA29: =+W29+V29+X29+Y29+Z29 -> 0 | AB29: =+U29-AA29 -> 738.92251 | AF29: =+AB29-AC29-AD29-AE29 -> 738.92251
A30: =A29+1 -> 24 | B30: MANZABA BRAVO LIDER ANTONIO | C30: =IF(L30>=401.41,401.41,IF(L30<401.41,L30)) -> 401.41 | D30: =+L30-C30 -> 14.641908 | E30: =+C30/13.3803 -> 30.000075 | F30: =+'TALLER ACTIVOS'!BF25 -> 260 | G30: 0 | H30: =+'TALLER ACTIVOS'!CX25 -> 156.05191 | I30: 0 | L30: =+F30+G30+H30+I30+K30+J30 -> 416.05191 | M30: =IF(L30>=401.41,37.933,IF(L30<401.41,L30*9.45%)) -> 37.933 | N30: =+L30-M30 -> 378.11891 | O30: =IF(E30>=30,33.45,IF(E30<30,E30*1.115)) -> 33.45 | P30: =IF(E30>=30,33.33,IF(E30<30,E30*1.111)) -> 33.33 | Q30: =+O30+P30 -> 66.78 | R30: =33.45/30*E30 -> 33.450083 | U30: =N30+Q30+R30+S30+T30 -> 478.34899 | AA30: =+W30+V30+X30+Y30+Z30 -> 0 | AB30: =+U30-AA30 -> 478.34899 | AF30: =+AB30-AC30-AD30-AE30 -> 478.34899
A31: =A30+1 -> 25 | B31: BAZURTO PARRAGA JUBER JAIR | C31: =IF(L31>=401.41,401.41,IF(L31<401.41,L31)) -> 401.41 | D31: =+L31-C31 -> 209.93919 | E31: =+C31/13.3803 -> 30.000075 | F31: =+'TALLER ACTIVOS'!BF26 -> 475.7927 | G31: 0 | H31: =+'TALLER ACTIVOS'!CX26 -> 135.55649 | I31: 0 | L31: =+F31+G31+H31+I31+K31+J31 -> 611.34919 | M31: =IF(L31>=401.41,37.933,IF(L31<401.41,L31*9.45%)) -> 37.933 | N31: =+L31-M31 -> 573.41619 | O31: =IF(E31>=30,33.45,IF(E31<30,E31*1.115)) -> 33.45 | P31: =IF(E31>=30,33.33,IF(E31<30,E31*1.111)) -> 33.33 | Q31: =+O31+P31 -> 66.78 | R31: =33.45/30*E31 -> 33.450083 | U31: =N31+Q31+R31+S31+T31 -> 673.64627 | AA31: =+W31+V31+X31+Y31+Z31 -> 0 | AB31: =+U31-AA31 -> 673.64627 | AF31: =+AB31-AC31-AD31-AE31 -> 673.64627
A32: =A31+1 -> 26 | B32: VIVAS MACIAS LISBETH ALEXANDRA | C32: =IF(L32>=401.41,401.41,IF(L32<401.41,L32)) -> 401.41 | D32: =+L32-C32 -> 39.693156 | E32: =+C32/13.3803 -> 30.000075 | F32: =+'TALLER ACTIVOS'!BF27 -> 348.27059 | G32: 0 | H32: =+'TALLER ACTIVOS'!CX27 -> 92.832563 | I32: 0 | L32: =+F32+G32+H32+I32+K32+J32 -> 441.10316 | M32: =IF(L32>=401.41,37.933,IF(L32<401.41,L32*9.45%)) -> 37.933 | N32: =+L32-M32 -> 403.17016 | O32: =IF(E32>=30,33.45,IF(E32<30,E32*1.115)) -> 33.45 | P32: =IF(E32>=30,33.33,IF(E32<30,E32*1.111)) -> 33.33 | Q32: =+O32+P32 -> 66.78 | R32: =33.45/30*E32 -> 33.450083 | U32: =N32+Q32+R32+S32+T32 -> 503.40024 | AA32: =+W32+V32+X32+Y32+Z32 -> 0 | AB32: =+U32-AA32 -> 503.40024 | AF32: =+AB32-AC32-AD32-AE32 -> 503.40024
A33: =A32+1 -> 27 | B33: PILOSO MANZABA YORGEN JAVIER | C33: =IF(L33>=401.41,401.41,IF(L33<401.41,L33)) -> 401.41 | D33: =+L33-C33 -> 187.09408 | E33: =+C33/13.3803 -> 30.000075 | F33: =+'TALLER ACTIVOS'!BF28 -> 375.49479 | G33: 0 | H33: =+'TALLER ACTIVOS'!CX28 -> 213.00929 | I33: 0 | L33: =+F33+G33+H33+I33+K33+J33 -> 588.50408 | M33: =IF(L33>=401.41,37.933,IF(L33<401.41,L33*9.45%)) -> 37.933 | N33: =+L33-M33 -> 550.57108 | O33: =IF(E33>=30,33.45,IF(E33<30,E33*1.115)) -> 33.45 | P33: =IF(E33>=30,33.33,IF(E33<30,E33*1.111)) -> 33.33 | Q33: =+O33+P33 -> 66.78 | R33: =33.45/30*E33 -> 33.450083 | U33: =N33+Q33+R33+S33+T33 -> 650.80116 | Z33: 49.87 | AA33: =+W33+V33+X33+Y33+Z33 -> 49.87 | AB33: =+U33-AA33 -> 600.93116 | AF33: =+AB33-AC33-AD33-AE33 -> 600.93116
A34: =A33+1 -> 28 | B34: ALVARADO MACIAS KAREN ELIZABETH | C34: =IF(L34>=401.41,401.41,IF(L34<401.41,L34)) -> 401.41 | D34: =+L34-C34 -> 101.13433 | E34: =+C34/13.3803 -> 30.000075 | F34: =+'TALLER ACTIVOS'!BF29 -> 254.63615 | G34: 0 | H34: =+'TALLER ACTIVOS'!CX29 -> 227.83818 | I34: 0 | J34: =13.38*3*50% -> 20.07 | L34: =+F34+G34+H34+I34+K34+J34 -> 502.54433 | M34: =IF(L34>=401.41,37.933,IF(L34<401.41,L34*9.45%)) -> 37.933 | N34: =+L34-M34 -> 464.61133 | O34: =IF(E34>=30,33.45,IF(E34<30,E34*1.115)) -> 33.45 | P34: =IF(E34>=30,33.33,IF(E34<30,E34*1.111)) -> 33.33 | Q34: =+O34+P34 -> 66.78 | R34: =33.45/30*E34 -> 33.450083 | U34: =N34+Q34+R34+S34+T34 -> 564.84141 | Z34: 23.36 | AA34: =+W34+V34+X34+Y34+Z34 -> 23.36 | AB34: =+U34-AA34 -> 541.48141 | AF34: =+AB34-AC34-AD34-AE34 -> 541.48141
A35: =A34+1 -> 29 | B35: NAVARRETE ALCIVAR BYRON ANDRES | C35: =IF(L35>=401.41,401.41,IF(L35<401.41,L35)) -> 401.41 | D35: =+L35-C35 -> 233.21661 | E35: =+C35/13.3803 -> 30.000075 | F35: =+'TALLER ACTIVOS'!BF30 -> 403.39775 | G35: 0 | H35: =+'TALLER ACTIVOS'!CX30 -> 231.22886 | I35: 0 | L35: =+F35+G35+H35+I35+K35+J35 -> 634.62661 | M35: =IF(L35>=401.41,37.933,IF(L35<401.41,L35*9.45%)) -> 37.933 | N35: =+L35-M35 -> 596.69361 | O35: =IF(E35>=30,33.45,IF(E35<30,E35*1.115)) -> 33.45 | P35: =IF(E35>=30,33.33,IF(E35<30,E35*1.111)) -> 33.33 | Q35: =+O35+P35 -> 66.78 | R35: =33.45/30*E35 -> 33.450083 | U35: =N35+Q35+R35+S35+T35 -> 696.9237 | AA35: =+W35+V35+X35+Y35+Z35 -> 0 | AB35: =+U35-AA35 -> 696.9237 | AF35: =+AB35-AC35-AD35-AE35 -> 696.9237
A36: =A35+1 -> 30 | B36: CHICA VERA STEVEN MANUEL | C36: =IF(L36>=401.41,401.41,IF(L36<401.41,L36)) -> 401.41 | D36: =+L36-C36 -> 148.01726 | E36: =+C36/13.3803 -> 30.000075 | F36: =+'TALLER ACTIVOS'!BF31 -> 375.76191 | G36: 0 | H36: =+'TALLER ACTIVOS'!CX31 -> 173.66535 | I36: 0 | L36: =+F36+G36+H36+I36+K36+J36 -> 549.42726 | M36: =IF(L36>=401.41,37.933,IF(L36<401.41,L36*9.45%)) -> 37.933 | N36: =+L36-M36 -> 511.49426 | O36: =IF(E36>=30,33.45,IF(E36<30,E36*1.115)) -> 33.45 | P36: =IF(E36>=30,33.33,IF(E36<30,E36*1.111)) -> 33.33 | Q36: =+O36+P36 -> 66.78 | R36: =33.45/30*E36 -> 33.450083 | U36: =N36+Q36+R36+S36+T36 -> 611.72434 | AA36: =+W36+V36+X36+Y36+Z36 -> 0 | AB36: =+U36-AA36 -> 611.72434 | AF36: =+AB36-AC36-AD36-AE36 -> 611.72434
A37: =A36+1 -> 31 | B37: RAMOS CACIQUE MARIA BEATRIZ | C37: =IF(L37>=401.41,401.41,IF(L37<401.41,L37)) -> 401.41 | D37: =+L37-C37 -> 216.13334 | E37: =+C37/13.3803 -> 30.000075 | F37: =+'TALLER ACTIVOS'!BF32 -> 388.28166 | G37: 0 | H37: =+'TALLER ACTIVOS'!CX32 -> 229.26168 | I37: 0 | L37: =+F37+G37+H37+I37+K37+J37 -> 617.54334 | M37: =IF(L37>=401.41,37.933,IF(L37<401.41,L37*9.45%)) -> 37.933 | N37: =+L37-M37 -> 579.61034 | O37: =IF(E37>=30,33.45,IF(E37<30,E37*1.115)) -> 33.45 | P37: =IF(E37>=30,33.33,IF(E37<30,E37*1.111)) -> 33.33 | Q37: =+O37+P37 -> 66.78 | R37: =33.45/30*E37 -> 33.450083 | U37: =N37+Q37+R37+S37+T37 -> 679.84042 | AA37: =+W37+V37+X37+Y37+Z37 -> 0 | AB37: =+U37-AA37 -> 679.84042 | AF37: =+AB37-AC37-AD37-AE37 -> 679.84042
A38: =A37+1 -> 32 | B38: CEDEÑO MUÑOZ HEINER JESUS | C38: =IF(L38>=401.41,401.41,IF(L38<401.41,L38)) -> 401.41 | D38: =+L38-C38 -> 224.01726 | E38: =+C38/13.3803 -> 30.000075 | F38: =+'TALLER ACTIVOS'!BF33 -> 375.76191 | G38: 0 | H38: =+'TALLER ACTIVOS'!CX33 -> 249.66535 | I38: 0 | L38: =+F38+G38+H38+I38+K38+J38 -> 625.42726 | M38: =IF(L38>=401.41,37.933,IF(L38<401.41,L38*9.45%)) -> 37.933 | N38: =+L38-M38 -> 587.49426 | O38: =IF(E38>=30,33.45,IF(E38<30,E38*1.115)) -> 33.45 | P38: =IF(E38>=30,33.33,IF(E38<30,E38*1.111)) -> 33.33 | Q38: =+O38+P38 -> 66.78 | R38: =33.45/30*E38 -> 33.450083 | U38: =N38+Q38+R38+S38+T38 -> 687.72434 | AA38: =+W38+V38+X38+Y38+Z38 -> 0 | AB38: =+U38-AA38 -> 687.72434 | AF38: =+AB38-AC38-AD38-AE38 -> 687.72434
A39: =A38+1 -> 33 | B39: SOLORZANO INTRIAGO JUAN CARLOS | C39: =IF(L39>=401.41,401.41,IF(L39<401.41,L39)) -> 401.41 | D39: =+L39-C39 -> 179.83008 | E39: =+C39/13.3803 -> 30.000075 | F39: =+'TALLER ACTIVOS'!BF34 -> 396.16583 | G39: 0 | H39: =+'TALLER ACTIVOS'!CX34 -> 185.07425 | I39: 0 | L39: =+F39+G39+H39+I39+K39+J39 -> 581.24008 | M39: =IF(L39>=401.41,37.933,IF(L39<401.41,L39*9.45%)) -> 37.933 | N39: =+L39-M39 -> 543.30708 | O39: =IF(E39>=30,33.45,IF(E39<30,E39*1.115)) -> 33.45 | P39: =IF(E39>=30,33.33,IF(E39<30,E39*1.111)) -> 33.33 | Q39: =+O39+P39 -> 66.78 | U39: =N39+Q39+R39+S39+T39 -> 610.08708 | AA39: =+W39+V39+X39+Y39+Z39 -> 0 | AB39: =+U39-AA39 -> 610.08708 | AF39: =+AB39-AC39-AD39-AE39 -> 610.08708
A40: =A39+1 -> 34 | B40: BRAVO LUCAS YANINE MARIUXI | C40: =IF(L40>=401.41,401.41,IF(L40<401.41,L40)) -> 401.41 | D40: =+L40-C40 -> 236.82253 | E40: =+C40/13.3803 -> 30.000075 | F40: =+'TALLER ACTIVOS'!BF35 -> 399.56864 | G40: 0 | H40: =+'TALLER ACTIVOS'!CX35 -> 238.6639 | I40: 0 | L40: =+F40+G40+H40+I40+K40+J40 -> 638.23253 | M40: =IF(L40>=401.41,37.933,IF(L40<401.41,L40*9.45%)) -> 37.933 | N40: =+L40-M40 -> 600.29953 | O40: =IF(E40>=30,33.45,IF(E40<30,E40*1.115)) -> 33.45 | P40: =IF(E40>=30,33.33,IF(E40<30,E40*1.111)) -> 33.33 | Q40: =+O40+P40 -> 66.78 | U40: =N40+Q40+R40+S40+T40 -> 667.07953 | Z40: 57.98 | AA40: =+W40+V40+X40+Y40+Z40 -> 57.98 | AB40: =+U40-AA40 -> 609.09953 | AF40: =+AB40-AC40-AD40-AE40 -> 609.09953
A41: =A40+1 -> 35 | B41: ANDRADE ZAMBRANO JESUS DANIEL | C41: =IF(L41>=401.41,401.41,IF(L41<401.41,L41)) -> 401.41 | D41: =+L41-C41 -> 293.37866 | E41: =+C41/13.3803 -> 30.000075 | F41: =+'TALLER ACTIVOS'!BF36 -> 462.37439 | G41: 0 | H41: =+'TALLER ACTIVOS'!CX36 -> 232.41427 | I41: 0 | L41: =+F41+G41+H41+I41+K41+J41 -> 694.78866 | M41: =IF(L41>=401.41,37.933,IF(L41<401.41,L41*9.45%)) -> 37.933 | N41: =+L41-M41 -> 656.85566 | O41: =IF(E41>=30,33.45,IF(E41<30,E41*1.115)) -> 33.45 | P41: =IF(E41>=30,33.33,IF(E41<30,E41*1.111)) -> 33.33 | Q41: =+O41+P41 -> 66.78 | U41: =N41+Q41+R41+S41+T41 -> 723.63566 | AA41: =+W41+V41+X41+Y41+Z41 -> 0 | AB41: =+U41-AA41 -> 723.63566 | AF41: =+AB41-AC41-AD41-AE41 -> 723.63566
...

Sheet TALLER ACTIVOS
A1: MANTELLOD S.A | BB1: 1RA QUINCENA JUNIO | CT1: 2DA QUINCENA JUNIO | CY1: MES DE JUNIO
A5: Nº | B5: PERSONAL DE PENDULA | C5: Nº DE GRUPOS | D5: # CELULAR | E5: CORREO | F5: MIERCOLES 26-05-2021 | I5: JUEVES 27-05-2021 | L5: VIERNES 28-05-2021 | O5: SABADO 29-05-2021 | R5: LUNES 31-05-2021 | U5: MARTES 01-06-2021 | X5: MIERCOLES 02-06-2021 | AA5: JUEVES 03-06-2021 | AD5: VIERNES 04-06-2021 | AG5: SABADO 05-06-2021 | AJ5: LUNES 07-05-2021 | AM5: MARTES 08-06-2021 | AP5: MIERCOLES 09-06-2021 | AS5: JUEVES 10-06-2021 | BB5: TOTAL BFT QUINCENA | BC5: $ POR AVANCE | BD5: $ AL DIARIO | BE5: MULTA | BF5: VALOR TOTAL QUINCENA | BG5: VIERNES 11-06-2021 | BJ5: SABADO 12-06-2021 | BM5: LUNES 14-06-2021 | BP5: MARTES 15-06-2021 | BS5: MIERCOLES 16-06-2021 | BV5: JUEVES 17-06-2021 | BY5: VIERNES 18-06-2021 | CB5: SABADO 19-06-2021 | CE5: LUNES 21-06-2021 | CH5: MARTES 22-06-2021 | CK5: MIERCOLES 23-06-2021 | CN5: JUEVES 24-06-2021 | CQ5: VIERNES 25-06-2021 | CT5: TOTAL BFT QUINCENA | CU5: $ POR AVANCE | CV5: $ AL DIARIO | CW5: MULTA | CX5: VALOR TOTAL QUINCENA | CY5: TOTAL BFT | CZ5: $ POR AVANCE | DA5: $ AL DIARIO | DB5: TOTAL A PAGAR
F6: BTF | G6: $ | H6: TRABAJOS DIARIO | I6: BTF | J6: $ | K6: TRABAJOS DIARIO | L6: BTF | M6: $ | N6: TRABAJOS DIARIO | O6: BTF | P6: $ | Q6: TRABAJOS DIARIO | R6: BTF | S6: $ | T6: TRABAJOS DIARIO | U6: BTF | V6: $ | W6: TRABAJOS DIARIO | X6: BTF | Y6: $ | Z6: TRABAJOS DIARIO | AA6: BTF | AB6: $ | AC6: TRABAJOS DIARIO | AD6: BTF | AE6: $ | AF6: TRABAJOS DIARIO | AG6: BTF | AH6: $ | AI6: TRABAJOS DIARIO | AJ6: BTF | AK6: $ | AL6: TRABAJOS DIARIO | AM6: BTF | AN6: $ | AO6: TRABAJOS DIARIO | AP6: BTF | AQ6: $ | AR6: TRABAJOS DIARIO | AS6: BTF | AT6: $ | AU6: TRABAJOS DIARIO | AV6: BTF | AW6: $ | AX6: TRABAJOS DIARIO | AY6: BTF | AZ6: $ | BA6: TRABAJOS DIARIO | BG6: BTF | BH6: $ | BI6: TRABAJOS DIARIO | BJ6: BTF | BK6: $ | BL6: TRABAJOS DIARIO | BM6: BTF | BN6: $ | BO6: TRABAJOS DIARIO | BP6: BTF | BQ6: $ | BR6: TRABAJOS DIARIO | BS6: BTF | BT6: $ | BU6: TRABAJOS DIARIO | BV6: BTF | BW6: $ | BX6: TRABAJOS DIARIO | BY6: BTF | BZ6: $ | CA6: TRABAJOS DIARIO | CB6: BTF | CC6: $ | CD6: TRABAJOS DIARIO | CE6: BTF | CF6: $ | CG6: TRABAJOS DIARIO | CH6: BTF | CI6: $ | CJ6: TRABAJOS DIARIO | CK6: BTF | CL6: $ | CM6: TRABAJOS DIARIO | CN6: BTF | CO6: $ | CP6: TRABAJOS DIARIO | CQ6: BTF | CR6: $ | CS6: TRABAJOS DIARIO
A7: 1 | B7: BAQUE MERO ROBERTH DANIEL | C7: PENDULA 1 | F7: 11378.37 | G7: =+F7*0.0035 -> 39.824295 | I7: 9683.62 | J7: =+I7*0.0035 -> 33.89267 | L7: 15254 | M7: =+L7*0.0035 -> 53.389 | O7: 0 | P7: =+O7*0.0035 -> 0 | R7: 10997.34 | S7: =+R7*0.0035 -> 38.49069 | U7: 8380.25 | V7: =+U7*0.0035 -> 29.330875 | X7: 6018.95 | Y7: =+X7*0.0035 -> 21.066325 | AA7: 7872.55 | AB7: =+AA7*0.0035 -> 27.553925 | AD7: 15764.41 | AE7: =+AD7*0.0035 -> 55.175435 | AG7: 0 | AH7: =+AG7*0.0035 -> 0 | AJ7: 11545.34 | AK7: =+AJ7*0.0035 -> 40.40869 | AM7: 0 | AN7: =+AM7*0.0035 -> 0 | AO7: 20 | AP7: 0 | AQ7: =+AP7*0.0035 -> 0 | AS7: 13201.08 | AT7: =+AS7*0.0035 -> 46.20378 | AW7: =+AV7*0.0035 -> 0 | AZ7: =+AY7*0.0035 -> 0 | BB7: =+F7+I7+L7+O7+R7+U7+X7+AA7+AD7+AG7+AJ7+AM7+AP7+AS7+AV7+AY7 -> 110095.91 | BC7: =+G7+J7+M7+P7+S7+V7+Y7+AB7+AE7+AH7+AK7+AN7+AQ7+AT7+AW7+AZ7 -> 385.33568 | BD7: =+H7+K7+N7+Q7+T7+W7+Z7+AC7+AF7+AI7+AL7+AO7+AR7+AU7+AX7+BA7 -> 20 | BF7: =+BC7+BD7-BE7 -> 405.33568 | BG7: 5590.75 | BH7: =+BG7*0.0035 -> 19.567625 | BJ7: 0 | BK7: =+BJ7*0.0035 -> 0 | BM7: 7777.15 | BN7: =+BM7*0.0035 -> 27.220025 | BP7: 7895.73 | BQ7: =+BP7*0.0035 -> 27.635055 | BS7: 0 | BT7: =+BS7*0.0035 -> 0 | BV7: 6079.55 | BW7: =+BV7*0.0035 -> 21.278425 | BY7: 0 | BZ7: =+BY7*0.0035 -> 0 | CB7: 0 | CC7: =+CB7*0.0035 -> 0 | CE7: 8627.51 | CF7: =+CE7*0.0035 -> 30.196285 | CH7: 0 | CI7: =+CH7*0.0035 -> 0 | CK7: 0 | CL7: =+CK7*0.0035 -> 0 | CN7: 0 | CO7: =+CN7*0.0035 -> 0 | CQ7: 0 | CR7: =+CQ7*0.0035 -> 0 | CT7: =BG7+BJ7+BM7+BP7+BS7+BV7+BY7+CB7+CH7+CK7+CN7+CQ7+CE7 -> 35970.69 | CU7: =BH7+BK7+BN7+BQ7+BT7+BW7+BZ7+CC7+CI7+CL7+CO7+CR7+CF7 -> 125.89741 | CV7: =+BI7+BL7+BO7+BR7+BU7+BX7+CA7+CD7+CG7+CJ7+CM7+CP7+CS7 -> 0 | CX7: =+CU7+CV7-CW7 -> 125.89741 | CY7: =+BB7+CT7 -> 146066.6 | CZ7: =+BC7+CU7 -> 511.2331 | DA7: =+BD7+CV7 -> 20 | DB7: =+CZ7+DA7 -> 531.2331
A8: =+A7+1 -> 2 | B8: RISCO ZAMBRANO JEFFERSON CECILIO | C8: PENDULA 1 | F8: 0 | G8: =+F8*0.0035 -> 0 | H8: 20 | I8: 10491.62 | J8: =+I8*0.0035 -> 36.72067 | L8: 13725 | M8: =+L8*0.0035 -> 48.0375 | O8: 0 | P8: =+O8*0.0035 -> 0 | R8: 10269.35 | S8: =+R8*0.0035 -> 35.942725 | U8: 7115.23 | V8: =+U8*0.0035 -> 24.903305 | X8: 5956.95 | Y8: =+X8*0.0035 -> 20.849325 | AA8: 0 | AB8: =+AA8*0.0035 -> 0 | AC8: 20 | AD8: 15942.41 | AE8: =+AD8*0.0035 -> 55.798435 | AG8: 0 | AH8: =+AG8*0.0035 -> 0 | AJ8: 10588.34 | AK8: =+AJ8*0.0035 -> 37.05919 | AM8: 9423.54 | AN8: =+AM8*0.0035 -> 32.98239 | AP8: 0 | AQ8: =+AP8*0.0035 -> 0 | AS8: 14840.08 | AT8: =+AS8*0.0035 -> 51.94028 | AW8: =+AV8*0.0035 -> 0 | AZ8: =+AY8*0.0035 -> 0 | BB8: =+F8+I8+L8+O8+R8+U8+X8+AA8+AD8+AG8+AJ8+AM8+AP8+AS8+AV8+AY8 -> 98352.52 | BC8: =+G8+J8+M8+P8+S8+V8+Y8+AB8+AE8+AH8+AK8+AN8+AQ8+AT8+AW8+AZ8 -> 344.23382 | BD8: =+H8+K8+N8+Q8+T8+W8+Z8+AC8+AF8+AI8+AL8+AO8+AR8+AU8+AX8+BA8 -> 40 | BF8: =+BC8+BD8-BE8 -> 384.23382 | BG8: 5590.77 | BH8: =+BG8*0.0035 -> 19.567695 | BJ8: 0 | BK8: =+BJ8*0.0035 -> 0 | BM8: 37108.31 | BN8: =+BM8*0.02/29 -> 25.591938 | BP8: 8347.73 | BQ8: =+BP8*0.0035 -> 29.217055 | BS8: 3309.84 | BT8: =+BS8*0.0035 -> 11.58444 | BV8: 6969.55 | BW8: =+BV8*0.0035 -> 24.393425 | BY8: 1931.09 | BZ8: =+BY8*0.0035 -> 6.758815 | CB8: 0 | CC8: =+CB8*0.0035 -> 0 | CE8: 0 | CF8: =+CE8*0.0035 -> 0 | CH8: 0 | CI8: =+CH8*0.0035 -> 0 | CK8: 0 | CL8: =+CK8*0.0035 -> 0 | CN8: 0 | CO8: =+CN8*0.0035 -> 0 | CQ8: 0 | CR8: =+CQ8*0.0035 -> 0 | CT8: =BG8+BJ8+BM8+BP8+BS8+BV8+BY8+CB8+CH8+CK8+CN8+CQ8+CE8 -> 63257.29 | CU8: =BH8+BK8+BN8+BQ8+BT8+BW8+BZ8+CC8+CI8+CL8+CO8+CR8+CF8 -> 117.11337 | CV8: =+BI8+BL8+BO8+BR8+BU8+BX8+CA8+CD8+CG8+CJ8+CM8+CP8+CS8 -> 0 | CX8: =+CU8+CV8-CW8 -> 117.11337 | CY8: =+BB8+CT8 -> 161609.81 | CZ8: =+BC8+CU8 -> 461.34719 | DA8: =+BD8+CV8 -> 40 | DB8: =+CZ8+DA8 -> 501.34719
A9: =+A8+1 -> 3 | B9: CHANALATA TONATO CESAR AUGUSTO | C9: PENDULA 1 | D9: 0988142911 | E9: cesarchanalata@gmail.com | F9: 10422.37 | G9: =+F9*0.0035 -> 36.478295 | I9: 8366.63 | J9: =+I9*0.0035 -> 29.283205 | L9: 13995 | M9: =+L9*0.0035 -> 48.9825 | O9: 0 | P9: =+O9*0.0035 -> 0 | R9: 9084.34 | S9: =+R9*0.0035 -> 31.79519 | U9: 0 | V9: =+U9*0.0035 -> 0 | W9: 20 | X9: 0 | Y9: =+X9*0.0035 -> 0 | Z9: 20 | AA9: 6716.55 | AB9: =+AA9*0.0035 -> 23.507925 | AD9: 14893.41 | AE9: =+AD9*0.0035 -> 52.126935 | AG9: 0 | AH9: =+AG9*0.0035 -> 0 | AJ9: 10850.34 | AK9: =+AJ9*0.0035 -> 37.97619 | AM9: 8256.54 | AN9: =+AM9*0.0035 -> 28.89789 | AP9: 0 | AQ9: =+AP9*0.0035 -> 0 | AS9: 13386.08 | AT9: =+AS9*0.0035 -> 46.85128 | AW9: =+AV9*0.0035 -> 0 | AZ9: =+AY9*0.0035 -> 0 | BB9: =+F9+I9+L9+O9+R9+U9+X9+AA9+AD9+AG9+AJ9+AM9+AP9+AS9+AV9+AY9 -> 95971.26 | BC9: =+G9+J9+M9+P9+S9+V9+Y9+AB9+AE9+AH9+AK9+AN9+AQ9+AT9+AW9+AZ9 -> 335.89941 | BD9: =+H9+K9+N9+Q9+T9+W9+Z9+AC9+AF9+AI9+AL9+AO9+AR9+AU9+AX9+BA9 -> 40 | BF9: =+BC9+BD9-BE9 -> 375.89941 | BG9: 5590.77 | BH9: =+BG9*0.0035 -> 19.567695 | BJ9: 0 | BK9: =+BJ9*0.0035 -> 0 | BM9: 7762.16 | BN9: =+BM9*0.0035 -> 27.16756 | BP9: 8498.73 | BQ9: =+BP9*0.0035 -> 29.745555 | BS9: 0 | BT9: =+BS9*0.0035 -> 0 | BV9: 7348.55 | BW9: =+BV9*0.0035 -> 25.719925 | BY9: 1931.09 | BZ9: =+BY9*0.0035 -> 6.758815 | CB9: 0 | CC9: =+CB9*0.0035 -> 0 | CE9: 7660.51 | CF9: =+CE9*0.0035 -> 26.811785 | CH9: 0 | CI9: =+CH9*0.0035 -> 0 | CK9: 0 | CL9: =+CK9*0.0035 -> 0 | CN9: 0 | CO9: =+CN9*0.0035 -> 0 | CQ9: 0 | CR9: =+CQ9*0.0035 -> 0 | CT9: =BG9+BJ9+BM9+BP9+BS9+BV9+BY9+CB9+CH9+CK9+CN9+CQ9+CE9 -> 38791.81 | CU9: =BH9+BK9+BN9+BQ9+BT9+BW9+BZ9+CC9+CI9+CL9+CO9+CR9+CF9 -> 135.77134 | CV9: =+BI9+BL9+BO9+BR9+BU9+BX9+CA9+CD9+CG9+CJ9+CM9+CP9+CS9 -> 0 | CX9: =+CU9+CV9-CW9 -> 135.77134 | CY9: =+BB9+CT9 -> 134763.07 | CZ9: =+BC9+CU9 -> 471.67075 | DA9: =+BD9+CV9 -> 40 | DB9: =+CZ9+DA9 -> 511.67075
A10: =+A9+1 -> 4 | B10: JATIVA REINA LUIS ENRIQUE | C10: PENDULA 2 | D10: 0968953599 | E10: Jhonhenrry-1994@hotmail.con | F10: 0 | G10: =+F10*0.0035 -> 0 | H10: 25 | I10: 5087.62 | J10: =+I10*0.0035 -> 17.80667 | K10: =25-J10 -> 7.19333 | L10: 5610.59 | M10: =+L10*0.0035 -> 19.637065 | N10: =36.33-M10 -> 16.692935 | O10: 0 | P10: =+O10*0.0035 -> 0 | R10: 10997.34 | S10: =+R10*0.0065/2 -> 35.741355 | U10: 7799.23 | V10: =+U10*0.0035 -> 27.297305 | X10: 7999.93 | Y10: =+X10*0.0035 -> 27.999755 | AA10: 8566.56 | AB10: =+AA10*0.0035 -> 29.98296 | AD10: 19351.39 | AE10: =+AD10*0.0035 -> 67.729865 | AG10: 0 | AH10: =+AG10*0.0035 -> 0 | AJ10: 12609.34 | AK10: =+AJ10*0.0035 -> 44.13269 | AM10: 10939.52 | AN10: =+AM10*0.0035 -> 38.28832 | AP10: 0 | AQ10: =+AP10*0.0035 -> 0 | AS10: 16702.08 | AT10: =+AS10*0.0035 -> 58.45728 | AW10: =+AV10*0.0035 -> 0 | AZ10: =+AY10*0.0035 -> 0 | BB10: =+F10+I10+L10+O10+R10+U10+X10+AA10+AD10+AG10+AJ10+AM10+AP10+AS10+AV10+AY10 -> 105663.6 | BC10: =+G10+J10+M10+P10+S10+V10+Y10+AB10+AE10+AH10+AK10+AN10+AQ10+AT10+AW10+AZ10 -> 367.07327 | BD10: =+H10+K10+N10+Q10+T10+W10+Z10+AC10+AF10+AI10+AL10+AO10+AR10+AU10+AX10+BA10 -> 48.886265 | BF10: =+BC10+BD10-BE10 -> 415.95953 | BG10: 5590.77 | BH10: =+BG10*0.0035 -> 19.567695 | BJ10: 0 | BK10: =+BJ10*0.0035 -> 0 | BM10: 12355 | BN10: =+BM10*0.0035 -> 43.2425 | BP10: 10021.73 | BQ10: =+BP10*0.0035 -> 35.076055 | BS10: 3309.84 | BT10: =+BS10*0.0035 -> 11.58444 | BV10: 8555.54 | BW10: =+BV10*0.0035 -> 29.94439 | BY10: 1931.09 | BZ10: =+BY10*0.0035 -> 6.758815 | CB10: 0 | CC10: =+CB10*0.0035 -> 0 | CE10: 9856.51 | CF10: =+CE10*0.0035 -> 34.497785 | CH10: 0 | CI10: =+CH10*0.0035 -> 0 | CK10: 0 | CL10: =+CK10*0.0035 -> 0 | CN10: 0 | CO10: =+CN10*0.0035 -> 0 | CQ10: 0 | CR10: =+CQ10*0.0035 -> 0 | CT10: =BG10+BJ10+BM10+BP10+BS10+BV10+BY10+CB10+CH10+CK10+CN10+CQ10+CE10 -> 51620.48 | CU10: =BH10+BK10+BN10+BQ10+BT10+BW10+BZ10+CC10+CI10+CL10+CO10+CR10+CF10 -> 180.67168 | CV10: =+BI10+BL10+BO10+BR10+BU10+BX10+CA10+CD10+CG10+CJ10+CM10+CP10+CS10 -> 0 | CX10: =+CU10+CV10-CW10 -> 180.67168 | CY10: =+BB10+CT10 -> 157284.08 | CZ10: =+BC10+CU10 -> 547.74495 | DA10: =+BD10+CV10 -> 48.886265 | DB10: =+CZ10+DA10 -> 596.63121
A11: =+A10+1 -> 5 | B11: FERNANDEZ RISCO ALEX BLADIMIR | C11: PENDULA 2 | F11: 11821.35 | G11: =+F11*0.0035 -> 41.374725 | I11: 7931.62 | J11: =+I11*0.0035 -> 27.76067 | L11: 13425 | M11: =+L11*0.0035 -> 46.9875 | O11: 0 | P11: =+O11*0.0035 -> 0 | R11: 11472.34 | S11: =+R11*0.0035 -> 40.15319 | U11: 6185.23 | V11: =+U11*0.0035 -> 21.648305 | X11: 6192.95 | Y11: =+X11*0.0035 -> 21.675325 | AA11: 0 | AB11: =+AA11*0.0035 -> 0 | AC11: 20 | AD11: 15688.41 | AE11: =+AD11*0.0035 -> 54.909435 | AG11: 0 | AH11: =+AG11*0.0035 -> 0 | AJ11: 10228.34 | AK11: =+AJ11*0.0035 -> 35.79919 | AM11: 10939.52 | AN11: =+AM11*0.0065/2 -> 35.55344 | AP11: 0 | AQ11: =+AP11*0.0035 -> 0 | AR11: 20 | AS11: 14577.08 | AT11: =+AS11*0.0035 -> 51.01978 | AW11: =+AV11*0.0035 -> 0 | AZ11: =+AY11*0.0035 -> 0 | BB11: =+F11+I11+L11+O11+R11+U11+X11+AA11+AD11+AG11+AJ11+AM11+AP11+AS11+AV11+AY11 -> 108461.84 | BC11: =+G11+J11+M11+P11+S11+V11+Y11+AB11+AE11+AH11+AK11+AN11+AQ11+AT11+AW11+AZ11 -> 376.88156 | BD11: =+H11+K11+N11+Q11+T11+W11+Z11+AC11+AF11+AI11+AL11+AO11+AR11+AU11+AX11+BA11 -> 40 | BF11: =+BC11+BD11-BE11 -> 416.88156 | BG11: 0 | BH11: =+BG11*0.0035 -> 0 | BI11: 20 | BJ11: 0 | BK11: =+BJ11*0.0035 -> 0 | BM11: 10923 | BN11: =+BM11*0.0035 -> 38.2305 | BP11: 8533.73 | BQ11: =+BP11*0.0035 -> 29.868055 | BS11: 3309.84 | BT11: =+BS11*0.0035 -> 11.58444 | BV11: 0 | BW11: =+BV11*0.0035 -> 0 | BX11: 20 | BY11: 0 | BZ11: =+BY11*0.0035 -> 0 | CA11: 20 | CB11: 0 | CC11: =+CB11*0.0035 -> 0 | CE11: 8301.51 | CF11: =+CE11*0.0035 -> 29.055285 | CH11: 0 | CI11: =+CH11*0.0035 -> 0 | CK11: 0 | CL11: =+CK11*0.0035 -> 0 | CN11: 0 | CO11: =+CN11*0.0035 -> 0 | CQ11: 0 | CR11: =+CQ11*0.0035 -> 0 | CT11: =BG11+BJ11+BM11+BP11+BS11+BV11+BY11+CB11+CH11+CK11+CN11+CQ11+CE11 -> 31068.08 | CU11: =BH11+BK11+BN11+BQ11+BT11+BW11+BZ11+CC11+CI11+CL11+CO11+CR11+CF11 -> 108.73828 | CV11: =+BI11+BL11+BO11+BR11+BU11+BX11+CA11+CD11+CG11+CJ11+CM11+CP11+CS11 -> 60 | CX11: =+CU11+CV11-CW11 -> 168.73828 | CY11: =+BB11+CT11 -> 139529.92 | CZ11: =+BC11+CU11 -> 485.61984 | DA11: =+BD11+CV11 -> 100 | DB11: =+CZ11+DA11 -> 585.61984
A12: =+A11+1 -> 6 | B12: LOOR TONATO JESUS MANUEL | C12: PENDULA 2 | F12: 10979.37 | G12: =+F12*0.0035 -> 38.427795 | I12: 0 | J12: =+I12*0.0035 -> 0 | K12: 20 | L12: 0 | M12: =+L12*0.0035 -> 0 | N12: 20 | O12: 0 | P12: =+O12*0.0035 -> 0 | Q12: 20 | R12: 9295.34 | S12: =+R12*0.0035 -> 32.53369 | U12: 8249.23 | V12: =+U12*0.0035 -> 28.872305 | X12: 6976.95 | Y12: =+X12*0.0035 -> 24.419325 | AA12: 6386.55 | AB12: =+AA12*0.0035 -> 22.352925 | AD12: 13160.41 | AE12: =+AD12*0.0035 -> 46.061435 | AG12: 0 | AH12: =+AG12*0.0035 -> 0 | AJ12: 8782.34 | AK12: =+AJ12*0.0035 -> 30.73819 | AM12: 7440.54 | AN12: =+AM12*0.0035 -> 26.04189 | AP12: 0 | AQ12: =+AP12*0.0035 -> 0 | AS12: 9806.09 | AT12: =+AS12*0.0035 -> 34.321315 | AU12: =56-AT12 -> 21.678685 | AW12: =+AV12*0.0035 -> 0 | AZ12: =+AY12*0.0035 -> 0 | BB12: =+F12+I12+L12+O12+R12+U12+X12+AA12+AD12+AG12+AJ12+AM12+AP12+AS12+AV12+AY12 -> 81076.82 | BC12: =+G12+J12+M12+P12+S12+V12+Y12+AB12+AE12+AH12+AK12+AN12+AQ12+AT12+AW12+AZ12 -> 283.76887 | BD12: =+H12+K12+N12+Q12+T12+W12+Z12+AC12+AF12+AI12+AL12+AO12+AR12+AU12+AX12+BA12 -> 81.678685 | BF12: =+BC12+BD12-BE12 -> 365.44755 | BG12: 5590.77 | BH12: =+BG12*0.0035 -> 19.567695 | BJ12: 0 | BK12: =+BJ12*0.0035 -> 0 | BM12: 10544 | BN12: =+BM12*0.0035 -> 36.904 | BP12: 42210.15 | BQ12: =+BP12*0.02/34 -> 24.8295 | BS12: 3309.85 | BT12: =+BS12*0.0035 -> 11.584475 | BV12: 8452.55 | BW12: =+BV12*0.0035 -> 29.583925 | BY12: 1931.09 | BZ12: =+BY12*0.0035 -> 6.758815 | CB12: 0 | CC12: =+CB12*0.0035 -> 0 | CE12: 10973.52 | CF12: =+CE12*0.0035 -> 38.40732 | CH12: 0 | CI12: =+CH12*0.0035 -> 0 | CK12: 0 | CL12: =+CK12*0.0035 -> 0 | CN12: 0 | CO12: =+CN12*0.0035 -> 0 | CQ12: 0 | CR12: =+CQ12*0.0035 -> 0 | CT12: =BG12+BJ12+BM12+BP12+BS12+BV12+BY12+CB12+CH12+CK12+CN12+CQ12+CE12 -> 83011.93 | CU12: =BH12+BK12+BN12+BQ12+BT12+BW12+BZ12+CC12+CI12+CL12+CO12+CR12+CF12 -> 167.63573 | CV12: =+BI12+BL12+BO12+BR12+BU12+BX12+CA12+CD12+CG12+CJ12+CM12+CP12+CS12 -> 0 | CX12: =+CU12+CV12-CW12 -> 167.63573 | CY12: =+BB12+CT12 -> 164088.75 | CZ12: =+BC12+CU12 -> 451.4046 | DA12: =+BD12+CV12 -> 81.678685 | DB12: =+CZ12+DA12 -> 533.08328
A13: =+A12+1 -> 7 | B13: HERRERA PEÑARRIETA ARIEL GABRIEL | C13: PENDULA 3 | D13: 0967523410 | E13: arielcedeño003@gmail.com | F13: 0 | G13: =+F13*0.0065/2 -> 0 | H13: 25 | I13: 5087.62 | J13: =+I13*0.0065/2 -> 16.534765 | K13: =25-J13 -> 8.465235 | L13: 5610.59 | M13: =+L13*0.0065/2 -> 18.234417 | N13: =36.33-M13 -> 18.095582 | O13: 0 | P13: =+O13*0.0065/2 -> 0 | R13: 11472.34 | S13: =+R13*0.0065/2 -> 37.285105 | U13: 7799.23 | V13: =+U13*0.0065/2 -> 25.347497 | X13: 7999.93 | Y13: =+X13*0.0065/2 -> 25.999772 | AA13: 8566.56 | AB13: =+AA13*0.0065/2 -> 27.84132 | AD13: 19351.39 | AE13: =+AD13*0.0065/2 -> 62.892017 | AG13: 0 | AH13: =+AG13*0.0065/2 -> 0 | AJ13: 12609.34 | AK13: =+AJ13*0.0065/2 -> 40.980355 | AM13: 10939.52 | AN13: =+AM13*0.0065/2 -> 35.55344 | AP13: 0 | AQ13: =+AP13*0.0065/2 -> 0 | AR13: 20 | AS13: 16702.08 | AT13: =+AS13*0.0065/2 -> 54.28176 | AW13: =+AV13*0.0065/2 -> 0 | AZ13: =+AY13*0.0065/2 -> 0 | BB13: =+F13+I13+L13+O13+R13+U13+X13+AA13+AD13+AG13+AJ13+AM13+AP13+AS13+AV13+AY13 -> 106138.6 | BC13: =+G13+J13+M13+P13+S13+V13+Y13+AB13+AE13+AH13+AK13+AN13+AQ13+AT13+AW13+AZ13 -> 344.95045 | BD13: =+H13+K13+N13+Q13+T13+W13+Z13+AC13+AF13+AI13+AL13+AO13+AR13+AU13+AX13+BA13 -> 71.560817 | BF13: =+BC13+BD13-BE13 -> 416.51127 | BG13: 5590.77 | BH13: =+BG13*0.0065/2 -> 18.170002 | BJ13: 0 | BK13: =+BJ13*0.0065/2 -> 0 | BM13: 12355 | BN13: =+BM13*0.0065/2 -> 40.15375 | BP13: 10021.73 | BQ13: =+BP13*0.0065/2 -> 32.570622 | BS13: 3309.84 | BT13: =+BS13*0.0065/2 -> 10.75698 | BV13: 8555.54 | BW13: =+BV13*0.0065/2 -> 27.805505 | BY13: 0 | BZ13: =+BY13*0.0065/2 -> 0 | CA13: 20 | CB13: 0 | CC13: =+CB13*0.0065/2 -> 0 | CE13: 9856.51 | CF13: =+CE13*0.0065/2 -> 32.033657 | CH13: 0 | CI13: =+CH13*0.0065/2 -> 0 | CK13: 0 | CL13: =+CK13*0.0065/2 -> 0 | CN13: 0 | CO13: =+CN13*0.0065/2 -> 0 | CQ13: 0 | CR13: =+CQ13*0.0065/2 -> 0 | CT13: =BG13+BJ13+BM13+BP13+BS13+BV13+BY13+CB13+CH13+CK13+CN13+CQ13+CE13 -> 49689.39 | CU13: =BH13+BK13+BN13+BQ13+BT13+BW13+BZ13+CC13+CI13+CL13+CO13+CR13+CF13 -> 161.49052 | CV13: =+BI13+BL13+BO13+BR13+BU13+BX13+CA13+CD13+CG13+CJ13+CM13+CP13+CS13 -> 20 | CX13: =+CU13+CV13-CW13 -> 181.49052 | CY13: =+BB13+CT13 -> 155827.99 | CZ13: =+BC13+CU13 -> 506.44097 | DA13: =+BD13+CV13 -> 91.560817 | DB13: =+CZ13+DA13 -> 598.00179
A14: =+A13+1 -> 8 | B14: SANCHEZ TES JUAN CARLOS | C14: PENDULA 4 | D14: 0994783560 | E14: juantessanches21@gmail.com | F14: 0 | G14: =+F14*0.0065/2 -> 0 | H14: 20 | I14: 10491.62 | J14: =+I14*0.0065/2 -> 34.097765 | L14: 13725 | M14: =+L14*0.0065/2 -> 44.60625 | O14: 0 | P14: =+O14*0.0065/2 -> 0 | R14: 10269.35 | S14: =+R14*0.0065/2 -> 33.375388 | U14: 7115.23 | V14: =+U14*0.0065/2 -> 23.124497 | X14: 5956.95 | Y14: =+X14*0.0065/2 -> 19.360087 | AA14: 0 | AB14: =+AA14*0.0065/2 -> 0 | AC14: 20 | AD14: 15942.41 | AE14: =+AD14*0.0065/2 -> 51.812832 | AG14: 0 | AH14: =+AG14*0.0065/2 -> 0 | AJ14: 10588.34 | AK14: =+AJ14*0.0065/2 -> 34.412105 | AM14: 9423.54 | AN14: =+AM14*0.0065/2 -> 30.626505 | AP14: 0 | AQ14: =+AP14*0.0065/2 -> 0 | AR14: 20 | AS14: 14840.08 | AT14: =+AS14*0.0065/2 -> 48.23026 | AW14: =+AV14*0.0065/2 -> 0 | AZ14: =+AY14*0.0065/2 -> 0 | BB14: =+F14+I14+L14+O14+R14+U14+X14+AA14+AD14+AG14+AJ14+AM14+AP14+AS14+AV14+AY14 -> 98352.52 | BC14: =+G14+J14+M14+P14+S14+V14+Y14+AB14+AE14+AH14+AK14+AN14+AQ14+AT14+AW14+AZ14 -> 319.64569 | BD14: =+H14+K14+N14+Q14+T14+W14+Z14+AC14+AF14+AI14+AL14+AO14+AR14+AU14+AX14+BA14 -> 60 | BF14: =+BC14+BD14-BE14 -> 379.64569 | BG14: 5590.77 | BH14: =+BG14*0.0065/2 -> 18.170002 | BJ14: 0 | BK14: =+BJ14*0.0065/2 -> 0 | BM14: 37108.31 | BN14: =+BM14*0.02/29 -> 25.591938 | BP14: 8347.73 | BQ14: =+BP14*0.0065/2 -> 27.130122 | BS14: 3309.84 | BT14: =+BS14*0.0035 -> 11.58444 | BV14: 6969.55 | BW14: =+BV14*0.0065/2 -> 22.651038 | BY14: 1931.09 | BZ14: =+BY14*0.0065/2 -> 6.2760425 | CB14: 0 | CC14: =+CB14*0.0065/2 -> 0 | CE14: 0 | CF14: =+CE14*0.0065/2 -> 0 | CH14: 0 | CI14: =+CH14*0.0065/2 -> 0 | CK14: 0 | CL14: =+CK14*0.0065/2 -> 0 | CN14: 0 | CO14: =+CN14*0.0065/2 -> 0 | CQ14: 0 | CR14: =+CQ14*0.0065/2 -> 0 | CT14: =BG14+BJ14+BM14+BP14+BS14+BV14+BY14+CB14+CH14+CK14+CN14+CQ14+CE14 -> 63257.29 | CU14: =BH14+BK14+BN14+BQ14+BT14+BW14+BZ14+CC14+CI14+CL14+CO14+CR14+CF14 -> 111.40358 | CV14: =+BI14+BL14+BO14+BR14+BU14+BX14+CA14+CD14+CG14+CJ14+CM14+CP14+CS14 -> 0 | CX14: =+CU14+CV14-CW14 -> 111.40358 | CY14: =+BB14+CT14 -> 161609.81 | CZ14: =+BC14+CU14 -> 431.04927 | DA14: =+BD14+CV14 -> 60 | DB14: =+CZ14+DA14 -> 491.04927
A15: =+A14+1 -> 9 | B15: VERA SALDARRIAGA EDISON ADOLFO | C15: PENDULA | D15: 0981145232 | F15: 11378.37 | G15: =+F15*0.0065/2 -> 36.979703 | I15: 9683.62 | J15: =+I15*0.0065/2 -> 31.471765 | L15: 15254 | M15: =+L15*0.0065/2 -> 49.5755 | O15: 0 | P15: =+O15*0.0065/2 -> 0 | R15: 10997.34 | S15: =+R15*0.0065/2 -> 35.741355 | U15: 8380.25 | V15: =+U15*0.0065/2 -> 27.235812 | X15: 6018.95 | Y15: =+X15*0.0065/2 -> 19.561587 | AA15: 7872.55 | AB15: =+AA15*0.0065/2 -> 25.585787 | AD15: 15764.41 | AE15: =+AD15*0.0065/2 -> 51.234333 | AG15: 0 | AH15: =+AG15*0.0065/2 -> 0 | AJ15: 11545.34 | AK15: =+AJ15*0.0065/2 -> 37.522355 | AM15: 7440.54 | AN15: =+AM15*0.0065/2 -> 24.181755 | AP15: 0 | AQ15: =+AP15*0.0065/2 -> 0 | AS15: 13201.08 | AT15: =+AS15*0.0065/2 -> 42.90351 | AW15: =+AV15*0.0065/2 -> 0 | AZ15: =+AY15*0.0065/2 -> 0 | BB15: =+F15+I15+L15+O15+R15+U15+X15+AA15+AD15+AG15+AJ15+AM15+AP15+AS15+AV15+AY15 -> 117536.45 | BC15: =+G15+J15+M15+P15+S15+V15+Y15+AB15+AE15+AH15+AK15+AN15+AQ15+AT15+AW15+AZ15 -> 381.99346 | BD15: =+H15+K15+N15+Q15+T15+W15+Z15+AC15+AF15+AI15+AL15+AO15+AR15+AU15+AX15+BA15 -> 0 | BF15: =+BC15+BD15-BE15 -> 381.99346 | BG15: 5590.75 | BH15: =+BG15*0.0065/2 -> 18.169937 | BJ15: 0 | BK15: =+BJ15*0.0065/2 -> 0 | BM15: 7777.15 | BN15: =+BM15*0.0065/2 -> 25.275737 | BP15: 7895.73 | BQ15: =+BP15*0.0065/2 -> 25.661122 | BS15: 3309.84 | BT15: =+BS15*0.0065/2 -> 10.75698 | BV15: 6079.55 | BW15: =+BV15*0.0065/2 -> 19.758537 | BY15: 1931.09 | BZ15: =+BY15*0.0065/2 -> 6.2760425 | CB15: 0 | CC15: =+CB15*0.0065/2 -> 0 | CE15: 8627.51 | CF15: =+CE15*0.0065/2 -> 28.039407 | CH15: 0 | CI15: =+CH15*0.0065/2 -> 0 | CK15: 0 | CL15: =+CK15*0.0065/2 -> 0 | CN15: 0 | CO15: =+CN15*0.0065/2 -> 0 | CQ15: 0 | CR15: =+CQ15*0.0065/2 -> 0 | CT15: =BG15+BJ15+BM15+BP15+BS15+BV15+BY15+CB15+CH15+CK15+CN15+CQ15+CE15 -> 41211.62 | CU15: =BH15+BK15+BN15+BQ15+BT15+BW15+BZ15+CC15+CI15+CL15+CO15+CR15+CF15 -> 133.93777 | CV15: =+BI15+BL15+BO15+BR15+BU15+BX15+CA15+CD15+CG15+CJ15+CM15+CP15+CS15 -> 0 | CX15: =+CU15+CV15-CW15 -> 133.93777 | CY15: =+BB15+CT15 -> 158748.07 | CZ15: =+BC15+CU15 -> 515.93123 | DA15: =+BD15+CV15 -> 0 | DB15: =+CZ15+DA15 -> 515.93123
A16: TOTAL | BB16: =SUM(BB7:BB15) -> 921649.52 | BC16: =SUM(BC7:BC15) -> 3139.7822 | BD16: =SUM(BD7:BD15) -> 402.12577 | BE16: =SUM(BE7:BE15) -> 0 | BF16: =SUM(BF7:BF15) -> 3541.908 | CT16: =SUM(CT7:CT15) -> 457878.58 | CU16: =SUM(CU7:CU15) -> 1242.6597 | CV16: =SUM(CV7:CV15) -> 80 | CW16: =SUM(CW7:CW15) -> 0 | CX16: =SUM(CX7:CX15) -> 1322.6597 | CY16: =SUM(CY7:CY15) -> 1379528.1 | CZ16: =SUM(CZ7:CZ15) -> 4382.4419 | DA16: =SUM(DA7:DA15) -> 482.12577 | DB16: =SUM(DB7:DB15) -> 4864.5677 | DD16: =+CZ16+DD17 -> 7720.2098 | DE16: =+DA16+DE17 -> 1188.5457 | DF16: =+DB16+DF17 -> 8908.7555
A17: Nº | B17: PERSONAL DE SIERRA MESA DE LA MAÑANA | C17: Nº DE GRUPOS | D17: # CELULAR | E17: CORREO | F17: MIERCOLES 26-05-2021 | I17: JUEVES 27-05-2021 | L17: VIERNES 28-05-2021 | O17: SABADO 29-05-2021 | R17: LUNES 31-05-2021 | U17: MARTES 01-06-2021 | X17: MIERCOLES 02-06-2021 | AA17: JUEVES 03-06-2021 | AD17: VIERNES 04-06-2021 | AG17: SABADO 05-06-2021 | AJ17: LUNES 07-05-2021 | AM17: MARTES 08-06-2021 | AP17: MIERCOLES 09-06-2021 | AS17: JUEVES 10-06-2021 | BB17: TOTAL BFT QUINCENA | BC17: $ POR AVANCE | BD17: $ AL DIARIO | BE17: MULTA | BF17: VALOR TOTAL QUINCENA | BG17: VIERNES 11-06-2021 | BJ17: SABADO 12-06-2021 | BM17: LUNES 14-06-2021 | BP17: MARTES 15-06-2021 | BS17: MIERCOLES 16-06-2021 | BV17: JUEVES 17-06-2021 | BY17: VIERNES 18-06-2021 | CB17: SABADO 19-06-2021 | CE17: LUNES 21-06-2021 | CH17: MARTES 22-06-2021 | CK17: MIERCOLES 23-06-2021 | CN17: JUEVES 24-06-2021 | CQ17: VIERNES 25-06-2021 | CT17: TOTAL BFT QUINCENA | CU17: $ POR AVANCE | CV17: $ AL DIARIO | CW17: MULTA | CX17: VALOR TOTAL QUINCENA | CY17: TOTAL BFT | CZ17: $ POR AVANCE | DA17: $ AL DIARIO | DB17: TOTAL A PAGAR | DD17: 3337.7679 | DE17: 706.41989 | DF17: 4044.1878
F18: BTF | G18: $ | H18: TRABAJOS DIARIO | I18: BTF | J18: $ | K18: TRABAJOS DIARIO | L18: BTF | M18: $ | N18: TRABAJOS DIARIO | O18: BTF | P18: $ | Q18: TRABAJOS DIARIO | R18: BTF | S18: $ | T18: TRABAJOS DIARIO | U18: BTF | V18: $ | W18: TRABAJOS DIARIO | X18: BTF | Y18: $ | Z18: TRABAJOS DIARIO | AA18: BTF | AB18: $ | AC18: TRABAJOS DIARIO | AD18: BTF | AE18: $ | AF18: TRABAJOS DIARIO | AG18: BTF | AH18: $ | AI18: TRABAJOS DIARIO | AJ18: BTF | AK18: $ | AL18: TRABAJOS DIARIO | AM18: BTF | AN18: $ | AO18: TRABAJOS DIARIO | AP18: BTF | AQ18: $ | AR18: TRABAJOS DIARIO | AS18: BTF | AT18: $ | AU18: TRABAJOS DIARIO | AV18: BTF | AW18: $ | AX18: TRABAJOS DIARIO | AY18: BTF | AZ18: $ | BA18: TRABAJOS DIARIO | BG18: BTF | BH18: $ | BI18: TRABAJOS DIARIO | BJ18: BTF | BK18: $ | BL18: TRABAJOS DIARIO | BM18: BTF | BN18: $ | BO18: TRABAJOS DIARIO | BP18: BTF | BQ18: $ | BR18: TRABAJOS DIARIO | BS18: BTF | BT18: $ | BU18: TRABAJOS DIARIO | BV18: BTF | BW18: $ | BX18: TRABAJOS DIARIO | BY18: BTF | BZ18: $ | CA18: TRABAJOS DIARIO | CB18: BTF | CC18: $ | CD18: TRABAJOS DIARIO | CE18: BTF | CF18: $ | CG18: TRABAJOS DIARIO | CH18: BTF | CI18: $ | CJ18: TRABAJOS DIARIO | CK18: BTF | CL18: $ | CM18: TRABAJOS DIARIO | CN18: BTF | CO18: $ | CP18: TRABAJOS DIARIO | CQ18: BTF | CR18: $ | CS18: TRABAJOS DIARIO | DF18: =+DB16+DF17 -> 8908.7555
A19: =+A15+1 -> 10 | B19: PACHECO MONTOYA JENIFFER KATHERINE | C19: SIERRA 1 | D19: 0993763536 | E19: jenifferpacheco.1996luky@gmail.com | F19: 3114.9347 | G19: =IF(F19<2700,F19*0.007,IF(F19<3200,F19*0.008,IF(F19<3700,F19*0.0097,IF(F19>3699,F19*0.01095,"")))) -> 24.919477 | I19: 3233.608 | J19: =IF(I19<2700,I19*0.007,IF(I19<3200,I19*0.008,IF(I19<3700,I19*0.0097,IF(I19>3699,I19*0.01095,"")))) -> 31.365998 | L19: 3523.5377 | M19: =IF(L19<2700,L19*0.007,IF(L19<3200,L19*0.008,IF(L19<3700,L19*0.0097,IF(L19>3699,L19*0.01095,"")))) -> 34.178316 | P19: =IF(O19<2700,O19*0.0097,IF(O19<3200,O19*0.01095,IF(O19<3700,O19*0.0122,IF(O19>3699,O19*0.01345,"")))) -> 0 | R19: 3653.3065 | S19: =IF(R19<2700,R19*0.007,IF(R19<3200,R19*0.008,IF(R19<3700,R19*0.0097,IF(R19>3699,R19*0.01095,"")))) -> 35.437073 | U19: 0 | V19: =IF(U19<2700,U19*0.008,IF(U19<3200,U19*0.0097,IF(U19<3700,U19*0.01095,IF(U19>3699,U19*0.0122,"")))) -> 0 | W19: 20 | X19: 0 | Y19: =IF(X19<2700,X19*0.008,IF(X19<3200,X19*0.0097,IF(X19<3700,X19*0.01095,IF(X19>3699,X19*0.0122,"")))) -> 0 | Z19: 20 | AA19: 0 | AB19: =IF(AA19<2700,AA19*0.008,IF(AA19<3200,AA19*0.0097,IF(AA19<3700,AA19*0.01095,IF(AA19>3699,AA19*0.0122,"")))) -> 0 | AC19: 20 | AD19: 2742.5126 | AE19: =IF(AD19<2700,AD19*0.007,IF(AD19<3200,AD19*0.008,IF(AD19<3700,AD19*0.0097,IF(AD19>3699,AD19*0.01095,"")))) -> 21.940101 | AF19: 30 | AG19: 0 | AH19: =IF(AG19<2700,AG19*0.0097,IF(AG19<3200,AG19*0.01095,IF(AG19<3700,AG19*0.0122,IF(AG19>3699,AG19*0.01345,"")))) -> 0 | AJ19: 3461.3065 | AK19: =IF(AJ19<2700,AJ19*0.007,IF(AJ19<3200,AJ19*0.008,IF(AJ19<3700,AJ19*0.0097,IF(AJ19>3699,AJ19*0.01095,"")))) -> 33.574673 | AM19: 2877.1055 | AN19: =IF(AM19<2700,AM19*0.007,IF(AM19<3200,AM19*0.008,IF(AM19<3700,AM19*0.0097,IF(AM19>3699,AM19*0.01095,"")))) -> 23.016844 | AP19: 0 | AQ19: =IF(AP19<2700,AP19*0.0097,IF(AP19<3200,AP19*0.01095,IF(AP19<3700,AP19*0.0122,IF(AP19>3699,AP19*0.01345,"")))) -> 0 | AR19: 12 | AS19: 0 | AT19: =IF(AS19<2700,AS19*0.008,IF(AS19<3200,AS19*0.0097,IF(AS19<3700,AS19*0.01095,IF(AS19>3699,AS19*0.0122,"")))) -> 0 | AU19: 20 | AW19: =IF(AV19<2700,AV19*0.0097,IF(AV19<3200,AV19*0.01095,IF(AV19<3700,AV19*0.0122,IF(AV19>3699,AV19*0.01345,"")))) -> 0 | AZ19: =IF(AY19<2700,AY19*0.0097,IF(AY19<3200,AY19*0.01095,IF(AY19<3700,AY19*0.0122,IF(AY19>3699,AY19*0.01345,"")))) -> 0 | BB19: =+F19+I19+L19+O19+R19+U19+X19+AA19+AD19+AG19+AJ19+AM19+AP19+AS19+AV19+AY19 -> 22606.312 | BC19: =+G19+J19+M19+P19+S19+V19+Y19+AB19+AE19+AH19+AK19+AN19+AQ19+AT19+AW19+AZ19 -> 204.43248 | BD19: =+H19+K19+N19+Q19+T19+W19+Z19+AC19+AF19+AI19+AL19+AO19+AR19+AU19+AX19+BA19 -> 122 | BF19: =+BC19+BD19-BE19 -> 326.43248 | BG19: 0 | BH19: =IF(BG19<2700,BG19*0.008,IF(BG19<3200,BG19*0.0097,IF(BG19<3700,BG19*0.01095,IF(BG19>3699,BG19*0.0122,"")))) -> 0 | BI19: 18 | BJ19: 0 | BK19: =IF(BJ19<2700,BJ19*0.0097,IF(BJ19<3200,BJ19*0.01095,IF(BJ19<3700,BJ19*0.0122,IF(BJ19>3699,BJ19*0.01345,"")))) -> 0 | BL19: 12 | BM19: 2175.196 | BN19: =IF(BM19<2700,BM19*0.007,IF(BM19<3200,BM19*0.008,IF(BM19<3700,BM19*0.0097,IF(BM19>3699,BM19*0.01095,"")))) -> 15.226372 | BP19: 2744.9246 | BQ19: =IF(BP19<2700,BP19*0.007,IF(BP19<3200,BP19*0.008,IF(BP19<3700,BP19*0.0097,IF(BP19>3699,BP19*0.01095,"")))) -> 21.959397 | BS19: 2624.804 | BT19: =IF(BS19<2700,BS19*0.007,IF(BS19<3200,BS19*0.008,IF(BS19<3700,BS19*0.0097,IF(BS19>3699,BS19*0.01095,"")))) -> 18.373628 | BV19: 2994.3317 | BW19: =IF(BV19<2700,BV19*0.007,IF(BV19<3200,BV19*0.008,IF(BV19<3700,BV19*0.0097,IF(BV19>3699,BV19*0.01095,"")))) -> 23.954653 | BY19: 1798.4322 | BZ19: =IF(BY19<2700,BY19*0.007,IF(BY19<3200,BY19*0.008,IF(BY19<3700,BY19*0.0097,IF(BY19>3699,BY19*0.01095,"")))) -> 12.589025 | CB19: 0 | CC19: =IF(CB19<2700,CB19*0.0097,IF(CB19<3200,CB19*0.01095,IF(CB19<3700,CB19*0.0122,IF(CB19>3699,CB19*0.01345,"")))) -> 0 | CD19: 10 | CE19: 2936.4422 | CF19: =IF(CE19<2700,CE19*0.007,IF(CE19<3200,CE19*0.008,IF(CE19<3700,CE19*0.0097,IF(CE19>3699,CE19*0.01095,"")))) -> 23.491538 | CH19: 0 | CI19: =IF(CH19<2700,CH19*0.0097,IF(CH19<3200,CH19*0.01095,IF(CH19<3700,CH19*0.0122,IF(CH19>3699,CH19*0.01345,"")))) -> 0 | CJ19: 18 | CK19: 0 | CL19: =IF(CK19<2700,CK19*0.0097,IF(CK19<3200,CK19*0.01095,IF(CK19<3700,CK19*0.0122,IF(CK19>3699,CK19*0.01345,"")))) -> 0 | CM19: 0 | CN19: 0 | CO19: =IF(CN19<2700,CN19*0.0097,IF(CN19<3200,CN19*0.01095,IF(CN19<3700,CN19*0.0122,IF(CN19>3699,CN19*0.01345,"")))) -> 0 | CQ19: 0 | CR19: =IF(CQ19<2700,CQ19*0.0097,IF(CQ19<3200,CQ19*0.01095,IF(CQ19<3700,CQ19*0.0122,IF(CQ19>3699,CQ19*0.01345,"")))) -> 0 | CT19: =BG19+BJ19+BM19+BP19+BS19+BV19+BY19+CB19+CH19+CK19+CN19+CQ19+CE19 -> 15274.131 | CU19: =BH19+BK19+BN19+BQ19+BT19+BW19+BZ19+CC19+CI19+CL19+CO19+CR19+CF19 -> 115.59461 | CV19: =+BI19+BL19+BO19+BR19+BU19+BX19+CA19+CD19+CG19+CJ19+CM19+CP19+CS19 -> 58 | CX19: =+CU19+CV19-CW19 -> 173.59461 | CY19: =+BB19+CT19 -> 37880.442 | CZ19: =+BC19+CU19 -> 320.0271 | DA19: =+BD19+CV19 -> 180 | DB19: =+CZ19+DA19 -> 500.0271
